Workbook

Sheet Instrucciones
A1: INSPECCIÓN FÍSICA DE EQUIPO — SERIE HORIBA AP-370
A2: APMA-370 (CO) · APSA-370 (SO2) · APOA-370 (O3) · APNA-370 (NOx)
A3: Ambientalia — Servicio Técnico · v5.0 · Estructura derivada del prototipo GRIMM EDM180 v1.2
A5: Novedades de la v5.0 — comentario de falla para el informe
A6: Columna N, «Comentario de falla (informe al cliente)»: el texto que describe el hallazgo cuando
A7: ese ítem no cumple, redactado para que se pueda pegar tal cual en el informe de servicio. Está
A8: escrito en tercera persona, sin jerga interna y sin códigos de tarjeta, nombrando el componente
A9: en términos que el cliente reconoce. Es texto fijo del catálogo: se edita una vez y sirve para
A10: todas las visitas.
A12: Columna Z, «Comentario para el informe (automático)»: arma el párrafo final por sí sola. Queda
A13: en blanco mientras el ítem esté Conforme, No aplica o Pendiente, y solo se redacta cuando hay
A14: hallazgo. Encadena cuatro piezas:
... A247: modelo (clic derecho → Mover o copiar → Crear una copia) antes de diligenciar las columnas U a Y.

Sheet APMA-370 (CO)
A1: FASE 1 — INSPECCIÓN FÍSICA DEL EQUIPO · APMA-370 (CO) (catálogo + captura)
A3: Cliente: | D3: Principio de medición: | E3: NDIR con modulación de flujo cruzado
A4: NIT: | D4: Fecha de inspección:
A5: Equipo / Modelo: | B5: Analizador de monóxido de carbono HORIBA APMA-370 | D5: Técnico responsable:
A6: Número de serie: | D6: N.º de informe (MT):
A8: ID | B8: Nivel macro (N1) | C8: Subnivel (N2) | D8: Ítem (N3) | E8: Qué se verifica | F8: Cómo se realiza la inspección | G8: Tipo de dato | H8: Unidad | I8: Criterio de aceptación | J8: Criterio de falla | K8: Si NO OK → causa probable | L8: Si NO OK → verificar (ID) | M8: Si NO OK → acción | N8: Comentario de falla (informe al cliente) | O8: Límite inferior | P8: Límite superior | Q8: Obligatorio | R8: Evidencia fotográfica requerida | S8: Repuesto / parte asociada (catálogo Zoho Books) | T8: Fuente documental | U8: Resultado | V8: Valor medido | W8: Verificación de rango | X8: Foto adjunta | Y8: Observación | Z8: Comentario para el informe (automático)
A9: 1.1.1 | B9: 1. Verificación funcional inicial | C9: 1.1 Encendido y LEDs frontales | D9: LED de encendido (Power LED) | E9: Color del LED indicador de encendido en el panel frontal | F9: Con el equipo energizado, observar el LED de la esquina inferior del panel frontal y registrar su color. No requiere abrir el equipo. | G9: OK / No OK | I9: Debe iluminarse en verde fijo (operación normal). Rojo indica alarma activa | J9: Alerta | K9: LED en rojo: hay al menos una alarma activa en el equipo | L9: 1.1.2 | M9: Registrar el color y pasar al listado de alarmas antes de continuar | N9: El indicador de encendido del panel frontal no muestra el estado normal de operación, lo que señala una condición de alarma activa en el analizador. | Q9: Sí | R9: Sí | T9: P-ST-018-MAN OPER APMA 370 V2 | U9: Pendiente | W9: =IF($G9<>"Numérico","",IF($V9="","Sin dato",IF(AND(OR(NOT(ISNUMBER($O9)),$V9>=$O9),OR(NOT(ISNUMBER($P9)),$V9<=$P9)),"Dentro de rango","Fuera de rango"))) | Z9: =IF(OR($U9="",$U9="Conforme",$U9="No aplica",$U9="Pendiente"),"",$N9&IF($W9="Fuera de rango"," Valor medido: "&TEXT($V9,"0.####")&IF($H9="",""," "&$H9)&IF(AND(ISNUMBER($O9),$V9<$O9),", por debajo del límite inferior de "&TEXT($O9,"0.####")&IF($H9="",""," "&$H9),"")&IF(AND(ISNUMBER($P9),$V9>$P9),", por encima del límite superior de "&TEXT($P9,"0.####")&IF($H9="",""," "&$H9),"")&".","")&IF($Y9="",""," "&$Y9&IF(RIGHT($Y9,1)=".","","."))&" Acción recomendada: "&$M9&IF(RIGHT($M9,1)=".","",".")&IF($J9="Bloqueante"," El equipo no se libera hasta resolver este hallazgo.",IF($J9="Cobrable"," Se incluye en la cotización de repuestos y consumibles."," Se deja registrado como observación.")))
A10: 1.1.2 | B10: 1. Verificación funcional inicial | C10: 1.1 Encendido y LEDs frontales | D10: LED de alarma (Alarm LED) | E10: Estado de alarma activa verificado mediante el color del indicador frontal | F10: Observar el LED de alarma en el panel frontal. Si está en rojo, entrar a MENU / ALARM y anotar el código de alarma activo antes de continuar. | G10: Sí/No | I10: El LED de alarma debe permanecer apagado. Si cambia a rojo indica fallo de hardware o de parámetro | J10: Bloqueante | K10: Alarma activa de proceso, de calibración o de tarjeta | L10: 3.1.1 ; 5.1.1 ; 5.1.2 ; 9.1.1 | M10: Anotar el código en MENU/ALARM y entrar por la rama que corresponda | N10: El analizador presenta al menos una alarma activa al momento de la inspección. | Q10: Sí | R10: No | T10: P-ST-018-MAN OPER APMA 370 V2 | U10: Pendiente | W10: =IF($G10<>"Numérico","",IF($V10="","Sin dato",IF(AND(OR(NOT(ISNUMBER($O10)),$V10>=$O10),OR(NOT(ISNUMBER($P10)),$V10<=$P10)),"Dentro de rango","Fuera de rango"))) | Z10: =IF(OR($U10="",$U10="Conforme",$U10="No aplica",$U10="Pendiente"),"",$N10&IF($W10="Fuera de rango"," Valor medido: "&TEXT($V10,"0.####")&IF($H10="",""," "&$H10)&IF(AND(ISNUMBER($O10),$V10<$O10),", por debajo del límite inferior de "&TEXT($O10,"0.####")&IF($H10="",""," "&$H10),"")&IF(AND(ISNUMBER($P10),$V10>$P10),", por encima del límite superior de "&TEXT($P10,"0.####")&IF($H10="",""," "&$H10),"")&".","")&IF($Y10="",""," "&$Y10&IF(RIGHT($Y10,1)=".","","."))&" Acción recomendada: "&$M10&IF(RIGHT($M10,1)=".","",".")&IF($J10="Bloqueante"," El equipo no se libera hasta resolver este hallazgo.",IF($J10="Cobrable"," Se incluye en la cotización de repuestos y consumibles."," Se deja registrado como observación.")))
A11: 1.1.3 | B11: 1. Verificación funcional inicial | C11: 1.1 Encendido y LEDs frontales | D11: Inicialización del display (TFT LCD) | E11: Arranque correcto y despliegue del menú MEAS. sin bloqueos ni líneas muertas | F11: Encender el equipo y observar la secuencia de arranque completa hasta que aparezca la pantalla MEAS. Presionar tres o cuatro botones de menú para confirmar que no hay zonas muertas ni bloqueos. | G11: OK / No OK | I11: La pantalla LCD TFT debe encender de forma estable y permitir navegación táctil | J11: Cobrable | K11: Cinta flex del LCD agrietada o suelta; panel táctil o unidad LCD averiados | L11: 7.3.1 ; 7.3.2 ; 7.4.1 | M11: Prueba cruzada con cinta y CPU de servicio; reemplazar la unidad LCD si el fallo sigue en la pantalla | N11: La pantalla del analizador no arranca correctamente: presenta bloqueos, zonas sin imagen o no despliega el menú de medición. | Q11: Sí | R11: Sí | S11: LCD Plate (3200595501) · LCD Unit (Apen LCD + Touch Panel) (3014035613) · LCD Unit / AP-370 is composed of CPU-02 (printed circuit board), chassis, and LCD. (3200627065) · LCD Unit chassis, and LCD. (3200618696) | T11: AP-370 LCD replacement / MT_191TE0NC_APMA370_241226 | U11: Pendiente | W11: =IF($G11<>"Numérico","",IF($V11="","Sin dato",IF(AND(OR(NOT(ISNUMBER($O11)),$V11>=$O11),OR(NOT(ISNUMBER($P11)),$V11<=$P11)),"Dentro de rango","Fuera de rango"))) | Z11: =IF(OR($U11="",$U11="Conforme",$U11="No aplica",$U11="Pendiente"),"",$N11&IF($W11="Fuera de rango"," Valor medido: "&TEXT($V11,"0.####")&IF($H11="",""," "&$H11)&IF(AND(ISNUMBER($O11),$V11<$O11),", por debajo del límite inferior de "&TEXT($O11,"0.####")&IF($H11="",""," "&$H11),"")&IF(AND(ISNUMBER($P11),$V11>$P11),", por encima del límite superior de "&TEXT($P11,"0.####")&IF($H11="",""," "&$H11),"")&".","")&IF($Y11="",""," "&$Y11&IF(RIGHT($Y11,1)=".","","."))&" Acción recomendada: "&$M11&IF(RIGHT($M11,1)=".","",".")&IF($J11="Bloqueante"," El equipo no se libera hasta resolver este hallazgo.",IF($J11="Cobrable"," Se incluye en la cotización de repuestos y consumibles."," Se deja registrado como observación.")))
A12: 1.2.1 | B12: 1. Verificación funcional inicial | C12: 1.2 Autodiagnóstico de software | D12: Versión de programa (firmware) | E12: Lectura de la versión de programa en la pantalla de información de software | F12: En la pantalla táctil ir a MENU / SYSTEM / INFORMATION y leer el número de programa. Anotarlo textualmente y contrastarlo con el estándar de fábrica. | G12: Texto | I12: Debe coincidir con la versión homologada de fábrica (estándar AP: P1000878001) | J12: Alerta | K12: Programa no homologado, o CPU sustituida sin recargar la configuración de fábrica | L12: 7.1.1 | M12: Confirmar el HGS con fábrica y recargar la configuración desde la CF antes de calibrar | N12: La versión de programa instalada no corresponde a la versión homologada de fábrica para este analizador. | Q12: Sí | R12: No | T12: 1 - LCD design change AP EN | U12: Pendiente | W12: =IF($G12<>"Numérico","",IF($V12="","Sin dato",IF(AND(OR(NOT(ISNUMBER($O12)),$V12>=$O12),OR(NOT(ISNUMBER($P12)),$V12<=$P12)),"Dentro de rango","Fuera de rango"))) | Z12: =IF(OR($U12="",$U12="Conforme",$U12="No aplica",$U12="Pendiente"),"",$N12&IF($W12="Fuera de rango"," Valor medido: "&TEXT($V12,"0.####")&IF($H12="",""," "&$H12)&IF(AND(ISNUMBER($O12),$V12<$O12),", por debajo del límite inferior de "&TEXT($O12,"0.####")&IF($H12="",""," "&$H12),"")&IF(AND(ISNUMBER($P12),$V12>$P12),", por encima del límite superior de "&TEXT($P12,"0.####")&IF($H12="",""," "&$H12),"")&".","")&IF($Y12="",""," "&$Y12&IF(RIGHT($Y12,1)=".","","."))&" Acción recomendada: "&$M12&IF(RIGHT($M12,1)=".","",".")&IF($J12="Bloqueante"," El equipo no se libera hasta resolver este hallazgo.",IF($J12="Cobrable"," Se incluye en la cotización de repuestos y consumibles."," Se deja registrado como observación.")))
A13: 1.3.1 | B13: 1. Verificación funcional inicial | C13: 1.3 Estabilización térmica | D13: Tiempo de calentamiento inicial (warm-up) | E13: Tiempo transcurrido desde el encendido en frío hasta la estabilización | F13: Anotar la hora de encendido del equipo y calcular las horas transcurridas hasta el momento de la inspección o de la calibración. Si el equipo llevaba operando, registrar que ya estaba estabilizado. | G13: Numérico | H13: horas | I13: Mínimo 3 h de calentamiento para estabilizar banco óptico y catalizador antes de medir. Límite superior PENDIENTE DE VALIDAR | J13: Alerta | K13: Equipo encendido hace menos de 3 h: banco óptico y catalizador aún inestables | L13: 9.1.1 ; 9.1.2 | M13: Esperar a completar el calentamiento; no calibrar ni juzgar derivas hasta entonces | N13: El analizador no ha completado el tiempo mínimo de calentamiento, por lo que sus lecturas aún no son representativas. | O13: 3 | Q13: Sí | R13: No | T13: GZ0000117746B SM E APXX-370 (Service Manual) | U13: Pendiente | W13: =IF($G13<>"Numérico","",IF($V13="","Sin dato",IF(AND(OR(NOT(ISNUMBER($O13)),$V13>=$O13),OR(NOT(ISNUMBER($P13)),$V13<=$P13)),"Dentro de rango","Fuera de rango"))) | Z13: =IF(OR($U13="",$U13="Conforme",$U13="No aplica",$U13="Pendiente"),"",$N13&IF($W13="Fuera de rango"," Valor medido: "&TEXT($V13,"0.####")&IF($H13="",""," "&$H13)&IF(AND(ISNUMBER($O13),$V13<$O13),", por debajo del límite inferior de "&TEXT($O13,"0.####")&IF($H13="",""," "&$H13),"")&IF(AND(ISNUMBER($P13),$V13>$P13),", por encima del límite superior de "&TEXT($P13,"0.####")&IF($H13="",""," "&$H13),"")&".","")&IF($Y13="",""," "&$Y13&IF(RIGHT($Y13,1)=".","","."))&" Acción recomendada: "&$M13&IF(RIGHT($M13,1)=".","",".")&IF($J13="Bloqueante"," El equipo no se libera hasta resolver este hallazgo.",IF($J13="Cobrable"," Se incluye en la cotización de repuestos y consumibles."," Se deja registrado como observación.")))
A14: 2.1.1 | B14: 2. Identificación y trazabilidad | C14: 2.1 Placas e identificación física | D14: Placa de número de serie frontal | E14: Presencia y legibilidad del número de serie en el panel frontal inferior | F14: Localizar la placa serigrafiada en la parte inferior del panel frontal, leerla y fotografiarla. Contrastar con la orden de servicio y la hoja de vida del equipo. | G14: Texto | I14: Debe ser legible y coincidir con el registro y la hoja de vida de la estación | J14: Alerta | K14: Placa ilegible, despegada, o equipo distinto al de la orden de servicio | L14: 2.1.2 | M14: Registrar el serial real, fotografiarlo y corregir la hoja de vida | N14: La placa de identificación frontal no es legible o no coincide con el equipo registrado en la orden de servicio. | Q14: Sí | R14: No | T14: MT_U7D80D0J_APMA370_260116 | U14: Pendiente | W14: =IF($G14<>"Numérico","",IF($V14="","Sin dato",IF(AND(OR(NOT(ISNUMBER($O14)),$V14>=$O14),OR(NOT(ISNUMBER($P14)),$V14<=$P14)),"Dentro de rango","Fuera de rango"))) | Z14: =IF(OR($U14="",$U14="Conforme",$U14="No aplica",$U14="Pendiente"),"",$N14&IF($W14="Fuera de rango"," Valor medido: "&TEXT($V14,"0.####")&IF($H14="",""," "&$H14)&IF(AND(ISNUMBER($O14),$V14<$O14),", por debajo del límite inferior de "&TEXT($O14,"0.####")&IF($H14="",""," "&$H14),"")&IF(AND(ISNUMBER($P14),$V14>$P14),", por encima del límite superior de "&TEXT($P14,"0.####")&IF($H14="",""," "&$H14),"")&".","")&IF($Y14="",""," "&$Y14&IF(RIGHT($Y14,1)=".","","."))&" Acción recomendada: "&$M14&IF(RIGHT($M14,1)=".","",".")&IF($J14="Bloqueante"," El equipo no se libera hasta resolver este hallazgo.",IF($J14="Cobrable"," Se incluye en la cotización de repuestos y consumibles."," Se deja registrado como observación.")))
A15: 2.1.2 | B15: 2. Identificación y trazabilidad | C15: 2.1 Placas e identificación física | D15: Placa de número de serie posterior | E15: Presencia y legibilidad de la placa de datos metálica HORIBA en el panel trasero | F15: Retirar el equipo del rack lo suficiente para ver el panel trasero, o usar espejo de inspección, y leer la placa metálica de datos HORIBA. Verificar que coincida con el serial frontal. | G15: Texto | I15: Debe ser legible y coincidir con el serial frontal y la etiqueta de la cabina | J15: Alerta | K15: Placa ilegible o no coincide con la frontal | L15: 2.1.1 | M15: Verificar contra la documentación de fábrica y reportar la discrepancia antes de intervenir | N15: La placa de datos del fabricante en el panel posterior no es legible o no coincide con la identificación frontal del equipo. | Q15: Sí | R15: No | T15: MT_U7D80D0J_APMA370_260116 | U15: Pendiente | W15: =IF($G15<>"Numérico","",IF($V15="","Sin dato",IF(AND(OR(NOT(ISNUMBER($O15)),$V15>=$O15),OR(NOT(ISNUMBER($P15)),$V15<=$P15)),"Dentro de rango","Fuera de rango"))) | Z15: =IF(OR($U15="",$U15="Conforme",$U15="No aplica",$U15="Pendiente"),"",$N15&IF($W15="Fuera de rango"," Valor medido: "&TEXT($V15,"0.####")&IF($H15="",""," "&$H15)&IF(AND(ISNUMBER($O15),$V15<$O15),", por debajo del límite inferior de "&TEXT($O15,"0.####")&IF($H15="",""," "&$H15),"")&IF(AND(ISNUMBER($P15),$V15>$P15),", por encima del límite superior de "&TEXT($P15,"0.####")&IF($H15="",""," "&$H15),"")&".","")&IF($Y15="",""," "&$Y15&IF(RIGHT($Y15,1)=".","","."))&" Acción recomendada: "&$M15&IF(RIGHT($M15,1)=".","",".")&IF($J15="Bloqueante"," El equipo no se libera hasta resolver este hallazgo.",IF($J15="Cobrable"," Se incluye en la cotización de repuestos y consumibles."," Se deja registrado como observación.")))
A16: 2.2.1 | B16: 2. Identificación y trazabilidad | C16: 2.2 Identificación lógica | D16: ID del equipo (Machine ID) | E16: Configuración del código ID del analizador para identificación en red | F16: Ir a MENU / SYSTEM / MACHINE ID y leer el valor configurado. Contrastarlo con el mapa de direcciones del sistema de adquisición de la estación. | G16: Numérico | I16: El ID configurado en el menú SYSTEM debe coincidir con el asignado por el sistema de adquisición | J16: Alerta | K16: ID distinto al asignado en el sistema de adquisición | L16: 7.5.1 | M16: Corregir el ID en MENU/SYSTEM y confirmar la llegada del dato al datalogger | N16: El identificador del analizador no coincide con el asignado en el sistema de adquisición de datos de la estación. | O16: 0 | P16: 255 | Q16: Sí | R16: No | T16: P-ST-018-MAN OPER APMA 370 V2 | U16: Pendiente | W16: =IF($G16<>"Numérico","",IF($V16="","Sin dato",IF(AND(OR(NOT(ISNUMBER($O16)),$V16>=$O16),OR(NOT(ISNUMBER($P16)),$V16<=$P16)),"Dentro de rango","Fuera de rango"))) | Z16: =IF(OR($U16="",$U16="Conforme",$U16="No aplica",$U16="Pendiente"),"",$N16&IF($W16="Fuera de rango"," Valor medido: "&TEXT($V16,"0.####")&IF($H16="",""," "&$H16)&IF(AND(ISNUMBER($O16),$V16<$O16),", por debajo del límite inferior de "&TEXT($O16,"0.####")&IF($H16="",""," "&$H16),"")&IF(AND(ISNUMBER($P16),$V16>$P16),", por encima del límite superior de "&TEXT($P16,"0.####")&IF($H16="",""," "&$H16),"")&".","")&IF($Y16="",""," "&$Y16&IF(RIGHT($Y16,1)=".","","."))&" Acción recomendada: "&$M16&IF(RIGHT($M16,1)=".","",".")&IF($J16="Bloqueante"," El equipo no se libera hasta resolver este hallazgo.",IF($J16="Cobrable"," Se incluye en la cotización de repuestos y consumibles."," Se deja registrado como observación.")))
A17: 2.3.1 | B17: 2. Identificación y trazabilidad | C17: 2.3 Etiquetas de seguridad | D17: Señalización de choque eléctrico | E17: Etiquetas de advertencia de alto voltaje en cubiertas de placas y transformadores | F17: Con el equipo apagado y desconectado, retirar la cubierta superior y verificar visualmente la presencia y legibilidad de las etiquetas de advertencia sobre cubiertas de tarjetas y transformador. | G17: Presente / Ausente | I17: Deben estar adheridas y legibles las advertencias Choque eléctrico 1, 2 y 3 | J17: Alerta | K17: Etiqueta desprendida o ilegible por limpieza con solventes | L17: Nodo terminal — actuar directamente | M17: Reponer la etiqueta de seguridad y dejar constancia del faltante | N17: Faltan o no son legibles las etiquetas de advertencia de riesgo eléctrico en el interior del analizador. | Q17: Sí | R17: Sí | T17: P-ST-019-MAN MTTO APMA370 V2 | U17: Pendiente | W17: =IF($G17<>"Numérico","",IF($V17="","Sin dato",IF(AND(OR(NOT(ISNUMBER($O17)),$V17>=$O17),OR(NOT(ISNUMBER($P17)),$V17<=$P17)),"Dentro de rango","Fuera de rango"))) | Z17: =IF(OR($U17="",$U17="Conforme",$U17="No aplica",$U17="Pendiente"),"",$N17&IF($W17="Fuera de rango"," Valor medido: "&TEXT($V17,"0.####")&IF($H17="",""," "&$H17)&IF(AND(ISNUMBER($O17),$V17<$O17),", por debajo del límite inferior de "&TEXT($O17,"0.####")&IF($H17="",""," "&$H17),"")&IF(AND(ISNUMBER($P17),$V17>$P17),", por encima del límite superior de "&TEXT($P17,"0.####")&IF($H17="",""," "&$H17),"")&".","")&IF($Y17="",""," "&$Y17&IF(RIGHT($Y17,1)=".","","."))&" Acción recomendada: "&$M17&IF(RIGHT($M17,1)=".","",".")&IF($J17="Bloqueante"," El equipo no se libera hasta resolver este hallazgo.",IF($J17="Cobrable"," Se incluye en la cotización de repuestos y consumibles."," Se deja registrado como observación.")))
A18: 2.3.2 | B18: 2. Identificación y trazabilidad | C18: 2.3 Etiquetas de seguridad | D18: Señalización de componentes calientes | E18: Etiquetas adhesivas amarillas de advertencia térmica en zonas de alta temperatura | F18: Con el equipo frío y desconectado, retirar la cubierta superior y verificar la presencia de las etiquetas amarillas de advertencia térmica sobre la carcasa del catalizador y de la bomba. | G18: Presente / Ausente | I18: Deben estar adheridas las etiquetas de calor sobre la carcasa del catalizador y de la bomba | J18: Alerta | K18: Etiqueta desprendida por el calor del catalizador o de la bomba | L18: Nodo terminal — actuar directamente | M18: Reponer la etiqueta de advertencia térmica | N18: Faltan o no son legibles las etiquetas de advertencia de superficies calientes sobre el catalizador y la bomba. | Q18: Sí | R18: Sí | T18: P-ST-019-MAN MTTO APMA370 V2 | U18: Pendiente | W18: =IF($G18<>"Numérico","",IF($V18="","Sin dato",IF(AND(OR(NOT(ISNUMBER($O18)),$V18>=$O18),OR(NOT(ISNUMBER($P18)),$V18<=$P18)),"Dentro de rango","Fuera de rango"))) | Z18: =IF(OR($U18="",$U18="Conforme",$U18="No aplica",$U18="Pendiente"),"",$N18&IF($W18="Fuera de rango"," Valor medido: "&TEXT($V18,"0.####")&IF($H18="",""," "&$H18)&IF(AND(ISNUMBER($O18),$V18<$O18),", por debajo del límite inferior de "&TEXT($O18,"0.####")&IF($H18="",""," "&$H18),"")&IF(AND(ISNUMBER($P18),$V18>$P18),", por encima del límite superior de "&TEXT($P18,"0.####")&IF($H18="",""," "&$H18),"")&".","")&IF($Y18="",""," "&$Y18&IF(RIGHT($Y18,1)=".","","."))&" Acción recomendada: "&$M18&IF(RIGHT($M18,1)=".","",".")&IF($J18="Bloqueante"," El equipo no se libera hasta resolver este hallazgo.",IF($J18="Cobrable"," Se incluye en la cotización de repuestos y consumibles."," Se deja registrado como observación.")))
A19: 3.1.1 | B19: 3. Estado de calibración | C19: 3.1 Coeficientes de calibración | D19: Coeficiente de calibración de cero | E19: Factor de corrección de cero almacenado tras el último ajuste manual o AIC | F19: Ir a MENU / CAL. y leer el valor del coeficiente ZERO en pantalla. Anotarlo antes de realizar cualquier calibración; si parpadea, indica alarma de cero. | G19: Numérico | H19: counts | I19: Debe estar dentro del rango operativo; fuera de él parpadea la alarma ZERO | J19: Bloqueante | K19: Aire cero contaminado, calentamiento insuficiente, catalizador CAT-1 agotado o humedad en la línea de referencia | L19: 1.3.1 ; 6.4.1 ; 4.3.1 ; 5.3.2 ; 3.2.1 | M19: Inyectar aire cero de cilindro certificado para descartar el generador; si persiste, seguir la rama de catalizador y humedad | N19: El coeficiente de calibración de cero se encuentra fuera del rango admisible, por lo que la calibración del punto cero no es válida. | O19: -3500 | P19: 3500 | Q19: Sí | R19: No | T19: P-ST-018-MAN OPER APMA 370 V2 | U19: Pendiente | W19: =IF($G19<>"Numérico","",IF($V19="","Sin dato",IF(AND(OR(NOT(ISNUMBER($O19)),$V19>=$O19),OR(NOT(ISNUMBER($P19)),$V19<=$P19)),"Dentro de rango","Fuera de rango"))) | Z19: =IF(OR($U19="",$U19="Conforme",$U19="No aplica",$U19="Pendiente"),"",$N19&IF($W19="Fuera de rango"," Valor medido: "&TEXT($V19,"0.####")&IF($H19="",""," "&$H19)&IF(AND(ISNUMBER($O19),$V19<$O19),", por debajo del límite inferior de "&TEXT($O19,"0.####")&IF($H19="",""," "&$H19),"")&IF(AND(ISNUMBER($P19),$V19>$P19),", por encima del límite superior de "&TEXT($P19,"0.####")&IF($H19="",""," "&$H19),"")&".","")&IF($Y19="",""," "&$Y19&IF(RIGHT($Y19,1)=".","","."))&" Acción recomendada: "&$M19&IF(RIGHT($M19,1)=".","",".")&IF($J19="Bloqueante"," El equipo no se libera hasta resolver este hallazgo.",IF($J19="Cobrable"," Se incluye en la cotización de repuestos y consumibles."," Se deja registrado como observación.")))
A20: 3.1.2 | B20: 3. Estado de calibración | C20: 3.1 Coeficientes de calibración | D20: Coeficiente de calibración de span | E20: Ganancia del detector de CO calibrada con gas patrón y almacenada en memoria | F20: Ir a MENU / CAL. y leer el valor del coeficiente SPAN en pantalla. Anotarlo antes de calibrar; si parpadea, indica alarma de span. | G20: Numérico | I20: Debe estar dentro de los límites de amplificación admitidos; fuera de él parpadea la alarma SPAN | J20: Bloqueante | K20: Concentración del patrón mal configurada, caudal de exceso insuficiente, o pérdida de intensidad óptica | L20: 3.2.1 ; 3.2.2 ; 6.1.1 ; 6.2.2 ; 6.2.1 | M20: Confirmar SPAN CONC. contra el certificado del cilindro y volver a calibrar | N20: El coeficiente de calibración de span se encuentra fuera del rango admisible, por lo que la calibración de sensibilidad no es válida. | O20: 0.5 | P20: 2 | Q20: Sí | R20: No | T20: P-ST-018-MAN OPER APMA 370 V2 | U20: Pendiente | W20: =IF($G20<>"Numérico","",IF($V20="","Sin dato",IF(AND(OR(NOT(ISNUMBER($O20)),$V20>=$O20),OR(NOT(ISNUMBER($P20)),$V20<=$P20)),"Dentro de rango","Fuera de rango"))) | Z20: =IF(OR($U20="",$U20="Conforme",$U20="No aplica",$U20="Pendiente"),"",$N20&IF($W20="Fuera de rango"," Valor medido: "&TEXT($V20,"0.####")&IF($H20="",""," "&$H20)&IF(AND(ISNUMBER($O20),$V20<$O20),", por debajo del límite inferior de "&TEXT($O20,"0.####")&IF($H20="",""," "&$H20),"")&IF(AND(ISNUMBER($P20),$V20>$P20),", por encima del límite superior de "&TEXT($P20,"0.####")&IF($H20="",""," "&$H20),"")&".","")&IF($Y20="",""," "&$Y20&IF(RIGHT($Y20,1)=".","","."))&" Acción recomendada: "&$M20&IF(RIGHT($M20,1)=".","",".")&IF($J20="Bloqueante"," El equipo no se libera hasta resolver este hallazgo.",IF($J20="Cobrable"," Se incluye en la cotización de repuestos y consumibles."," Se deja registrado como observación.")))
A21: 3.2.1 | B21: 3. Estado de calibración | C21: 3.2 Suministro de gases patrón | D21: Presión de entrada de gas patrón | E21: Presión de entrega de gases de referencia (cero y span) en las entradas traseras | F21: Conectar un manómetro de baja presión en la línea de gas patrón, aguas arriba de la entrada CAL GAS INLET, y leer la presión con el gas fluyendo. Ajustar en el regulador del cilindro. | G21: Numérico | H21: kPa | I21: Deben entregarse ligeramente por encima de la presión atmosférica para generar overflow | J21: Bloqueante | K21: Regulador del cilindro mal ajustado o cilindro despresurizado | L21: 3.2.2 | M21: Reajustar el regulador de doble etapa hasta lograr overflow estable | N21: La presión de entrega del gas patrón no es la adecuada, lo que compromete la validez de la calibración. | O21: 0 | P21: 0.5 | Q21: Sí | R21: No | T21: P-ST-018-MAN OPER APMA 370 V2 | U21: Pendiente | W21: =IF($G21<>"Numérico","",IF($V21="","Sin dato",IF(AND(OR(NOT(ISNUMBER($O21)),$V21>=$O21),OR(NOT(ISNUMBER($P21)),$V21<=$P21)),"Dentro de rango","Fuera de rango"))) | Z21: =IF(OR($U21="",$U21="Conforme",$U21="No aplica",$U21="Pendiente"),"",$N21&IF($W21="Fuera de rango"," Valor medido: "&TEXT($V21,"0.####")&IF($H21="",""," "&$H21)&IF(AND(ISNUMBER($O21),$V21<$O21),", por debajo del límite inferior de "&TEXT($O21,"0.####")&IF($H21="",""," "&$H21),"")&IF(AND(ISNUMBER($P21),$V21>$P21),", por encima del límite superior de "&TEXT($P21,"0.####")&IF($H21="",""," "&$H21),"")&".","")&IF($Y21="",""," "&$Y21&IF(RIGHT($Y21,1)=".","","."))&" Acción recomendada: "&$M21&IF(RIGHT($M21,1)=".","",".")&IF($J21="Bloqueante"," El equipo no se libera hasta resolver este hallazgo.",IF($J21="Cobrable"," Se incluye en la cotización de repuestos y consumibles."," Se deja registrado como observación.")))
A22: 3.2.2 | B22: 3. Estado de calibración | C22: 3.2 Suministro de gases patrón | D22: Caudal de exceso de gas de calibración (OVER FLOW) | E22: Caudal excedente medido por el sensor de flujo opcional de calibración | F22: Con el gas patrón fluyendo, leer el caudal de exceso en MENU / MAINTENANCE / ANALOG INPUT, o medirlo con flujómetro de burbuja en la salida de venteo del arreglo de calibración. | G22: Numérico | H22: L/min | I22: Caudal mínimo 1,2 L/min para que el analizador absorba gas patrón sin aspirar aire ambiente. Límite superior PENDIENTE DE VALIDAR | J22: Bloqueante | K22: Caudal insuficiente: el analizador aspira aire ambiente mezclado con el patrón | L22: 3.2.1 ; 5.3.2 | M22: Subir el caudal por encima de 1,2 L/min y repetir la calibración | N22: El caudal de exceso del gas de calibración es insuficiente: el analizador aspira aire ambiente mezclado con el gas patrón. | O22: 1.2 | Q22: Sí | R22: No | T22: P-ST-018-MAN OPER APMA 370 V2 | U22: Pendiente | W22: =IF($G22<>"Numérico","",IF($V22="","Sin dato",IF(AND(OR(NOT(ISNUMBER($O22)),$V22>=$O22),OR(NOT(ISNUMBER($P22)),$V22<=$P22)),"Dentro de rango","Fuera de rango"))) | Z22: =IF(OR($U22="",$U22="Conforme",$U22="No aplica",$U22="Pendiente"),"",$N22&IF($W22="Fuera de rango"," Valor medido: "&TEXT($V22,"0.####")&IF($H22="",""," "&$H22)&IF(AND(ISNUMBER($O22),$V22<$O22),", por debajo del límite inferior de "&TEXT($O22,"0.####")&IF($H22="",""," "&$H22),"")&IF(AND(ISNUMBER($P22),$V22>$P22),", por encima del límite superior de "&TEXT($P22,"0.####")&IF($H22="",""," "&$H22),"")&".","")&IF($Y22="",""," "&$Y22&IF(RIGHT($Y22,1)=".","","."))&" Acción recomendada: "&$M22&IF(RIGHT($M22,1)=".","",".")&IF($J22="Bloqueante"," El equipo no se libera hasta resolver este hallazgo.",IF($J22="Cobrable"," Se incluye en la cotización de repuestos y consumibles."," Se deja registrado como observación.")))
A23: 3.3.1 | B23: 3. Estado de calibración | C23: 3.3 Secuencia de autocalibración (AIC) | D23: Tiempo de espera (WAIT) en AIC | E23: Tiempo configurado para purgar la celda y estabilizar lecturas tras conmutar la línea de gas | F23: Ir a MENU / MAINTENANCE / AIC y leer el tiempo WAIT configurado. Anotarlo y compararlo con el mínimo recomendado por el fabricante. | G23: Numérico | H23: minutos | I23: Tiempo mínimo de retardo tras conmutar la línea de gas; el fabricante recomienda 3 min o más | J23: Alerta | K23: Tiempo insuficiente para purgar la línea de calibración | L23: Nodo terminal — actuar directamente | M23: Subir el WAIT a 3 min o más, según la longitud de la línea instalada | N23: El tiempo de espera de la secuencia de autocalibración es insuficiente para purgar la línea antes de tomar la lectura. | O23: 3 | P23: 999 | Q23: Sí | R23: No | T23: P-ST-018-MAN OPER APMA 370 V2 | U23: Pendiente | W23: =IF($G23<>"Numérico","",IF($V23="","Sin dato",IF(AND(OR(NOT(ISNUMBER($O23)),$V23>=$O23),OR(NOT(ISNUMBER($P23)),$V23<=$P23)),"Dentro de rango","Fuera de rango"))) | Z23: =IF(OR($U23="",$U23="Conforme",$U23="No aplica",$U23="Pendiente"),"",$N23&IF($W23="Fuera de rango"," Valor medido: "&TEXT($V23,"0.####")&IF($H23="",""," "&$H23)&IF(AND(ISNUMBER($O23),$V23<$O23),", por debajo del límite inferior de "&TEXT($O23,"0.####")&IF($H23="",""," "&$H23),"")&IF(AND(ISNUMBER($P23),$V23>$P23),", por encima del límite superior de "&TEXT($P23,"0.####")&IF($H23="",""," "&$H23),"")&".","")&IF($Y23="",""," "&$Y23&IF(RIGHT($Y23,1)=".","","."))&" Acción recomendada: "&$M23&IF(RIGHT($M23,1)=".","",".")&IF($J23="Bloqueante"," El equipo no se libera hasta resolver este hallazgo.",IF($J23="Cobrable"," Se incluye en la cotización de repuestos y consumibles."," Se deja registrado como observación.")))
A24: 3.3.2 | B24: 3. Estado de calibración | C24: 3.3 Secuencia de autocalibración (AIC) | D24: Tiempo de sostenimiento (HOLD) en AIC | E24: Tiempo de retención y chequeo de lecturas de salida al finalizar el AIC | F24: Ir a MENU / MAINTENANCE / AIC y leer el tiempo HOLD configurado. Anotarlo junto con el resto de parámetros de la secuencia. | G24: Numérico | H24: minutos | I24: Tiempo de validación posterior a la calibración física de las señales analógicas | J24: Alerta | K24: Parámetro distinto al acordado con la red de monitoreo | L24: Nodo terminal — actuar directamente | M24: Ajustar el HOLD al valor definido por el operador de la red | N24: El tiempo de sostenimiento de la secuencia de autocalibración no corresponde al definido para la red de monitoreo. | O24: 0 | P24: 999 | Q24: Sí | R24: No | T24: P-ST-018-MAN OPER APMA 370 V2 | U24: Pendiente | W24: =IF($G24<>"Numérico","",IF($V24="","Sin dato",IF(AND(OR(NOT(ISNUMBER($O24)),$V24>=$O24),OR(NOT(ISNUMBER($P24)),$V24<=$P24)),"Dentro de rango","Fuera de rango"))) | Z24: =IF(OR($U24="",$U24="Conforme",$U24="No aplica",$U24="Pendiente"),"",$N24&IF($W24="Fuera de rango"," Valor medido: "&TEXT($V24,"0.####")&IF($H24="",""," "&$H24)&IF(AND(ISNUMBER($O24),$V24<$O24),", por debajo del límite inferior de "&TEXT($O24,"0.####")&IF($H24="",""," "&$H24),"")&IF(AND(ISNUMBER($P24),$V24>$P24),", por encima del límite superior de "&TEXT($P24,"0.####")&IF($H24="",""," "&$H24),"")&".","")&IF($Y24="",""," "&$Y24&IF(RIGHT($Y24,1)=".","","."))&" Acción recomendada: "&$M24&IF(RIGHT($M24,1)=".","",".")&IF($J24="Bloqueante"," El equipo no se libera hasta resolver este hallazgo.",IF($J24="Cobrable"," Se incluye en la cotización de repuestos y consumibles."," Se deja registrado como observación.")))
A25: 3.3.3 | B25: 3. Estado de calibración | C25: 3.3 Secuencia de autocalibración (AIC) | D25: Activación de calibración (CAL) en AIC | E25: Selección de la corrección física del factor cero/span durante el AIC | F25: Ir a MENU / MAINTENANCE / AIC y leer el ajuste CAL (YES / NO). Confirmar con el responsable de la red si la política es corregir factores o solo verificar. | G25: Sí/No | I25: Define si se corrigen factores (YES) o solo se realiza lectura de verificación (NO) | J25: Alerta | K25: Ajuste incoherente con la política de la red (corregir factores vs. solo verificar) | L25: Nodo terminal — actuar directamente | M25: Definirlo con el responsable de la red y dejarlo documentado | N25: La opción de corrección automática de la secuencia de autocalibración no corresponde a la política definida para la estación. | Q25: Sí | R25: No | T25: P-ST-018-MAN OPER APMA 370 V2 | U25: Pendiente | W25: =IF($G25<>"Numérico","",IF($V25="","Sin dato",IF(AND(OR(NOT(ISNUMBER($O25)),$V25>=$O25),OR(NOT(ISNUMBER($P25)),$V25<=$P25)),"Dentro de rango","Fuera de rango"))) | Z25: =IF(OR($U25="",$U25="Conforme",$U25="No aplica",$U25="Pendiente"),"",$N25&IF($W25="Fuera de rango"," Valor medido: "&TEXT($V25,"0.####")&IF($H25="",""," "&$H25)&IF(AND(ISNUMBER($O25),$V25<$O25),", por debajo del límite inferior de "&TEXT($O25,"0.####")&IF($H25="",""," "&$H25),"")&IF(AND(ISNUMBER($P25),$V25>$P25),", por encima del límite superior de "&TEXT($P25,"0.####")&IF($H25="",""," "&$H25),"")&".","")&IF($Y25="",""," "&$Y25&IF(RIGHT($Y25,1)=".","","."))&" Acción recomendada: "&$M25&IF(RIGHT($M25,1)=".","",".")&IF($J25="Bloqueante"," El equipo no se libera hasta resolver este hallazgo.",IF($J25="Cobrable"," Se incluye en la cotización de repuestos y consumibles."," Se deja registrado como observación.")))
A26: 4.1.1 | B26: 4. Línea de muestreo y acondicionamiento | C26: 4.1 Conectores neumáticos traseros | D26: Férula de Sample Inlet (Sleeve) | E26: Presencia del casquillo de teflón de sellado interno en la entrada de muestra | F26: Aflojar la tuerca del puerto SAMPLE INLET en el panel trasero, extraer la manguera y verificar que la férula de teflón esté montada sobre el tubo. Volver a montar sin sobreapretar. | G26: Presente / Ausente | I26: Debe estar montada la férula para asegurar acople hermético libre de aire falso | J26: Bloqueante | K26: Férula ausente o mal montada: ingreso de aire falso por la entrada de muestra | L26: 5.3.2 ; 5.1.1 ; 3.1.1 | M26: Instalar la férula, reapretar y repetir la prueba de estanqueidad antes de calibrar | N26: Falta la férula de sellado en la entrada de muestra, lo que permite el ingreso de aire ambiente y altera la medición. | Q26: Sí | R26: Sí | S26: Sleeve / SO2001-6 (3030021777) | T26: MT_P4B4CK60_APMA370_220511 | U26: Pendiente | W26: =IF($G26<>"Numérico","",IF($V26="","Sin dato",IF(AND(OR(NOT(ISNUMBER($O26)),$V26>=$O26),OR(NOT(ISNUMBER($P26)),$V26<=$P26)),"Dentro de rango","Fuera de rango"))) | Z26: =IF(OR($U26="",$U26="Conforme",$U26="No aplica",$U26="Pendiente"),"",$N26&IF($W26="Fuera de rango"," Valor medido: "&TEXT($V26,"0.####")&IF($H26="",""," "&$H26)&IF(AND(ISNUMBER($O26),$V26<$O26),", por debajo del límite inferior de "&TEXT($O26,"0.####")&IF($H26="",""," "&$H26),"")&IF(AND(ISNUMBER($P26),$V26>$P26),", por encima del límite superior de "&TEXT($P26,"0.####")&IF($H26="",""," "&$H26),"")&".","")&IF($Y26="",""," "&$Y26&IF(RIGHT($Y26,1)=".","","."))&" Acción recomendada: "&$M26&IF(RIGHT($M26,1)=".","",".")&IF($J26="Bloqueante"," El equipo no se libera hasta resolver este hallazgo.",IF($J26="Cobrable"," Se incluye en la cotización de repuestos y consumibles."," Se deja registrado como observación.")))
A27: 4.1.2 | B27: 4. Línea de muestreo y acondicionamiento | C27: 4.1 Conectores neumáticos traseros | D27: Tuerca de Sample Inlet (Cap Nut) | E27: Presencia de la tuerca plástica de rosca fina en la entrada de muestra | F27: Inspeccionar visualmente el puerto SAMPLE INLET y comprobar que la tuerca de PVDF esté presente y roscada. Verificar el apriete manualmente, sin herramienta. | G27: Presente / Ausente | I27: Debe estar presente y roscada firmemente la tuerca PVDF para sellar la tubería | J27: Bloqueante | K27: Tuerca ausente, fisurada o floja | L27: 5.3.2 ; 4.1.1 | M27: Reponer la tuerca de PVDF y repetir la prueba de estanqueidad | N27: La tuerca de sellado de la entrada de muestra está ausente, fisurada o floja, con riesgo de fuga. | Q27: Sí | R27: Sí | S27: Cap Nut / S020020-6PVDF (3030021779) | T27: MT_P4B4CK60_APMA370_220511 | U27: Pendiente | W27: =IF($G27<>"Numérico","",IF($V27="","Sin dato",IF(AND(OR(NOT(ISNUMBER($O27)),$V27>=$O27),OR(NOT(ISNUMBER($P27)),$V27<=$P27)),"Dentro de rango","Fuera de rango"))) | Z27: =IF(OR($U27="",$U27="Conforme",$U27="No aplica",$U27="Pendiente"),"",$N27&IF($W27="Fuera de rango"," Valor medido: "&TEXT($V27,"0.####")&IF($H27="",""," "&$H27)&IF(AND(ISNUMBER($O27),$V27<$O27),", por debajo del límite inferior de "&TEXT($O27,"0.####")&IF($H27="",""," "&$H27),"")&IF(AND(ISNUMBER($P27),$V27>$P27),", por encima del límite superior de "&TEXT($P27,"0.####")&IF($H27="",""," "&$H27),"")&".","")&IF($Y27="",""," "&$Y27&IF(RIGHT($Y27,1)=".","","."))&" Acción recomendada: "&$M27&IF(RIGHT($M27,1)=".","",".")&IF($J27="Bloqueante"," El equipo no se libera hasta resolver este hallazgo.",IF($J27="Cobrable"," Se incluye en la cotización de repuestos y consumibles."," Se deja registrado como observación.")))
A28: 4.1.3 | B28: 4. Línea de muestreo y acondicionamiento | C28: 4.1 Conectores neumáticos traseros | D28: Férula de Exhaust (Sleeve) | E28: Presencia del casquillo de teflón de sellado interno en la salida de escape | F28: Aflojar la tuerca del puerto EXHAUST, extraer la manguera y verificar que la férula de teflón esté montada sobre el tubo. Volver a montar sin sobreapretar. | G28: Presente / Ausente | I28: Debe estar montada la férula para evitar fugas de gases de escape hacia la cabina | J28: Bloqueante | K28: Férula ausente: fuga de gases de escape hacia la cabina | L28: 5.3.2 | M28: Instalar la férula y verificar que el escape quede canalizado | N28: Falta la férula de sellado en la salida de escape, lo que permite la fuga de los gases de descarga hacia la cabina. | Q28: Sí | R28: Sí | S28: Sleeve / SO2001-6 (3030021777) | T28: MT_P4B4CK60_APMA370_220511 | U28: Pendiente | W28: =IF($G28<>"Numérico","",IF($V28="","Sin dato",IF(AND(OR(NOT(ISNUMBER($O28)),$V28>=$O28),OR(NOT(ISNUMBER($P28)),$V28<=$P28)),"Dentro de rango","Fuera de rango"))) | Z28: =IF(OR($U28="",$U28="Conforme",$U28="No aplica",$U28="Pendiente"),"",$N28&IF($W28="Fuera de rango"," Valor medido: "&TEXT($V28,"0.####")&IF($H28="",""," "&$H28)&IF(AND(ISNUMBER($O28),$V28<$O28),", por debajo del límite inferior de "&TEXT($O28,"0.####")&IF($H28="",""," "&$H28),"")&IF(AND(ISNUMBER($P28),$V28>$P28),", por encima del límite superior de "&TEXT($P28,"0.####")&IF($H28="",""," "&$H28),"")&".","")&IF($Y28="",""," "&$Y28&IF(RIGHT($Y28,1)=".","","."))&" Acción recomendada: "&$M28&IF(RIGHT($M28,1)=".","",".")&IF($J28="Bloqueante"," El equipo no se libera hasta resolver este hallazgo.",IF($J28="Cobrable"," Se incluye en la cotización de repuestos y consumibles."," Se deja registrado como observación.")))
A29: 4.1.4 | B29: 4. Línea de muestreo y acondicionamiento | C29: 4.1 Conectores neumáticos traseros | D29: Tuerca de Exhaust (Cap Nut) | E29: Presencia de la tuerca plástica de rosca fina en la salida de escape | F29: Inspeccionar visualmente el puerto EXHAUST y comprobar que la tuerca de PVDF esté presente y roscada. Verificar el apriete manualmente, sin herramienta. | G29: Presente / Ausente | I29: Debe estar presente y roscada firmemente la tuerca PVDF para canalizar el escape | J29: Bloqueante | K29: Tuerca ausente o floja en la salida de escape | L29: 5.3.2 ; 4.1.3 | M29: Reponer la tuerca de PVDF y reapretar | N29: La tuerca de sellado de la salida de escape está ausente, fisurada o floja. | Q29: Sí | R29: Sí | S29: Cap Nut / S020020-6PVDF (3030021779) | T29: MT_P4B4CK60_APMA370_220511 | U29: Pendiente | W29: =IF($G29<>"Numérico","",IF($V29="","Sin dato",IF(AND(OR(NOT(ISNUMBER($O29)),$V29>=$O29),OR(NOT(ISNUMBER($P29)),$V29<=$P29)),"Dentro de rango","Fuera de rango"))) | Z29: =IF(OR($U29="",$U29="Conforme",$U29="No aplica",$U29="Pendiente"),"",$N29&IF($W29="Fuera de rango"," Valor medido: "&TEXT($V29,"0.####")&IF($H29="",""," "&$H29)&IF(AND(ISNUMBER($O29),$V29<$O29),", por debajo del límite inferior de "&TEXT($O29,"0.####")&IF($H29="",""," "&$H29),"")&IF(AND(ISNUMBER($P29),$V29>$P29),", por encima del límite superior de "&TEXT($P29,"0.####")&IF($H29="",""," "&$H29),"")&".","")&IF($Y29="",""," "&$Y29&IF(RIGHT($Y29,1)=".","","."))&" Acción recomendada: "&$M29&IF(RIGHT($M29,1)=".","",".")&IF($J29="Bloqueante"," El equipo no se libera hasta resolver este hallazgo.",IF($J29="Cobrable"," Se incluye en la cotización de repuestos y consumibles."," Se deja registrado como observación.")))
A30: 4.1.5 | B30: 4. Línea de muestreo y acondicionamiento | C30: 4.1 Conectores neumáticos traseros | D30: Panel Mount Union (SO21521-6 PVDF) | E30: Estado físico e integridad del racor plástico de montaje de panel | F30: Con las mangueras retiradas, inspeccionar el racor pasamuros del panel trasero buscando fisuras en la rosca, deformación o material fatigado. Iluminar con linterna. | G30: OK / No OK | I30: Racor libre de fisuras en su rosca o fatiga de material por sobreajuste | J30: Bloqueante | K30: Racor fisurado por sobreapriete o fatiga del plástico | L30: 5.3.2 | M30: Reemplazar el racor pasamuros y repetir la prueba de estanqueidad | N30: El racor de montaje del panel posterior presenta fisuras o fatiga del material, con riesgo de fuga. | Q30: Sí | R30: Sí | S30: Panel mount union SO21521- 6(PVDF)SP SW1=14 (3030021548) | T30: MT_191TE0NC_APMA370_241226 | U30: Pendiente | W30: =IF($G30<>"Numérico","",IF($V30="","Sin dato",IF(AND(OR(NOT(ISNUMBER($O30)),$V30>=$O30),OR(NOT(ISNUMBER($P30)),$V30<=$P30)),"Dentro de rango","Fuera de rango"))) | Z30: =IF(OR($U30="",$U30="Conforme",$U30="No aplica",$U30="Pendiente"),"",$N30&IF($W30="Fuera de rango"," Valor medido: "&TEXT($V30,"0.####")&IF($H30="",""," "&$H30)&IF(AND(ISNUMBER($O30),$V30<$O30),", por debajo del límite inferior de "&TEXT($O30,"0.####")&IF($H30="",""," "&$H30),"")&IF(AND(ISNUMBER($P30),$V30>$P30),", por encima del límite superior de "&TEXT($P30,"0.####")&IF($H30="",""," "&$H30),"")&".","")&IF($Y30="",""," "&$Y30&IF(RIGHT($Y30,1)=".","","."))&" Acción recomendada: "&$M30&IF(RIGHT($M30,1)=".","",".")&IF($J30="Bloqueante"," El equipo no se libera hasta resolver este hallazgo.",IF($J30="Cobrable"," Se incluye en la cotización de repuestos y consumibles."," Se deja registrado como observación.")))
A31: 4.2.1 | B31: 4. Línea de muestreo y acondicionamiento | C31: 4.2 Portafiltros frontal | D31: Colmatación del filtro de partículas PA-10L | E31: Nivel de colmatación, hollín, polvo o humedad en el filtro frontal de teflón de 54 mm | F31: Abrir la puerta frontal, desenroscar el vaso del portafiltros, extraer el elemento y compararlo contra un filtro nuevo sobre fondo blanco. Fotografiar antes de reemplazar. | G31: OK / No OK | I31: Filtro de teflón blanco uniforme, sin partículas ni manchas oscuras que estrangulen el caudal | J31: Cobrable | K31: Filtro saturado de material particulado, hollín o humedad | L31: 5.1.2 ; 5.1.1 ; 8.1.1 | M31: Reemplazar el elemento filtrante y reiniciar su horómetro | N31: El filtro de partículas se encuentra colmatado, lo que restringe el caudal de muestra. | Q31: Sí | R31: Sí | S31: Filter Element PA-10L diámetro 54*0.5t (24pc/set) (3200043947; alt. 3200043947-1PC) | T31: MT_56X1BA8G_APMA370_260109 | U31: Pendiente | W31: =IF($G31<>"Numérico","",IF($V31="","Sin dato",IF(AND(OR(NOT(ISNUMBER($O31)),$V31>=$O31),OR(NOT(ISNUMBER($P31)),$V31<=$P31)),"Dentro de rango","Fuera de rango"))) | Z31: =IF(OR($U31="",$U31="Conforme",$U31="No aplica",$U31="Pendiente"),"",$N31&IF($W31="Fuera de rango"," Valor medido: "&TEXT($V31,"0.####")&IF($H31="",""," "&$H31)&IF(AND(ISNUMBER($O31),$V31<$O31),", por debajo del límite inferior de "&TEXT($O31,"0.####")&IF($H31="",""," "&$H31),"")&IF(AND(ISNUMBER($P31),$V31>$P31),", por encima del límite superior de "&TEXT($P31,"0.####")&IF($H31="",""," "&$H31),"")&".","")&IF($Y31="",""," "&$Y31&IF(RIGHT($Y31,1)=".","","."))&" Acción recomendada: "&$M31&IF(RIGHT($M31,1)=".","",".")&IF($J31="Bloqueante"," El equipo no se libera hasta resolver este hallazgo.",IF($J31="Cobrable"," Se incluye en la cotización de repuestos y consumibles."," Se deja registrado como observación.")))
A32: 4.2.2 | B32: 4. Línea de muestreo y acondicionamiento | C32: 4.2 Portafiltros frontal | D32: Empaque del filtro frontal (PA-10L) | E32: Flexibilidad y ausencia de grietas en la junta elástica plana del portafiltros | F32: Con el portafiltros abierto, retirar el empaque plano, flexionarlo entre los dedos y buscar grietas, aplastamiento permanente o pérdida de elasticidad. | G32: OK / No OK | I32: Empaque blando, sin aplastamientos ni deformaciones permanentes que provoquen fugas | J32: Cobrable | K32: Empaque endurecido o aplastado: fuga en el portafiltros | L32: 5.3.2 | M32: Reemplazar el empaque y repetir la prueba de estanqueidad | N32: El empaque del portafiltros ha perdido elasticidad y no garantiza el sello del alojamiento del filtro. | Q32: Sí | R32: Sí | S32: F-Packing FPM (3200044273) | T32: P-ST-019-MAN MTTO APMA370 V2 | U32: Pendiente | W32: =IF($G32<>"Numérico","",IF($V32="","Sin dato",IF(AND(OR(NOT(ISNUMBER($O32)),$V32>=$O32),OR(NOT(ISNUMBER($P32)),$V32<=$P32)),"Dentro de rango","Fuera de rango"))) | Z32: =IF(OR($U32="",$U32="Conforme",$U32="No aplica",$U32="Pendiente"),"",$N32&IF($W32="Fuera de rango"," Valor medido: "&TEXT($V32,"0.####")&IF($H32="",""," "&$H32)&IF(AND(ISNUMBER($O32),$V32<$O32),", por debajo del límite inferior de "&TEXT($O32,"0.####")&IF($H32="",""," "&$H32),"")&IF(AND(ISNUMBER($P32),$V32>$P32),", por encima del límite superior de "&TEXT($P32,"0.####")&IF($H32="",""," "&$H32),"")&".","")&IF($Y32="",""," "&$Y32&IF(RIGHT($Y32,1)=".","","."))&" Acción recomendada: "&$M32&IF(RIGHT($M32,1)=".","",".")&IF($J32="Bloqueante"," El equipo no se libera hasta resolver este hallazgo.",IF($J32="Cobrable"," Se incluye en la cotización de repuestos y consumibles."," Se deja registrado como observación.")))
A33: 4.2.3 | B33: 4. Línea de muestreo y acondicionamiento | C33: 4.2 Portafiltros frontal | D33: Junta tórica del portafiltros (O-Ring) | E33: Resequedad, microfisuras o deformación de la junta tórica de la tapa del filtro | F33: Retirar la junta tórica de la tapa del portafiltros, limpiarla y examinarla estirándola suavemente contra la luz, buscando microfisuras, resequedad o deformación. | G33: OK / No OK | I33: Junta de vitón elástica y ligeramente lubricada para garantizar hermetismo de la tapa | J33: Cobrable | K33: Junta reseca o con microfisuras: fuga en la tapa | L33: 5.3.2 | M33: Reemplazar la junta tórica y lubricarla levemente al montar | N33: La junta tórica de la tapa del portafiltros presenta resequedad o microfisuras y no garantiza la hermeticidad. | Q33: Sí | R33: Sí | S33: O-Ring JISB2401 G70 (3200043785) | T33: P-ST-019-MAN MTTO APMA370 V2 | U33: Pendiente | W33: =IF($G33<>"Numérico","",IF($V33="","Sin dato",IF(AND(OR(NOT(ISNUMBER($O33)),$V33>=$O33),OR(NOT(ISNUMBER($P33)),$V33<=$P33)),"Dentro de rango","Fuera de rango"))) | Z33: =IF(OR($U33="",$U33="Conforme",$U33="No aplica",$U33="Pendiente"),"",$N33&IF($W33="Fuera de rango"," Valor medido: "&TEXT($V33,"0.####")&IF($H33="",""," "&$H33)&IF(AND(ISNUMBER($O33),$V33<$O33),", por debajo del límite inferior de "&TEXT($O33,"0.####")&IF($H33="",""," "&$H33),"")&IF(AND(ISNUMBER($P33),$V33>$P33),", por encima del límite superior de "&TEXT($P33,"0.####")&IF($H33="",""," "&$H33),"")&".","")&IF($Y33="",""," "&$Y33&IF(RIGHT($Y33,1)=".","","."))&" Acción recomendada: "&$M33&IF(RIGHT($M33,1)=".","",".")&IF($J33="Bloqueante"," El equipo no se libera hasta resolver este hallazgo.",IF($J33="Cobrable"," Se incluye en la cotización de repuestos y consumibles."," Se deja registrado como observación.")))
A34: 4.3.1 | B34: 4. Línea de muestreo y acondicionamiento | C34: 4.3 Acondicionamiento de la muestra | D34: Trampa de humedad (Mist Catcher BAA) | E34: Acumulación de agua condensada y saturación del depurador de humedad | F34: Con el equipo apagado, retirar la cubierta superior, desmontar la trampa Mist Catcher y verificar si hay agua acumulada en el depósito y el estado del relleno. Vaciar y secar si aplica. | G34: OK / No OK | I34: El depósito debe estar libre de condensados y el relleno sin saturación física | J34: Cobrable | K34: Condensado acumulado por línea de muestreo sin trampa, o shelter con oscilación térmica | L34: 4.3.2 ; 3.1.1 ; 10.4.1 | M34: Vaciar y secar la trampa, purgar el circuito con aire seco y corregir el origen del condensado | N34: La trampa de humedad presenta acumulación de condensado, con riesgo de arrastre de agua hacia el sistema de medición. | Q34: Sí | R34: Sí | S34: Sin artículo en el catálogo (Mist Catcher MC-1) — PENDIENTE DE CREAR EN ZOHO | T34: MT_V440EL8D_APMA370_260430 | U34: Pendiente | W34: =IF($G34<>"Numérico","",IF($V34="","Sin dato",IF(AND(OR(NOT(ISNUMBER($O34)),$V34>=$O34),OR(NOT(ISNUMBER($P34)),$V34<=$P34)),"Dentro de rango","Fuera de rango"))) | Z34: =IF(OR($U34="",$U34="Conforme",$U34="No aplica",$U34="Pendiente"),"",$N34&IF($W34="Fuera de rango"," Valor medido: "&TEXT($V34,"0.####")&IF($H34="",""," "&$H34)&IF(AND(ISNUMBER($O34),$V34<$O34),", por debajo del límite inferior de "&TEXT($O34,"0.####")&IF($H34="",""," "&$H34),"")&IF(AND(ISNUMBER($P34),$V34>$P34),", por encima del límite superior de "&TEXT($P34,"0.####")&IF($H34="",""," "&$H34),"")&".","")&IF($Y34="",""," "&$Y34&IF(RIGHT($Y34,1)=".","","."))&" Acción recomendada: "&$M34&IF(RIGHT($M34,1)=".","",".")&IF($J34="Bloqueante"," El equipo no se libera hasta resolver este hallazgo.",IF($J34="Cobrable"," Se incluye en la cotización de repuestos y consumibles."," Se deja registrado como observación.")))
A35: 4.3.2 | B35: 4. Línea de muestreo y acondicionamiento | C35: 4.3 Acondicionamiento de la muestra | D35: Líneas de teflón internas | E35: Estrangulamientos, dobleces agudos o acumulación de suciedad en mangueras neumáticas | F35: Con la cubierta superior retirada, recorrer visualmente cada tramo de manguera interna buscando dobleces agudos, aplastamientos, decoloración o suciedad. Verificar el asiento de cada racor. | G35: OK / No OK | I35: Tuberías de teflón translúcidas, firmes en sus racores y sin dobleces que restrinjan el flujo | J35: Cobrable | K35: Manguera doblada, aplastada o con suciedad interna | L35: 5.1.1 ; 5.1.2 | M35: Rectificar el trazado o reemplazar el tramo afectado | N35: Las líneas neumáticas internas presentan dobleces, aplastamientos o suciedad que restringen el paso del gas de muestra. | Q35: Sí | R35: Sí | T35: MT_U403C0JJ_APMA370_21033001 | U35: Pendiente | W35: =IF($G35<>"Numérico","",IF($V35="","Sin dato",IF(AND(OR(NOT(ISNUMBER($O35)),$V35>=$O35),OR(NOT(ISNUMBER($P35)),$V35<=$P35)),"Dentro de rango","Fuera de rango"))) | Z35: =IF(OR($U35="",$U35="Conforme",$U35="No aplica",$U35="Pendiente"),"",$N35&IF($W35="Fuera de rango"," Valor medido: "&TEXT($V35,"0.####")&IF($H35="",""," "&$H35)&IF(AND(ISNUMBER($O35),$V35<$O35),", por debajo del límite inferior de "&TEXT($O35,"0.####")&IF($H35="",""," "&$H35),"")&IF(AND(ISNUMBER($P35),$V35>$P35),", por encima del límite superior de "&TEXT($P35,"0.####")&IF($H35="",""," "&$H35),"")&".","")&IF($Y35="",""," "&$Y35&IF(RIGHT($Y35,1)=".","","."))&" Acción recomendada: "&$M35&IF(RIGHT($M35,1)=".","",".")&IF($J35="Bloqueante"," El equipo no se libera hasta resolver este hallazgo.",IF($J35="Cobrable"," Se incluye en la cotización de repuestos y consumibles."," Se deja registrado como observación.")))
A36: 5.1.1 | B36: 5. Sistema neumático | C36: 5.1 Caudal y presión de muestra | D36: Caudal volumétrico de muestra (SAMPLE) | E36: Caudal de gas de muestra a través de la celda de medida en ANALOG INPUT | F36: Leer el valor SAMPLE en MENU / MAINTENANCE / ANALOG INPUT. Para verificación independiente, medir con flujómetro de burbuja en el puerto SAMPLE INLET con la línea desconectada. | G36: Numérico | H36: L/min | I36: Caudal nominal de muestreo; fuera de 1,0 a 2,0 L/min se activa la alarma FLOW 1 | J36: Bloqueante | K36: Filtro colmatado, fuga en el circuito, o diafragma de bomba desgastado | L36: 4.2.1 ; 5.1.2 ; 5.2.2 ; 5.3.2 | M36: Medir el caudal real con flujómetro de burbuja en SAMPLE INLET y recorrer la rama en ese orden | N36: El caudal de muestra se encuentra fuera del rango de operación especificado por el fabricante. | O36: 1 | P36: 2 | Q36: Sí | R36: No | T36: P-ST-018-MAN OPER APMA 370 V2 | U36: Pendiente | W36: =IF($G36<>"Numérico","",IF($V36="","Sin dato",IF(AND(OR(NOT(ISNUMBER($O36)),$V36>=$O36),OR(NOT(ISNUMBER($P36)),$V36<=$P36)),"Dentro de rango","Fuera de rango"))) | Z36: =IF(OR($U36="",$U36="Conforme",$U36="No aplica",$U36="Pendiente"),"",$N36&IF($W36="Fuera de rango"," Valor medido: "&TEXT($V36,"0.####")&IF($H36="",""," "&$H36)&IF(AND(ISNUMBER($O36),$V36<$O36),", por debajo del límite inferior de "&TEXT($O36,"0.####")&IF($H36="",""," "&$H36),"")&IF(AND(ISNUMBER($P36),$V36>$P36),", por encima del límite superior de "&TEXT($P36,"0.####")&IF($H36="",""," "&$H36),"")&".","")&IF($Y36="",""," "&$Y36&IF(RIGHT($Y36,1)=".","","."))&" Acción recomendada: "&$M36&IF(RIGHT($M36,1)=".","",".")&IF($J36="Bloqueante"," El equipo no se libera hasta resolver este hallazgo.",IF($J36="Cobrable"," Se incluye en la cotización de repuestos y consumibles."," Se deja registrado como observación.")))
A37: 5.1.2 | B37: 5. Sistema neumático | C37: 5.1 Caudal y presión de muestra | D37: Presión de succión de la bomba (PUMP) | E37: Presión de succión generada por la bomba de muestreo en la celda óptica | F37: Leer el valor PUMP en MENU / MAINTENANCE / ANALOG INPUT con el equipo en operación normal y la línea de muestra conectada. Anotar el valor estabilizado. | G37: Numérico | H37: kPa | I37: Lectura en ANALOG INPUT; un valor mayor o igual a 65 kPa activa la alarma PRE1 | J37: Bloqueante | K37: Vacío alto: obstrucción aguas arriba. Vacío bajo: fuga o diafragma roto | L37: 4.2.1 ; 4.3.2 ; 5.2.2 ; 5.3.2 | M37: Desconectar la línea en SAMPLE INLET: si la presión cae, la obstrucción está aguas arriba; si no, está dentro del equipo | N37: La presión de succión de la bomba está fuera del rango de operación, lo que indica una obstrucción o una fuga en el circuito neumático. | O37: 0 | P37: 65 | Q37: Sí | R37: No | T37: P-ST-018-MAN OPER APMA 370 V2 | U37: Pendiente | W37: =IF($G37<>"Numérico","",IF($V37="","Sin dato",IF(AND(OR(NOT(ISNUMBER($O37)),$V37>=$O37),OR(NOT(ISNUMBER($P37)),$V37<=$P37)),"Dentro de rango","Fuera de rango"))) | Z37: =IF(OR($U37="",$U37="Conforme",$U37="No aplica",$U37="Pendiente"),"",$N37&IF($W37="Fuera de rango"," Valor medido: "&TEXT($V37,"0.####")&IF($H37="",""," "&$H37)&IF(AND(ISNUMBER($O37),$V37<$O37),", por debajo del límite inferior de "&TEXT($O37,"0.####")&IF($H37="",""," "&$H37),"")&IF(AND(ISNUMBER($P37),$V37>$P37),", por encima del límite superior de "&TEXT($P37,"0.####")&IF($H37="",""," "&$H37),"")&".","")&IF($Y37="",""," "&$Y37&IF(RIGHT($Y37,1)=".","","."))&" Acción recomendada: "&$M37&IF(RIGHT($M37,1)=".","",".")&IF($J37="Bloqueante"," El equipo no se libera hasta resolver este hallazgo.",IF($J37="Cobrable"," Se incluye en la cotización de repuestos y consumibles."," Se deja registrado como observación.")))
A38: 5.2.1 | B38: 5. Sistema neumático | C38: 5.2 Bomba de muestreo | D38: Vibración y ruido mecánico de la bomba (P-1-B) | E38: Estabilidad del motor y rodamientos de la bomba de muestreo (verificación auditiva y táctil) | F38: Con el equipo en marcha y la cubierta retirada, escuchar la bomba y apoyar la mano sobre su carcasa para detectar vibración anormal, golpeteo metálico u oscilación excesiva. | G38: OK / No OK | I38: Operación continua y estable, sin golpes metálicos ni oscilación mecánica excesiva | J38: Cobrable | K38: Diafragma roto (siseo de aire) o rodamiento y motor dañados (golpeteo metálico) | L38: 5.2.2 ; 5.2.3 ; 5.1.2 | M38: Discriminar por el tipo de ruido y reemplazar diafragmas o la unidad de bomba completa | N38: La bomba de muestreo presenta ruido o vibración anormal, señal de desgaste mecánico interno. | Q38: Sí | R38: Sí | S38: Pump GD-6EH-100 (100～120V) APMA / APNA / APSA / APHA (3014059459) | T38: P-ST-019-MAN MTTO APMA370 V2 | U38: Pendiente | W38: =IF($G38<>"Numérico","",IF($V38="","Sin dato",IF(AND(OR(NOT(ISNUMBER($O38)),$V38>=$O38),OR(NOT(ISNUMBER($P38)),$V38<=$P38)),"Dentro de rango","Fuera de rango"))) | Z38: =IF(OR($U38="",$U38="Conforme",$U38="No aplica",$U38="Pendiente"),"",$N38&IF($W38="Fuera de rango"," Valor medido: "&TEXT($V38,"0.####")&IF($H38="",""," "&$H38)&IF(AND(ISNUMBER($O38),$V38<$O38),", por debajo del límite inferior de "&TEXT($O38,"0.####")&IF($H38="",""," "&$H38),"")&IF(AND(ISNUMBER($P38),$V38>$P38),", por encima del límite superior de "&TEXT($P38,"0.####")&IF($H38="",""," "&$H38),"")&".","")&IF($Y38="",""," "&$Y38&IF(RIGHT($Y38,1)=".","","."))&" Acción recomendada: "&$M38&IF(RIGHT($M38,1)=".","",".")&IF($J38="Bloqueante"," El equipo no se libera hasta resolver este hallazgo.",IF($J38="Cobrable"," Se incluye en la cotización de repuestos y consumibles."," Se deja registrado como observación.")))
A39: 5.2.2 | B39: 5. Sistema neumático | C39: 5.2 Bomba de muestreo | D39: Desgaste de diafragmas de la bomba (P-1-D) | E39: Resequedad, porosidad o fisuras de los dos diafragmas de EPDM de la bomba | F39: Apagar el equipo, desmontar los dos cabezales de la bomba y extraer los diafragmas. Examinarlos contra la luz buscando porosidades, fisuras radiales o endurecimiento del EPDM. | G39: OK / No OK | I39: Diafragmas de EPDM elásticos y sin fisuras, para evitar caídas de vacío y de caudal | J39: Cobrable | K39: Fatiga del EPDM por horas de servicio, o arrastre de condensado hacia el cabezal | L39: 8.1.2 ; 4.3.1 | M39: Reemplazar el juego de diafragmas, reiniciar el horómetro y corregir el origen del condensado | N39: Los diafragmas de la bomba de muestreo presentan desgaste, fisuras o pérdida de elasticidad. | Q39: Sí | R39: Sí | S39: Diaphragm Assy GS, GD series EPDM - APMA / APOA / APHA (3200044033) · Diaphragm Assy GS, Gdseries EPDM (3200602390) | T39: MT_2V0CY0DC_APMA370_250930 | U39: Pendiente | W39: =IF($G39<>"Numérico","",IF($V39="","Sin dato",IF(AND(OR(NOT(ISNUMBER($O39)),$V39>=$O39),OR(NOT(ISNUMBER($P39)),$V39<=$P39)),"Dentro de rango","Fuera de rango"))) | Z39: =IF(OR($U39="",$U39="Conforme",$U39="No aplica",$U39="Pendiente"),"",$N39&IF($W39="Fuera de rango"," Valor medido: "&TEXT($V39,"0.####")&IF($H39="",""," "&$H39)&IF(AND(ISNUMBER($O39),$V39<$O39),", por debajo del límite inferior de "&TEXT($O39,"0.####")&IF($H39="",""," "&$H39),"")&IF(AND(ISNUMBER($P39),$V39>$P39),", por encima del límite superior de "&TEXT($P39,"0.####")&IF($H39="",""," "&$H39),"")&".","")&IF($Y39="",""," "&$Y39&IF(RIGHT($Y39,1)=".","","."))&" Acción recomendada: "&$M39&IF(RIGHT($M39,1)=".","",".")&IF($J39="Bloqueante"," El equipo no se libera hasta resolver este hallazgo.",IF($J39="Cobrable"," Se incluye en la cotización de repuestos y consumibles."," Se deja registrado como observación.")))
