Workbook

Sheet Instrucciones
A1: INSPECCIÓN FÍSICA DEL EQUIPO — GRIMM EDM180 (C/D)
A2: Prototipo de estructura jerárquica en Excel · Ambientalia — Servicio Técnico · v9
A4: Novedades de la v9
A5: Se añadió la hoja «Flujo No OK 2»: la misma información de encadenamiento condicional (columnas
A6: N-O de Inspección y hoja «Flujo No OK»), reorganizada en tabla plana de un renglón por enlace
A7: origen→destino — misma filosofía que la referencia que compartió el usuario para los Horiba
A8: APxA-370 (columnas Modelo, ID origen, Ítem, Criterio de falla, Causa probable, Orden, ID destino,
A9: Verificación siguiente, Acción si se confirma, Resultado del origen y Rama activa). «Resultado del
A10: origen» y «Rama activa» son fórmulas en vivo contra la hoja Inspección: si el ítem de origen queda
A11: marcado No conforme/Requiere reemplazo en la visita, la fila se enciende sola. Filtre por «Rama
A12: activa = SÍ» para ver solo lo que la visita de hoy disparó. ID origen e ID destino son hipervínculos
A13: a la fila del ítem en Inspección. 84 enlaces sobre los mismos ~40 ítems con secuencia documentada
... A128: no uno publicado por GRIMM; se deja igual, pero sin fuente oficial confirmada.
A129: ID | B129: Ítem | C129: Resultado | D129: Valor medido | E129: Foto | F129: Observación
A130: 3.1.1 | B130: Flujo de la bomba de secado | C130: Requiere reemplazo | D130: 2.45 | E130: Sí | F130: Flujo cercano al límite de reemplazo; desgaste en el empaque del pistón.

Sheet Listas
A1: Resultado | B1: Foto adjunta | C1: Obligatorio | D1: Criterio de falla
A2: Conforme | B2: Sí | C2: Sí | D2: Alerta
A3: No conforme | B3: No | C3: No | D3: Cobrable
A4: Requiere reemplazo | B4: No aplica | D4: Bloqueante
A5: No aplica
A6: Pendiente

Sheet Inspección
A1: FASE 1 — INSPECCIÓN FÍSICA DEL EQUIPO (catálogo + captura)
A3: Cliente: | D3: Serie del espectrómetro:
A4: NIT: | D4: Fecha de inspección:
A5: Equipo / Modelo: | B5: Monitor de partículas GRIMM EDM180 | D5: Técnico responsable:
A6: Número de serie: | D6: N.º de informe (MT):
A8: ID | B8: Nivel macro (N1) | C8: Subnivel (N2) | D8: Ítem (N3) | E8: Qué se verifica | F8: Cómo se verifica (método) | G8: Tipo de dato | H8: Unidad | I8: Criterio de aceptación | J8: Límite inferior | K8: Límite superior | L8: Obligatorio | M8: Criterio de falla | N8: Acción si sale No OK | O8: Ítem(s) relacionado(s) | P8: Comentario de falla (informe al cliente) | Q8: Evidencia fotográfica requerida | R8: Repuesto / parte asociada | S8: Informe de referencia | T8: Resultado | U8: Valor medido | V8: Verificación de rango | W8: Foto adjunta | X8: Observación
A9: 1.1.1 | B9: 1. Verificación funcional inicial | C9: 1.1 Encendido y autodiagnóstico | D9: Ciclo self-test | E9: El equipo enciende y supera el ciclo self test | F9: Encender el equipo desde el panel frontal y observar en pantalla que complete el ciclo de autodiagnóstico (self-test) sin quedar detenido ni mostrar código de error. | G9: Sí/No | I9: Debe superar el self test | L9: Sí | M9: Bloqueante | N9: Revisar el código específico mostrado en pantalla (SER-MAN cap. 2.1). Si es “New Self Test”, limpiar la entrada de aire de muestra (2.1.3) y reintentar; si el código persiste, el equipo requiere servicio técnico calificado. Ver Cadena 1 en hoja Flujo No OK. | O9: 2.1.3 · 5.3.2 · 7.1.1 | P9: El equipo no completa el ciclo de autodiagnóstico (self-test) al encender. | Q9: No | S9: MT_18A12051_260811 | T9: Pendiente | V9: =IF($G9<>"Numérico","",IF($U9="","Sin dato",IF(AND(OR(NOT(ISNUMBER($J9)),$U9>=$J9),OR(NOT(ISNUMBER($K9)),$U9<=$K9)),"Dentro de rango","Fuera de rango")))
A10: 1.1.2 | B10: 1. Verificación funcional inicial | C10: 1.1 Encendido y autodiagnóstico | D10: Inicio de medición | E10: El equipo comienza a medir tras el self test | F10: Verificar en pantalla o en el software Diagnosis GRIMM que, al finalizar el self-test, el equipo pase automáticamente a modo de medición y comience a reportar conteos. | G10: Sí/No | I10: Debe iniciar medición | L10: Sí | M10: Bloqueante | N10: Si el equipo completa el self-test pero no pasa a medición, revisar los mismos códigos de la Cadena 1 (self-test) — causa probablemente común con 1.1.1. | O10: 1.1.1 | P10: El equipo supera el self-test pero no inicia la medición automáticamente. | Q10: No | S10: MT_18A12051_260811 | T10: Pendiente | V10: =IF($G10<>"Numérico","",IF($U10="","Sin dato",IF(AND(OR(NOT(ISNUMBER($J10)),$U10>=$J10),OR(NOT(ISNUMBER($K10)),$U10<=$K10)),"Dentro de rango","Fuera de rango")))
A11: 1.1.3 | B11: 1. Verificación funcional inicial | C11: 1.1 Encendido y autodiagnóstico | D11: Alarmas activas | E11: Alarmas o avisos en pantalla al arranque (p. ej. alerta "Dryer") | F11: Revisar la pantalla del equipo al arranque y anotar cualquier alarma o aviso visible (p. ej. "Dryer"); confirmar en el software de diagnóstico si hay alarmas adicionales no visibles en pantalla. | G11: Texto | I11: Sin alarmas activas | L11: Sí | M11: Alerta | N11: Si la alarma es “Dryer”: revisar el manómetro de vacío tras la tapa del panel frontal (3.2.1) y la presión de vacío (3.2.2). Ver Cadena 2 en hoja Flujo No OK. | O11: 3.2.1 · 3.2.2 · 2.4.1 | P11: Se observa una alarma o aviso activo en pantalla al arranque del equipo (p. ej. «Dryer»). | Q11: Sí | S11: MT_18A21062_260227 | T11: Pendiente | V11: =IF($G11<>"Numérico","",IF($U11="","Sin dato",IF(AND(OR(NOT(ISNUMBER($J11)),$U11>=$J11),OR(NOT(ISNUMBER($K11)),$U11<=$K11)),"Dentro de rango","Fuera de rango")))
A12: 1.2.1 | B12: 1. Verificación funcional inicial | C12: 1.2 Identificación y trazabilidad | D12: Serial del monitor | E12: El serial del monitor coincide con la placa y con la orden de servicio | F12: Comparar el número de serie impreso en la placa/etiqueta del equipo con el registrado en la orden de servicio. | G12: Sí/No | I12: Debe coincidir | L12: Sí | M12: Bloqueante | N12: No liberar el equipo hasta resolver. Reparar/reemplazar el componente asociado (ver Repuesto/parte asociada); si no se resuelve en sitio, escalar a soporte GRIMM/DURAG. | P12: El número de serie del equipo no coincide con el registrado en la orden de servicio. | Q12: Sí | S12: MT_18A19035_260727 | T12: Pendiente | V12: =IF($G12<>"Numérico","",IF($U12="","Sin dato",IF(AND(OR(NOT(ISNUMBER($J12)),$U12>=$J12),OR(NOT(ISNUMBER($K12)),$U12<=$K12)),"Dentro de rango","Fuera de rango")))
A13: 1.2.2 | B13: 1. Verificación funcional inicial | C13: 1.2 Identificación y trazabilidad | D13: Serial del espectrómetro | E13: El espectrómetro instalado corresponde al del equipo (no de otro monitor) | F13: Ingresar al software Diagnosis GRIMM y leer el serial del espectrómetro instalado; contrastarlo con el serial de fábrica asociado a ese monitor. | G13: Sí/No | I13: Debe corresponder | L13: Sí | M13: Bloqueante | N13: No liberar el equipo hasta resolver. Reparar/reemplazar el componente asociado (ver Repuesto/parte asociada); si no se resuelve en sitio, escalar a soporte GRIMM/DURAG. | P13: El espectrómetro instalado no corresponde al registrado para este equipo; podría tratarse de un componente de otro monitor. | Q13: Sí | S13: MT_18A19035_260727 | T13: Pendiente | V13: =IF($G13<>"Numérico","",IF($U13="","Sin dato",IF(AND(OR(NOT(ISNUMBER($J13)),$U13>=$J13),OR(NOT(ISNUMBER($K13)),$U13<=$K13)),"Dentro de rango","Fuera de rango")))
A14: 1.2.3 | B14: 1. Verificación funcional inicial | C14: 1.2 Identificación y trazabilidad | D14: Accesorios recibidos | E14: Inventario de accesorios: tubo de muestra, cabezal TSP, sensor T/HR, cables | F14: Hacer inventario visual de los accesorios entregados junto al equipo (tubo de muestra, cabezal TSP, sensor T/HR, cables) y contrastarlo contra la lista estándar de accesorios. | G14: Texto | I14: Inventario completo | L14: Sí | M14: Cobrable | N14: Reemplazar o reparar el componente indicado en Repuesto/parte asociada; incluir en la cotización al cliente. | P14: El inventario de accesorios entregados con el equipo está incompleto (tubo de muestra, cabezal TSP, sensor T/HR o cables). | Q14: Sí | S14: MT_18A19035_260727 | T14: Pendiente | V14: =IF($G14<>"Numérico","",IF($U14="","Sin dato",IF(AND(OR(NOT(ISNUMBER($J14)),$U14>=$J14),OR(NOT(ISNUMBER($K14)),$U14<=$K14)),"Dentro de rango","Fuera de rango")))
A15: 1.2.4 | B15: 1. Verificación funcional inicial | C15: 1.2 Identificación y trazabilidad | D15: Etiquetas físicas (Type Label / etiqueta de calibración) | E15: Presencia y legibilidad de la etiqueta de tipo y de la etiqueta de calibración vigente | F15: Inspección visual: verificar que la etiqueta de tipo (Type Label) y la etiqueta de calibración estén adheridas, legibles y con fecha vigente. | G15: OK / No OK | I15: Presentes y legibles | L15: No | M15: Alerta | N15: Registrar el hallazgo en Observación y dar seguimiento; no requiere acción inmediata. | P15: La etiqueta de tipo o la etiqueta de calibración no están presentes, no son legibles o están vencidas. | Q15: Sí | S15: Service Training NEW v0.8 | T15: Pendiente | V15: =IF($G15<>"Numérico","",IF($U15="","Sin dato",IF(AND(OR(NOT(ISNUMBER($J15)),$U15>=$J15),OR(NOT(ISNUMBER($K15)),$U15<=$K15)),"Dentro de rango","Fuera de rango")))
A16: 1.3.1 | B16: 1. Verificación funcional inicial | C16: 1.3 Estado de calibración | D16: Vigencia de calibración en Torre GRIMM | E16: Fecha de la última calibración en torre patrón | F16: Revisar la fecha de la última calibración en la torre patrón GRIMM (registro interno AMB-STCALENVIRO-01) y calcular si han transcurrido menos de 12 meses. | G16: Fecha | I16: Vigencia máxima 12 meses | L16: Sí | M16: Bloqueante | N16: No liberar el equipo hasta resolver. Reparar/reemplazar el componente asociado (ver Repuesto/parte asociada); si no se resuelve en sitio, escalar a soporte GRIMM/DURAG. | P16: La última calibración en torre patrón tiene más de 12 meses de vigencia. | Q16: No | R16: AMB-STCALENVIRO-01 | S16: MT_18A12051_260811 | T16: Pendiente | V16: =IF($G16<>"Numérico","",IF($U16="","Sin dato",IF(AND(OR(NOT(ISNUMBER($J16)),$U16>=$J16),OR(NOT(ISNUMBER($K16)),$U16<=$K16)),"Dentro de rango","Fuera de rango")))
A17: 1.3.2 | B17: 1. Verificación funcional inicial | C17: 1.3 Estado de calibración | D17: Certificado disponible | E17: Existe certificado de la última calibración | F17: Solicitar/consultar el archivo del certificado de calibración correspondiente a la última fecha registrada. | G17: Sí/No | I17: Debe existir | L17: No | M17: Alerta | N17: Registrar el hallazgo en Observación y dar seguimiento; no requiere acción inmediata. | P17: No se cuenta con el certificado de la última calibración del equipo. | Q17: No | S17: MT_18A19035_260727 | T17: Pendiente | V17: =IF($G17<>"Numérico","",IF($U17="","Sin dato",IF(AND(OR(NOT(ISNUMBER($J17)),$U17>=$J17),OR(NOT(ISNUMBER($K17)),$U17<=$K17)),"Dentro de rango","Fuera de rango")))
A18: 1.3.3 | B18: 1. Verificación funcional inicial | C18: 1.3 Estado de calibración | D18: Desviación relativa de masa (verificación con aire ambiente) | E18: Diferencia entre el candidato y el espectrómetro de referencia al verificar con aire ambiente tras la calibración en torre | F18: Con el equipo ya calibrado en torre, realizar una medición simultánea con aire ambiente frente al espectrómetro de referencia y calcular la diferencia porcentual o en µg/m³ entre ambos. | G18: Numérico | H18: % o µg/m³ | I18: Criterio de fábrica: ±3% o ±2µg/m³. Criterio para cliente/campo: ±5% o ±2µg/m³ (correo GRIMM 25-nov-2021) | J18: -5 | K18: 5 | L18: Sí | M18: Bloqueante | N18: Si la desviación de masa queda fuera de criterio tras calibrar en torre, el Service Training documenta el ciclo completo: pre-comparación, calibración de preamplificador/láser/flujo/umbrales, prueba de 48 h, verificación final. Ver Cadena 13. | O18: 5.2.1 · 4.3.3 | P18: La desviación de masa frente al equipo de referencia supera el criterio aceptado tras la calibración en torre. | Q18: Sí | S18: Correo EDM180C Calibration desviación (nov-2021) | T18: Pendiente | V18: =IF($G18<>"Numérico","",IF($U18="","Sin dato",IF(AND(OR(NOT(ISNUMBER($J18)),$U18>=$J18),OR(NOT(ISNUMBER($K18)),$U18<=$K18)),"Dentro de rango","Fuera de rango"))) -> Sin dato
A19: 2.1.1 | B19: 2. Línea de muestreo y cabezal | C19: 2.1 Cabezal TSP | D19: Estado físico del cabezal | E19: Golpes, deformación, corrosión del cabezal TSP | F19: Inspección visual del cabezal TSP buscando golpes, deformación o corrosión. | G19: OK / No OK | I19: Sin deformación ni corrosión | L19: Sí | M19: Cobrable | N19: Reemplazar o reparar el componente indicado en Repuesto/parte asociada; incluir en la cotización al cliente. | P19: El cabezal TSP presenta golpes, deformación o corrosión. | Q19: Sí | R19: 1205317 / X180TSP (cabezal TSP completo) / GRM-CTSP-01 (tubo capilar de la sonda) | S19: MT_18A20087_260512 | T19: Pendiente | V19: =IF($G19<>"Numérico","",IF($U19="","Sin dato",IF(AND(OR(NOT(ISNUMBER($J19)),$U19>=$J19),OR(NOT(ISNUMBER($K19)),$U19<=$K19)),"Dentro de rango","Fuera de rango")))
A20: 2.1.2 | B20: 2. Línea de muestreo y cabezal | C20: 2.1 Cabezal TSP | D20: Tornillo de seguridad del cabezal | E20: Presencia y estado del tornillo de seguridad del cabezal TSP | F20: Inspección visual y manual: confirmar presencia y ajuste del tornillo de seguridad del cabezal. | G20: Presente / Ausente | I20: Debe estar presente | L20: Sí | M20: Cobrable | N20: Reemplazar o reparar el componente indicado en Repuesto/parte asociada; incluir en la cotización al cliente. | P20: Falta el tornillo de seguridad del cabezal TSP o no está correctamente ajustado. | Q20: Sí | R20: M02M2X4D912A4 | S20: MT_18A20087_260512 | T20: Pendiente | V20: =IF($G20<>"Numérico","",IF($U20="","Sin dato",IF(AND(OR(NOT(ISNUMBER($J20)),$U20>=$J20),OR(NOT(ISNUMBER($K20)),$U20<=$K20)),"Dentro de rango","Fuera de rango")))
A21: 2.1.3 | B21: 2. Línea de muestreo y cabezal | C21: 2.1 Cabezal TSP | D21: Limpieza interna del cabezal | E21: Acumulación de material particulado en el interior del cabezal | F21: Desmontar el cabezal y revisar visualmente el interior en busca de acumulación de material particulado; limpiar si es necesario. | G21: OK / No OK | I21: Libre de acumulación | L21: Sí | M21: Cobrable | N21: Reemplazar o reparar el componente indicado en Repuesto/parte asociada; incluir en la cotización al cliente. | P21: Se observa acumulación de material particulado en el interior del cabezal. | Q21: No | S21: MT_18A20087_260512 | T21: Pendiente | V21: =IF($G21<>"Numérico","",IF($U21="","Sin dato",IF(AND(OR(NOT(ISNUMBER($J21)),$U21>=$J21),OR(NOT(ISNUMBER($K21)),$U21<=$K21)),"Dentro de rango","Fuera de rango")))
A22: 2.1.4 | B22: 2. Línea de muestreo y cabezal | C22: 2.1 Cabezal TSP | D22: Malla fly-mesh de la sonda | E22: Estado de la malla de protección (fly-mesh) del cabezal de muestreo | F22: Inspección visual de la malla de protección del cabezal, verificando que no esté obstruida ni rota. | G22: OK / No OK | I22: Sin obstrucción ni rotura | L22: No | M22: Cobrable | N22: Reemplazar o reparar el componente indicado en Repuesto/parte asociada; incluir en la cotización al cliente. | P22: La malla de protección (fly-mesh) del cabezal está obstruida o rota. | Q22: No | R22: 1204089 (Screening Foil — a confirmar si corresponde a la malla fly-mesh) | S22: Service Training.pdf | T22: Pendiente | V22: =IF($G22<>"Numérico","",IF($U22="","Sin dato",IF(AND(OR(NOT(ISNUMBER($J22)),$U22>=$J22),OR(NOT(ISNUMBER($K22)),$U22<=$K22)),"Dentro de rango","Fuera de rango")))
A23: 2.1.5 | B23: 2. Línea de muestreo y cabezal | C23: 2.1 Cabezal TSP | D23: Calefactor opcional del cabezal (head heater) | E23: Presencia y funcionamiento del calefactor opcional del cabezal de muestreo, en los equipos que lo incorporen | F23: Verificar si el equipo trae instalada la opción de calefactor del cabezal; de ser así, comprobar su encendido y funcionamiento. | G23: Presente / Ausente | I23: Aplica solo si el equipo trae la opción instalada; de ser así, debe operar sin falla | L23: No | M23: Alerta | N23: Registrar el hallazgo en Observación y dar seguimiento; no requiere acción inmediata. | P23: El calefactor opcional del cabezal no enciende o no funciona correctamente. | Q23: No | S23: Service Training NEW v0.8 | T23: Pendiente | V23: =IF($G23<>"Numérico","",IF($U23="","Sin dato",IF(AND(OR(NOT(ISNUMBER($J23)),$U23>=$J23),OR(NOT(ISNUMBER($K23)),$U23<=$K23)),"Dentro de rango","Fuera de rango")))
A24: 2.2.1 | B24: 2. Línea de muestreo y cabezal | C24: 2.2 Tubo de muestra (1.5 m) | D24: Rectitud del tubo | E24: Deformación o torcedura del tubo de muestra | F24: Inspección visual a lo largo del tubo de muestra buscando deformaciones o torceduras. | G24: OK / No OK | I24: Sin deformación mecánica | L24: Sí | M24: Cobrable | N24: Reemplazar o reparar el componente indicado en Repuesto/parte asociada; incluir en la cotización al cliente. | P24: El tubo de muestra presenta deformación o torcedura. | Q24: Sí | R24: GR-TI-01 / X180120150AR (tubo 1.5 m completo con cabezal y secador Nafion) / 182-15 | S24: MT_18A12051_260811 | T24: Pendiente | V24: =IF($G24<>"Numérico","",IF($U24="","Sin dato",IF(AND(OR(NOT(ISNUMBER($J24)),$U24>=$J24),OR(NOT(ISNUMBER($K24)),$U24<=$K24)),"Dentro de rango","Fuera de rango")))
A25: 2.2.2 | B25: 2. Línea de muestreo y cabezal | C25: 2.2 Tubo de muestra (1.5 m) | D25: Fugas internas | E25: Prueba de estanqueidad del tubo de muestra | F25: Realizar prueba de estanqueidad del tubo de muestra (obturar un extremo y aplicar presión/vacío controlado, verificando que no haya caída). | G25: OK / No OK | I25: Sin fugas | L25: Sí | M25: Cobrable | N25: Reemplazar o reparar el componente indicado en Repuesto/parte asociada; incluir en la cotización al cliente. | P25: El tubo de muestra no pasa la prueba de estanqueidad (presenta fugas). | Q25: No | S25: MT_18A12051_260811 | T25: Pendiente | V25: =IF($G25<>"Numérico","",IF($U25="","Sin dato",IF(AND(OR(NOT(ISNUMBER($J25)),$U25>=$J25),OR(NOT(ISNUMBER($K25)),$U25<=$K25)),"Dentro de rango","Fuera de rango")))
A26: 2.2.3 | B26: 2. Línea de muestreo y cabezal | C26: 2.2 Tubo de muestra (1.5 m) | D26: Estructura interna de bronce | E26: Integridad de la estructura de bronce y su base respecto a las líneas neumáticas | F26: Inspección visual y manual de la estructura de bronce interna y su unión con las líneas neumáticas. | G26: OK / No OK | I26: Base unida a las líneas neumáticas | L26: Sí | M26: Cobrable | N26: Reemplazar o reparar el componente indicado en Repuesto/parte asociada; incluir en la cotización al cliente. | P26: La estructura interna de bronce del tubo de muestra está dañada o desprendida de las líneas neumáticas. | Q26: Sí | R26: GR-TI-01 | S26: MT_18A12051_260811 | T26: Pendiente | V26: =IF($G26<>"Numérico","",IF($U26="","Sin dato",IF(AND(OR(NOT(ISNUMBER($J26)),$U26>=$J26),OR(NOT(ISNUMBER($K26)),$U26<=$K26)),"Dentro de rango","Fuera de rango")))
A27: 2.2.4 | B27: 2. Línea de muestreo y cabezal | C27: 2.2 Tubo de muestra (1.5 m) | D27: Tornillería del tubo | E27: Deformación mecánica de la tornillería del tubo de muestra | F27: Inspección visual y manual de los tornillos del tubo de muestra, verificando ausencia de deformación. | G27: OK / No OK | I27: Sin deformación | L27: Sí | M27: Cobrable | N27: Reemplazar o reparar el componente indicado en Repuesto/parte asociada; incluir en la cotización al cliente. | P27: La tornillería del tubo de muestra presenta deformación mecánica. | Q27: Sí | R27: 4037489 / M00M3X3D913A2 | S27: MT_18A20087_260512 | T27: Pendiente | V27: =IF($G27<>"Numérico","",IF($U27="","Sin dato",IF(AND(OR(NOT(ISNUMBER($J27)),$U27>=$J27),OR(NOT(ISNUMBER($K27)),$U27<=$K27)),"Dentro de rango","Fuera de rango")))
A28: 2.2.5 | B28: 2. Línea de muestreo y cabezal | C28: 2.2 Tubo de muestra (1.5 m) | D28: O-Ring de la boquilla de entrada | E28: Desgaste de la junta tórica interna de la boquilla de ingreso de muestreo | F28: Desmontar la boquilla de entrada e inspeccionar visualmente el O-Ring en busca de desgaste o cortes. | G28: OK / No OK | I28: Sin desgaste que genere fuga | L28: Sí | M28: Cobrable | N28: Punto habitual de fuga documentado para la prueba de estanqueidad (Cadena 9). | O28: 3.3.1 | P28: El O-Ring de la boquilla de entrada del tubo de muestra presenta desgaste que genera fuga. | Q28: Sí | R28: C0004x1 | S28: MT_18A21062_260227 | T28: Pendiente | V28: =IF($G28<>"Numérico","",IF($U28="","Sin dato",IF(AND(OR(NOT(ISNUMBER($J28)),$U28>=$J28),OR(NOT(ISNUMBER($K28)),$U28<=$K28)),"Dentro de rango","Fuera de rango")))
A29: 2.2.6 | B29: 2. Línea de muestreo y cabezal | C29: 2.2 Tubo de muestra (1.5 m) | D29: Soporte del tubo (Sample Pipe Holder) y tornillo de fijación | E29: Presencia y estado del soporte que fija el tubo de muestra y de su tornillo de fijación | F29: Inspección visual y manual del soporte (Sample Pipe Holder) y su tornillo de fijación, verificando que sostenga el tubo con firmeza. | G29: OK / No OK | I29: Presente y firme | L29: Sí | M29: Cobrable | N29: Punto de contacto documentado en el diagnóstico del mecanismo de lift (Cadena 8) si falla el switch de fin de carrera. | O29: 8.1.5 | P29: El soporte del tubo de muestra (Sample Pipe Holder) o su tornillo de fijación no sujetan el tubo con firmeza. | Q29: Sí | R29: 1200005 (19" Inlet Probe Holder — a confirmar si es el Sample Pipe Holder) | S29: Service Training NEW v0.8 | T29: Pendiente | V29: =IF($G29<>"Numérico","",IF($U29="","Sin dato",IF(AND(OR(NOT(ISNUMBER($J29)),$U29>=$J29),OR(NOT(ISNUMBER($K29)),$U29<=$K29)),"Dentro de rango","Fuera de rango")))
A30: 2.3.1 | B30: 2. Línea de muestreo y cabezal | C30: 2.3 Protección contra intemperie | D30: Rain protector / deflector | E30: Presencia e integridad del protector de lluvia del tubo de muestra | F30: Inspección visual del protector de lluvia/deflector, verificando presencia e integridad. | G30: Presente / Ausente | I30: Presente y sin roturas | L30: Sí | M30: Cobrable | N30: Reemplazar o reparar el componente indicado en Repuesto/parte asociada; incluir en la cotización al cliente. | P30: Falta el protector de lluvia del tubo de muestra o está deteriorado. | Q30: Sí | R30: 4019827 (deflector) / 1202546 (rain protector, SKU independiente en Zoho) | S30: MT_18A20087_260512 | T30: Pendiente | V30: =IF($G30<>"Numérico","",IF($U30="","Sin dato",IF(AND(OR(NOT(ISNUMBER($J30)),$U30>=$J30),OR(NOT(ISNUMBER($K30)),$U30<=$K30)),"Dentro de rango","Fuera de rango")))
A31: 2.3.2 | B31: 2. Línea de muestreo y cabezal | C31: 2.3 Protección contra intemperie | D31: Acople de sellado tubo–shelter | E31: Acople de protección para filtrado de agua hacia el shelter | F31: Inspección visual del acople de protección contra filtración de agua hacia el shelter. | G31: OK / No OK | I31: Acople original instalado | L31: Sí | M31: Alerta | N31: Registrar el hallazgo en Observación y dar seguimiento; no requiere acción inmediata. | P31: El acople de sellado entre el tubo y el shelter no es el original o no cumple su función de protección contra agua. | Q31: Sí | S31: MT_18A20087_260512 | T31: Pendiente | V31: =IF($G31<>"Numérico","",IF($U31="","Sin dato",IF(AND(OR(NOT(ISNUMBER($J31)),$U31>=$J31),OR(NOT(ISNUMBER($K31)),$U31<=$K31)),"Dentro de rango","Fuera de rango")))
A32: 2.3.3 | B32: 2. Línea de muestreo y cabezal | C32: 2.3 Protección contra intemperie | D32: Sellados provisionales | E32: Uso de cinta u otros sellos provisionales en la conexión | F32: Inspección visual de la conexión tubo-shelter, verificando que no haya cinta u otros sellos improvisados. | G32: Sí/No | I32: No debe haber sellos provisionales | L32: Sí | M32: Alerta | N32: Registrar el hallazgo en Observación y dar seguimiento; no requiere acción inmediata. | P32: Se detectan sellos provisionales (cinta u otros) en la conexión del tubo con el shelter. | Q32: Sí | S32: MT_18A20087_260512 | T32: Pendiente | V32: =IF($G32<>"Numérico","",IF($U32="","Sin dato",IF(AND(OR(NOT(ISNUMBER($J32)),$U32>=$J32),OR(NOT(ISNUMBER($K32)),$U32<=$K32)),"Dentro de rango","Fuera de rango")))
A33: 2.3.4 | B33: 2. Línea de muestreo y cabezal | C33: 2.3 Protección contra intemperie | D33: Paso de techo (roof lead through) | E33: Estado del pasamuros/paso de techo por donde ingresa el tubo de muestra a la caseta | F33: Inspección visual del pasamuros/paso de techo por donde entra el tubo, verificando sellado y ausencia de daño. | G33: OK / No OK | I33: Sellado y sin daño | L33: Sí | M33: Alerta | N33: Registrar el hallazgo en Observación y dar seguimiento; no requiere acción inmediata. | P33: El pasamuros/paso de techo por donde ingresa el tubo de muestra no está sellado o presenta daño. | Q33: Sí | S33: Service Training NEW v0.8 | T33: Pendiente | V33: =IF($G33<>"Numérico","",IF($U33="","Sin dato",IF(AND(OR(NOT(ISNUMBER($J33)),$U33>=$J33),OR(NOT(ISNUMBER($K33)),$U33<=$K33)),"Dentro de rango","Fuera de rango")))
A34: 2.4.1 | B34: 2. Línea de muestreo y cabezal | C34: 2.4 Secador Nafion y drenaje | D34: Estado del Nafion | E34: Deterioro del secador Nafion integrado | F34: Inspección visual del secador Nafion integrado, revisando signos de deterioro. | G34: OK / No OK | I34: Sin deterioro | L34: Sí | M34: Cobrable | N34: Estado del Nafion ligado a la alarma Dryer y a “vacío no OK” (Cadena 2); revisar junto con el drenaje (2.4.2). | O34: 2.4.2 · 1.1.3 · 3.3.3 | P34: El secador Nafion integrado muestra signos de deterioro. | Q34: Sí | R34: 1205244 (Nafion sampling pipe) / X1801203A (Nafion tube assembly 0.98 m) | S34: MT_18A12051_260811 | T34: Pendiente | V34: =IF($G34<>"Numérico","",IF($U34="","Sin dato",IF(AND(OR(NOT(ISNUMBER($J34)),$U34>=$J34),OR(NOT(ISNUMBER($K34)),$U34<=$K34)),"Dentro de rango","Fuera de rango")))
A35: 2.4.2 | B35: 2. Línea de muestreo y cabezal | C35: 2.4 Secador Nafion y drenaje | D35: Water drain | E35: Drenaje de agua despejado y operativo | F35: Verificar visualmente que el drenaje de agua esté despejado, dejando salir el condensado sin obstrucción. | G35: OK / No OK | I35: Despejado | L35: Sí | M35: Cobrable | N35: Un drenaje obstruido puede contribuir a la alarma Dryer/vacío no OK (Cadena 2). | O35: 2.4.1 · 1.1.3 | P35: El drenaje de agua está obstruido. | Q35: No | R35: X180150 | S35: MT_18A12051_260811 | T35: Pendiente | V35: =IF($G35<>"Numérico","",IF($U35="","Sin dato",IF(AND(OR(NOT(ISNUMBER($J35)),$U35>=$J35),OR(NOT(ISNUMBER($K35)),$U35<=$K35)),"Dentro de rango","Fuera de rango")))
A36: 2.4.3 | B36: 2. Línea de muestreo y cabezal | C36: 2.4 Secador Nafion y drenaje | D36: Mangueras de la línea neumática | E36: Roturas, fisuras o endurecimiento de las mangueras | F36: Inspección visual y manual de las mangueras de la línea neumática, doblándolas suavemente para detectar endurecimiento o fisuras. | G36: OK / No OK | I36: Sin roturas | L36: Sí | M36: Cobrable | N36: Punto habitual de fuga/obstrucción documentado tanto en la prueba de estanqueidad (Cadena 9) como en el filtro cero (Cadena 4). | O36: 3.3.1 · 4.4.1 | P36: Las mangueras de la línea neumática presentan roturas, fisuras o endurecimiento. | Q36: Sí | R36: E003.2X6.4SILBL/GN/RT · E004.6X7.8SILBL/GN/RT (mangueras de silicona) / 1200914, 1200915 (conectores de manguera M3.2/F3.2) | S36: MT_18A12051_260811 | T36: Pendiente | V36: =IF($G36<>"Numérico","",IF($U36="","Sin dato",IF(AND(OR(NOT(ISNUMBER($J36)),$U36>=$J36),OR(NOT(ISNUMBER($K36)),$U36<=$K36)),"Dentro de rango","Fuera de rango")))
A37: 2.4.4 | B37: 2. Línea de muestreo y cabezal | C37: 2.4 Secador Nafion y drenaje | D37: Prueba de luz "First Aid" (obstrucción del tubo) | E37: Pasar una luz LED por el tubo de muestra: la luz debe atravesarlo completo, sin bloqueos ni residuos visibles; limpiar con aire comprimido si hay obstrucción | F37: Pasar una luz LED por un extremo del tubo de muestra y verificar desde el otro extremo que la luz se vea completa, sin bloqueos; si hay obstrucción, limpiar con aire comprimido. | G37: OK / No OK | I37: La luz debe pasar completa por el tubo | L37: No | M37: Alerta | N37: Registrar el hallazgo en Observación y dar seguimiento; no requiere acción inmediata. | P37: El tubo de muestra presenta obstrucción interna (no permite el paso completo de una luz LED). | Q37: Sí | S37: Correo GRIMM EDM180 TEST FIRST AID 18A12046 | T37: Pendiente | V37: =IF($G37<>"Numérico","",IF($U37="","Sin dato",IF(AND(OR(NOT(ISNUMBER($J37)),$U37>=$J37),OR(NOT(ISNUMBER($K37)),$U37<=$K37)),"Dentro de rango","Fuera de rango")))
A38: 2.4.5 | B38: 2. Línea de muestreo y cabezal | C38: 2.4 Secador Nafion y drenaje | D38: Trampa de agua y racor de salida (water trap / condensate outlet) | E38: Integridad física de la trampa de agua y del racor de salida de condensado, como componentes distintos del secador Nafion | F38: Inspección visual de la trampa de agua y del racor de salida de condensado, verificando ausencia de daño o fugas. | G38: OK / No OK | I38: Sin daño ni fugas | L38: No | M38: Cobrable | N38: Reemplazar o reparar el componente indicado en Repuesto/parte asociada; incluir en la cotización al cliente. | P38: La trampa de agua o el racor de salida de condensado presentan daño o fuga. | Q38: No | R38: 1204257 (frasco 25 mL) / 1204257OR (O-Ring 16x2 mm) | S38: Service Training NEW v0.8 | T38: Pendiente | V38: =IF($G38<>"Numérico","",IF($U38="","Sin dato",IF(AND(OR(NOT(ISNUMBER($J38)),$U38>=$J38),OR(NOT(ISNUMBER($K38)),$U38<=$K38)),"Dentro de rango","Fuera de rango")))
A39: 3.1.1 | B39: 3. Sistema neumático y etapa de secado | C39: 3.1 Bombas (vacío/secado y muestra) | D39: Flujo de la bomba de secado (vacuum flow) | E39: Medición del flujo de la bomba de secado en la salida de condensado (condensate outlet) | F39: Conectar un flujómetro en la salida de condensado (condensate outlet) de la bomba de secado y registrar la lectura en L/min con el equipo en operación normal. | G39: Numérico | H39: L/min | I39: Manual: ~1,8 L/min (válvula de aguja, equipos antiguos) o 2,0-2,2 L/min (tobera crítica, desde 2004). Service Training: 2,0 ±0,1 L/min. 2,45 L/min se registró en campo como valor cercano al límite de reemplazo | J39: 1.8 | K39: 2.3 | L39: Sí | M39: Bloqueante | N39: Tras confirmar fugas y P-Valve (Cadena 3), si aparece “Error 200” revisar el manómetro y el flujo de vacío en el pin de salida trasero (~2,1 L/min); considerar el kit de vacío/bomba. | O39: 3.1.2 · 3.2.1 · 3.4.1 | P39: El flujo de la bomba de secado, medido en la salida de condensado, está fuera del rango de referencia. | Q39: No | R39: 1205273 (kit reparación) / 1205271 o X1809001A115V (bomba completa 230V/115V) | S39: SER-MAN DUST MONITOR 180 / Service Training.pdf / MT_18A24064_260609 | T39: Requiere reemplazo | U39: 2.45 | V39: =IF($G39<>"Numérico","",IF($U39="","Sin dato",IF(AND(OR(NOT(ISNUMBER($J39)),$U39>=$J39),OR(NOT(ISNUMBER($K39)),$U39<=$K39)),"Dentro de rango","Fuera de rango"))) -> Fuera de rango | W39: Sí | X39: EJEMPLO — Flujo en el límite superior del rango; desgaste en el empaque del pistón. Borrar antes de usar el formato.
A40: 3.1.2 | B40: 3. Sistema neumático y etapa de secado | C40: 3.1 Bombas (vacío/secado y muestra) | D40: Estado del kit de la bomba (bomba de vacío/secado) | E40: Desgaste de los componentes internos del kit de la bomba de vacío | F40: Desmontar la bomba de vacío/secado e inspeccionar visualmente el desgaste de los componentes internos del kit. | G40: OK / No OK | I40: Sin desgaste significativo | L40: Sí | M40: Cobrable | N40: El kit de vacío es una causa documentada de error de flujo persistente (correo Flow Error) — reemplazarlo si el ajuste de flujo no resuelve el error. Ver Cadena 3. | O40: 3.1.1 · 3.4.1 | P40: Los componentes internos del kit de la bomba de vacío/secado presentan desgaste significativo. | Q40: Sí | R40: 1205273 / 1204472 (juego de bielas 70SH) / U0929002552 (sello Viton) | S40: MT_18A20087_260512 | T40: Pendiente | V40: =IF($G40<>"Numérico","",IF($U40="","Sin dato",IF(AND(OR(NOT(ISNUMBER($J40)),$U40>=$J40),OR(NOT(ISNUMBER($K40)),$U40<=$K40)),"Dentro de rango","Fuera de rango")))
A41: 3.1.3 | B41: 3. Sistema neumático y etapa de secado | C41: 3.1 Bombas (vacío/secado y muestra) | D41: Empaque del pistón (sealing sleeve) de la bomba de vacío/secado | E41: Desgaste del empaque del pistón de la bomba de secado | F41: Con la bomba desmontada, inspeccionar visualmente el empaque del pistón (sealing sleeve) en busca de desgaste. | G41: OK / No OK | I41: Sin desgaste | L41: Sí | M41: Cobrable | N41: Reemplazar o reparar el componente indicado en Repuesto/parte asociada; incluir en la cotización al cliente. | P41: El empaque del pistón (sealing sleeve) de la bomba de vacío/secado presenta desgaste. | Q41: Sí | R41: 1204480 | S41: MT_18A24064_260609 | T41: Pendiente | V41: =IF($G41<>"Numérico","",IF($U41="","Sin dato",IF(AND(OR(NOT(ISNUMBER($J41)),$U41>=$J41),OR(NOT(ISNUMBER($K41)),$U41<=$K41)),"Dentro de rango","Fuera de rango")))
A42: 3.1.4 | B42: 3. Sistema neumático y etapa de secado | C42: 3.1 Bombas (vacío/secado y muestra) | D42: Ruido y vibración de la bomba de vacío/secado | E42: Ruido o vibración anómala de la bomba | F42: Con el equipo en operación, escuchar y palpar la bomba de secado para detectar ruido o vibración anómala. | G42: OK / No OK | I42: Sin ruido anómalo | L42: No | M42: Alerta | N42: Registrar el hallazgo en Observación y dar seguimiento; no requiere acción inmediata. | P42: La bomba de vacío/secado presenta ruido o vibración anómala. | Q42: No | R42: M6015X8M4 / GR-VD158M4-01 (amortiguadores de vibración) | S42: Derivado | T42: Pendiente | V42: =IF($G42<>"Numérico","",IF($U42="","Sin dato",IF(AND(OR(NOT(ISNUMBER($J42)),$U42>=$J42),OR(NOT(ISNUMBER($K42)),$U42<=$K42)),"Dentro de rango","Fuera de rango")))
...

Sheet Resumen
A1: RESUMEN DE CONFORMIDAD POR NIVEL MACRO
A2: Calculado automáticamente sobre la hoja Inspección.
A4: Nivel macro (N1) | B4: Ítems | C4: Conforme | D4: No conforme | E4: Requiere reemplazo | F4: No aplica | G4: Pendiente | H4: % conformidad | I4: Fuera de rango
A5: 1. Verificación funcional inicial | B5: =COUNTIF(Inspección!$B$9:$B$111,$A5) -> 10 | C5: =COUNTIFS(Inspección!$B$9:$B$111,$A5,Inspección!$T$9:$T$111,"Conforme") -> 0 | D5: =COUNTIFS(Inspección!$B$9:$B$111,$A5,Inspección!$T$9:$T$111,"No conforme") -> 0 | E5: =COUNTIFS(Inspección!$B$9:$B$111,$A5,Inspección!$T$9:$T$111,"Requiere reemplazo") -> 0 | F5: =COUNTIFS(Inspección!$B$9:$B$111,$A5,Inspección!$T$9:$T$111,"No aplica") -> 0 | G5: =COUNTIFS(Inspección!$B$9:$B$111,$A5,Inspección!$T$9:$T$111,"Pendiente") -> 10 | H5: =IFERROR($C5/($B5-$F5-$G5),"") | I5: =COUNTIFS(Inspección!$B$9:$B$111,$A5,Inspección!$V$9:$V$111,"Fuera de rango") -> 0
A6: 2. Línea de muestreo y cabezal | B6: =COUNTIF(Inspección!$B$9:$B$111,$A6) -> 20 | C6: =COUNTIFS(Inspección!$B$9:$B$111,$A6,Inspección!$T$9:$T$111,"Conforme") -> 0 | D6: =COUNTIFS(Inspección!$B$9:$B$111,$A6,Inspección!$T$9:$T$111,"No conforme") -> 0 | E6: =COUNTIFS(Inspección!$B$9:$B$111,$A6,Inspección!$T$9:$T$111,"Requiere reemplazo") -> 0 | F6: =COUNTIFS(Inspección!$B$9:$B$111,$A6,Inspección!$T$9:$T$111,"No aplica") -> 0 | G6: =COUNTIFS(Inspección!$B$9:$B$111,$A6,Inspección!$T$9:$T$111,"Pendiente") -> 20 | H6: =IFERROR($C6/($B6-$F6-$G6),"") | I6: =COUNTIFS(Inspección!$B$9:$B$111,$A6,Inspección!$V$9:$V$111,"Fuera de rango") -> 0
A7: 3. Sistema neumático y etapa de secado | B7: =COUNTIF(Inspección!$B$9:$B$111,$A7) -> 18 | C7: =COUNTIFS(Inspección!$B$9:$B$111,$A7,Inspección!$T$9:$T$111,"Conforme") -> 0 | D7: =COUNTIFS(Inspección!$B$9:$B$111,$A7,Inspección!$T$9:$T$111,"No conforme") -> 0 | E7: =COUNTIFS(Inspección!$B$9:$B$111,$A7,Inspección!$T$9:$T$111,"Requiere reemplazo") -> 1 | F7: =COUNTIFS(Inspección!$B$9:$B$111,$A7,Inspección!$T$9:$T$111,"No aplica") -> 0 | G7: =COUNTIFS(Inspección!$B$9:$B$111,$A7,Inspección!$T$9:$T$111,"Pendiente") -> 17 | H7: =IFERROR($C7/($B7-$F7-$G7),"") -> 0 | I7: =COUNTIFS(Inspección!$B$9:$B$111,$A7,Inspección!$V$9:$V$111,"Fuera de rango") -> 1
A8: 4. Espectrómetro: cámara de medida y óptica | B8: =COUNTIF(Inspección!$B$9:$B$111,$A8) -> 14 | C8: =COUNTIFS(Inspección!$B$9:$B$111,$A8,Inspección!$T$9:$T$111,"Conforme") -> 0 | D8: =COUNTIFS(Inspección!$B$9:$B$111,$A8,Inspección!$T$9:$T$111,"No conforme") -> 0 | E8: =COUNTIFS(Inspección!$B$9:$B$111,$A8,Inspección!$T$9:$T$111,"Requiere reemplazo") -> 0 | F8: =COUNTIFS(Inspección!$B$9:$B$111,$A8,Inspección!$T$9:$T$111,"No aplica") -> 0 | G8: =COUNTIFS(Inspección!$B$9:$B$111,$A8,Inspección!$T$9:$T$111,"Pendiente") -> 14 | H8: =IFERROR($C8/($B8-$F8-$G8),"") | I8: =COUNTIFS(Inspección!$B$9:$B$111,$A8,Inspección!$V$9:$V$111,"Fuera de rango") -> 0
A9: 5. Electrónica y control | B9: =COUNTIF(Inspección!$B$9:$B$111,$A9) -> 15 | C9: =COUNTIFS(Inspección!$B$9:$B$111,$A9,Inspección!$T$9:$T$111,"Conforme") -> 0 | D9: =COUNTIFS(Inspección!$B$9:$B$111,$A9,Inspección!$T$9:$T$111,"No conforme") -> 0 | E9: =COUNTIFS(Inspección!$B$9:$B$111,$A9,Inspección!$T$9:$T$111,"Requiere reemplazo") -> 0 | F9: =COUNTIFS(Inspección!$B$9:$B$111,$A9,Inspección!$T$9:$T$111,"No aplica") -> 0 | G9: =COUNTIFS(Inspección!$B$9:$B$111,$A9,Inspección!$T$9:$T$111,"Pendiente") -> 15 | H9: =IFERROR($C9/($B9-$F9-$G9),"") | I9: =COUNTIFS(Inspección!$B$9:$B$111,$A9,Inspección!$V$9:$V$111,"Fuera de rango") -> 0
A10: 6. Filtros y consumibles | B10: =COUNTIF(Inspección!$B$9:$B$111,$A10) -> 9 | C10: =COUNTIFS(Inspección!$B$9:$B$111,$A10,Inspección!$T$9:$T$111,"Conforme") -> 0 | D10: =COUNTIFS(Inspección!$B$9:$B$111,$A10,Inspección!$T$9:$T$111,"No conforme") -> 0 | E10: =COUNTIFS(Inspección!$B$9:$B$111,$A10,Inspección!$T$9:$T$111,"Requiere reemplazo") -> 0 | F10: =COUNTIFS(Inspección!$B$9:$B$111,$A10,Inspección!$T$9:$T$111,"No aplica") -> 0 | G10: =COUNTIFS(Inspección!$B$9:$B$111,$A10,Inspección!$T$9:$T$111,"Pendiente") -> 9 | H10: =IFERROR($C10/($B10-$F10-$G10),"") | I10: =COUNTIFS(Inspección!$B$9:$B$111,$A10,Inspección!$V$9:$V$111,"Fuera de rango") -> 0
A11: 7. Sensores auxiliares | B11: =COUNTIF(Inspección!$B$9:$B$111,$A11) -> 6 | C11: =COUNTIFS(Inspección!$B$9:$B$111,$A11,Inspección!$T$9:$T$111,"Conforme") -> 0 | D11: =COUNTIFS(Inspección!$B$9:$B$111,$A11,Inspección!$T$9:$T$111,"No conforme") -> 0 | E11: =COUNTIFS(Inspección!$B$9:$B$111,$A11,Inspección!$T$9:$T$111,"Requiere reemplazo") -> 0 | F11: =COUNTIFS(Inspección!$B$9:$B$111,$A11,Inspección!$T$9:$T$111,"No aplica") -> 0 | G11: =COUNTIFS(Inspección!$B$9:$B$111,$A11,Inspección!$T$9:$T$111,"Pendiente") -> 6 | H11: =IFERROR($C11/($B11-$F11-$G11),"") | I11: =COUNTIFS(Inspección!$B$9:$B$111,$A11,Inspección!$V$9:$V$111,"Fuera de rango") -> 0
A12: 8. Gabinete, montaje e instalación | B12: =COUNTIF(Inspección!$B$9:$B$111,$A12) -> 11 | C12: =COUNTIFS(Inspección!$B$9:$B$111,$A12,Inspección!$T$9:$T$111,"Conforme") -> 0 | D12: =COUNTIFS(Inspección!$B$9:$B$111,$A12,Inspección!$T$9:$T$111,"No conforme") -> 0 | E12: =COUNTIFS(Inspección!$B$9:$B$111,$A12,Inspección!$T$9:$T$111,"Requiere reemplazo") -> 0 | F12: =COUNTIFS(Inspección!$B$9:$B$111,$A12,Inspección!$T$9:$T$111,"No aplica") -> 0 | G12: =COUNTIFS(Inspección!$B$9:$B$111,$A12,Inspección!$T$9:$T$111,"Pendiente") -> 11 | H12: =IFERROR($C12/($B12-$F12-$G12),"") | I12: =COUNTIFS(Inspección!$B$9:$B$111,$A12,Inspección!$V$9:$V$111,"Fuera de rango") -> 0
A13: TOTAL | B13: =SUM(B5:B12) -> 103 | C13: =SUM(C5:C12) -> 0 | D13: =SUM(D5:D12) -> 0 | E13: =SUM(E5:E12) -> 1 | F13: =SUM(F5:F12) -> 0 | G13: =SUM(G5:G12) -> 102 | H13: =IFERROR($C13/($B13-$F13-$G13),"") -> 0 | I13: =SUM(I5:I12) -> 1
A15: % conformidad = Conforme / (Ítems − No aplica − Pendiente).
A16: Nota: con la hoja recién abierta todos los ítems están en «Pendiente», por lo que el % queda vacío hasta diligenciar.
A19: RESUMEN POR CRITERIO DE FALLA
A20: Alerta = se registra, no detiene el proceso · Cobrable = genera línea de cotización · Bloqueante = el equipo no se libera sin resolverlo.
A22: Criterio de falla | B22: Ítems en catálogo | C22: Detectados en esta visita
A23: Alerta | B23: =COUNTIF(Inspección!$M$9:$M$111,$A23) -> 19 | C23: =COUNTIFS(Inspección!$M$9:$M$111,$A23,Inspección!$T$9:$T$111,"No conforme")+COUNTIFS(Inspección!$M$9:$M$111,$A23,Inspección!$T$9:$T$111,"Requiere reemplazo") -> 0
A24: Cobrable | B24: =COUNTIF(Inspección!$M$9:$M$111,$A24) -> 57 | C24: =COUNTIFS(Inspección!$M$9:$M$111,$A24,Inspección!$T$9:$T$111,"No conforme")+COUNTIFS(Inspección!$M$9:$M$111,$A24,Inspección!$T$9:$T$111,"Requiere reemplazo") -> 0
A25: Bloqueante | B25: =COUNTIF(Inspección!$M$9:$M$111,$A25) -> 27 | C25: =COUNTIFS(Inspección!$M$9:$M$111,$A25,Inspección!$T$9:$T$111,"No conforme")+COUNTIFS(Inspección!$M$9:$M$111,$A25,Inspección!$T$9:$T$111,"Requiere reemplazo") -> 1
A26: TOTAL | B26: =SUM(B23:B25) -> 103 | C26: =SUM(C23:C25) -> 1
A28: «Detectados en esta visita» cuenta los ítems con Resultado = No conforme o Requiere reemplazo (columna T de Inspección) según su Criterio de falla.
A29: El Criterio de falla es un criterio propio de Ambientalia (ítem por ítem, según impacto en medición/seguridad/trazabilidad), no un dato publicado por GRIMM — valídelo con el equipo técnico.

Sheet Flujo No OK
A1: FLUJO DE DIAGNÓSTICO CUANDO UN ÍTEM SALE NO OK
A2: Cadenas de diagnóstico documentadas en el notebook «ST Grimm EDM180» (manual SER-MAN DUST MONITOR 180 cap. 2, Service Training / Service Training NEW, correos de soporte GRIMM). Cada cadena cita su fuente; úsela junto con las columnas N «Acción si sale No OK» y O «Ítem(s) relacionado(s)» de la hoja Inspección.
A3: No es un árbol de decisión formal de GRIMM (ninguna fuente lo tiene así estructurado) — es una reconstrucción de Ambientalia a partir de mensajes de error tabulados y protocolos de servicio encontrados en las fuentes, para que la tabla se pueda navegar como un flujo. Cubre ~40 de los 103 ítems: los que tienen una secuencia de diagnóstico documentada. El resto del catálogo usa una acción por defecto en la hoja Inspección, según su Criterio de falla.
A5: Cadena 1 — El equipo no completa el self-test / no inicia medición
A6: Fuente: SER-MAN DUST MONITOR 180 cap. 2.1 · Service Training NEW
A7: Paso / disparador | B7: Verificación o acción | C7: Ítem(s) del catálogo
A8: Código en pantalla “New Self Test”. | B8: Limpiar la entrada de aire de muestra y reintentar el self-test. | C8: 2.1.3
A9: El código persiste tras la limpieza. | B9: El equipo requiere mantenimiento por personal de servicio calificado (Bloqueante). | C9: 1.1.1
A10: Código “Fatal Error Please Check!” (self-test fallido varias veces). | B10: Contactar al fabricante/representante (GRIMM/DURAG); no insistir con más ciclos en sitio. | C10: 1.1.1
A11: Código “CARD ERROR! PLEASE CHECK”. | B11: Tarjeta insertada/retirada durante operación, o protección de escritura activa — ver Cadena 10. | C11: 5.3.2
A12: Código “NO SENSOR! PLEASE CHECK”. | B12: Sensor de T/HR no conectado o defectuoso; la medición se detiene. | C12: 7.1.1
A14: Cadena 2 — Alarma “Dryer” / vacío de la etapa de secado no OK
A15: Fuente: SER-MAN DUST MONITOR 180 cap. 2.1
A16: Paso / disparador | B16: Verificación o acción | C16: Ítem(s) del catálogo
A17: “Self Test not OK!” con el LED del dryer en rojo (solo durante self-test). | B17: Vacío de la unidad de secado no OK — revisar el manómetro tras la tapa del panel frontal. | C17: 3.2.1
A18: Código “VACUUM NOT OK! PLEASE CHECK”. | B18: La medición se detiene; revisar la presión de vacío y el estado del secador Nafion/drenaje. | C18: 3.2.2 · 2.4.1 · 2.4.2
A19: Código “VACUUM SWITCH! PLEASE CHECK” (presostato cerrado sin vacío suficiente). | B19: La medición se detiene; el manual indica contactar al fabricante/representante — no resoluble en sitio (Bloqueante). | C19: 3.3.3
A21: Cadena 3 — Error de flujo (“AIR FLOW NOT OK”, corriente de bomba alta)
A22: Fuente: Correo “GRIMM EDM 180 FLOW ERROR” S/N 18A12047
A23: Paso / disparador | B23: Verificación o acción | C23: Ítem(s) del catálogo
A24: Código “AIR FLOW NOT OK CHECK AIR INLET” o alarma “AIR PUMP CURRENT TOO HIGH” en self-test. | B24: El controlador de flujo no logra regular a 1,2 L/min. | C24: 3.4.1
A25: Paso 1. | B25: Verificar fugas en el circuito y medir el voltaje de la válvula proporcional P-Valve (referencia de campo: 11,47 V). | C25: 3.3.1 · 3.4.2
A26: Paso 2. | B26: Aislar el espectrómetro: intercambiarlo a otra carcasa o usar tubería externa, para saber si la falla es interna o externa.
A27: Paso 3 (si la falla queda dentro del espectrómetro). | B27: Retirar la tarjeta digital y el sensor de presión diferencial; inspeccionar la tarjeta análoga en busca de residuos conductivos y limpiarla con limpiador de tarjetas. | C27: 5.1.1 · 5.1.2
A28: Paso 4. | B28: En modo servicio (Terminal/HyperTerminal): enviar “ctrl-f”, ajustar al 100 % el flujo manual, girar el potenciómetro de flujo antihorario hasta clic, reajustar a 1,2 L/min en sentido horario.
A29: Si aparece “Error 200” (problema de vacío). | B29: Revisar el manómetro y el flujo de vacío en el pin de salida trasero (~2,1 L/min); considerar el kit de vacío/bomba. | C29: 3.2.1 · 3.1.1 · 3.1.2
A30: Si la presión atmosférica muestra un valor anómalo (p. ej. 4 hPa) tras lo anterior. | B30: Los factores de calibración (factor/offset) del sensor de presión absoluta pueden haberse perdido, sobre todo tras reemplazar la tarjeta digital; reconfigurar por Terminal. | C30: 7.1.4
A31: Si nada de lo anterior resuelve el error y se confirma daño del láser. | B31: Reemplazo de la unidad láser completa (ref. de campo: pieza 1205338 “Lasereinheit 187 komplett”). | C31: 4.3.1 · 4.3.2 · 4.3.5
A33: Cadena 4 — Prueba de filtro cero: los conteos no dan cero
A34: Fuente: Service Training · Service Training NEW
A35: Paso / disparador | B35: Verificación o acción | C35: Ítem(s) del catálogo
A36: Todos los conteos deben ser cero con el filtro cero instalado; si no lo son… | B36: Revisar también CO_h y CO_d. | C36: 4.4.3
A37: Causas documentadas. | B37: Sistema neumático no estanco, conexiones de tubo defectuosas, disturbios electrónicos, membrana defectuosa del controlador de aire de purga (RAC). | C37: 3.3.1 · 2.4.3 · 5.1.2 · 5.1.3 · 3.4.3
A38: Si CO_h/CO_d quedan anormalmente altos sin causa hallada. | B38: Posible corrosión o daño del fotodiodo/preamplificador — reparación solo en fábrica (Bloqueante). | C38: 4.4.3
A40: Cadena 5 — Reloj interno (RTC) inestable
A41: Fuente: Correo “Date and hour problem” S/N 18A18103
A42: Paso / disparador | B42: Verificación o acción | C42: Ítem(s) del catálogo
A43: Verificación. | B43: En HyperTerminal: leer la hora, esperar unos minutos, volver a leer — si no coincide, el reloj interno dejó de funcionar. | C43: 5.5.1
A44: 1er componente a reemplazar. | B44: Chip temporizador PCF8583 (en Zoho, SKU activo PCF8583P; el correo cita PCF8583F). | C44: 5.5.1
A45: Si la falla reaparece. | B45: El capacitor ajustable es, según GRIMM, la causa más común — reemplazarlo. | C45: 5.5.1
...

Sheet Flujo No OK 2
A1: ENCADENAMIENTO CONDICIONAL — TABLA DE ENLACES ORIGEN → DESTINO
A2: Un renglón por enlace del árbol de diagnóstico (misma filosofía que la referencia del cliente para los Horiba APxA-370). La columna «Rama activa» se enciende sola cuando el ítem de origen queda marcado como hallazgo (No conforme / Requiere reemplazo) en la hoja Inspección de esta misma visita.
A3: Filtre por «Rama activa = SÍ — verificar destino» para ver únicamente las verificaciones que la visita de hoy realmente disparó. ID origen e ID destino son hipervínculos a la fila del ítem en la hoja Inspección. Es la versión en tabla plana, consultable y filtrable, de las 13 cadenas narradas en la hoja «Flujo No OK»; cubre los mismos ~40 ítems con secuencia documentada en el notebook — no añade cobertura nueva, la reorganiza para poder filtrarla por resultado de visita.
A5: Modelo | B5: ID origen | C5: Ítem que salió No OK | D5: Criterio de falla | E5: Causa probable | F5: Orden | G5: ID destino | H5: Verificación siguiente | I5: Acción si se confirma | J5: Resultado del origen | K5: Rama activa
A6: GRIMM EDM180 | B6: 1.1.1 | C6: Ciclo self-test | D6: Bloqueante | E6: Código de self-test no superado: entrada de aire de muestra obstruida, sensor no conectado, o falla que requiere servicio calificado. | F6: 1 | G6: 2.1.3 | H6: Limpieza interna del cabezal | I6: Revisar el código específico mostrado en pantalla (SER-MAN cap. 2.1). Si es “New Self Test”, limpiar la entrada de aire de muestra (2.1.3) y reintentar; si el código persiste, el equipo requiere servicio técnico calificado. Ver Cadena 1 en hoja Flujo No OK. | J6: =IFERROR(INDEX(Inspección!$T$9:$T$111,MATCH($B6,Inspección!$A$9:$A$111,0)),"") -> Pendiente | K6: =IF(OR($J6="No conforme",$J6="Requiere reemplazo"),"SÍ — verificar destino","")
A7: GRIMM EDM180 | B7: 1.1.1 | C7: Ciclo self-test | D7: Bloqueante | E7: Código de self-test no superado: entrada de aire de muestra obstruida, sensor no conectado, o falla que requiere servicio calificado. | F7: 2 | G7: 5.3.2 | H7: Tarjeta PCMCIA / almacenamiento | I7: Revisar el código específico mostrado en pantalla (SER-MAN cap. 2.1). Si es “New Self Test”, limpiar la entrada de aire de muestra (2.1.3) y reintentar; si el código persiste, el equipo requiere servicio técnico calificado. Ver Cadena 1 en hoja Flujo No OK. | J7: =IFERROR(INDEX(Inspección!$T$9:$T$111,MATCH($B7,Inspección!$A$9:$A$111,0)),"") -> Pendiente | K7: =IF(OR($J7="No conforme",$J7="Requiere reemplazo"),"SÍ — verificar destino","")
A8: GRIMM EDM180 | B8: 1.1.1 | C8: Ciclo self-test | D8: Bloqueante | E8: Código de self-test no superado: entrada de aire de muestra obstruida, sensor no conectado, o falla que requiere servicio calificado. | F8: 3 | G8: 7.1.1 | H8: Sensor de T y HR ambiente | I8: Revisar el código específico mostrado en pantalla (SER-MAN cap. 2.1). Si es “New Self Test”, limpiar la entrada de aire de muestra (2.1.3) y reintentar; si el código persiste, el equipo requiere servicio técnico calificado. Ver Cadena 1 en hoja Flujo No OK. | J8: =IFERROR(INDEX(Inspección!$T$9:$T$111,MATCH($B8,Inspección!$A$9:$A$111,0)),"") -> Pendiente | K8: =IF(OR($J8="No conforme",$J8="Requiere reemplazo"),"SÍ — verificar destino","")
A9: GRIMM EDM180 | B9: 1.1.2 | C9: Inicio de medición | D9: Bloqueante | E9: Comparte causa probable con el self-test (1.1.1): mismo código de arranque no resuelto. | F9: 1 | G9: 1.1.1 | H9: Ciclo self-test | I9: Si el equipo completa el self-test pero no pasa a medición, revisar los mismos códigos de la Cadena 1 (self-test) — causa probablemente común con 1.1.1. | J9: =IFERROR(INDEX(Inspección!$T$9:$T$111,MATCH($B9,Inspección!$A$9:$A$111,0)),"") -> Pendiente | K9: =IF(OR($J9="No conforme",$J9="Requiere reemplazo"),"SÍ — verificar destino","")
A10: GRIMM EDM180 | B10: 1.1.3 | C10: Alarmas activas | D10: Alerta | E10: Alarma «Dryer» activa: vacío o presión de la etapa de secado fuera de rango. | F10: 1 | G10: 3.2.1 | H10: Manómetro de vacío | I10: Si la alarma es “Dryer”: revisar el manómetro de vacío tras la tapa del panel frontal (3.2.1) y la presión de vacío (3.2.2). Ver Cadena 2 en hoja Flujo No OK. | J10: =IFERROR(INDEX(Inspección!$T$9:$T$111,MATCH($B10,Inspección!$A$9:$A$111,0)),"") -> Pendiente | K10: =IF(OR($J10="No conforme",$J10="Requiere reemplazo"),"SÍ — verificar destino","")
A11: GRIMM EDM180 | B11: 1.1.3 | C11: Alarmas activas | D11: Alerta | E11: Alarma «Dryer» activa: vacío o presión de la etapa de secado fuera de rango. | F11: 2 | G11: 3.2.2 | H11: Presión negativa de succión (vacío) | I11: Si la alarma es “Dryer”: revisar el manómetro de vacío tras la tapa del panel frontal (3.2.1) y la presión de vacío (3.2.2). Ver Cadena 2 en hoja Flujo No OK. | J11: =IFERROR(INDEX(Inspección!$T$9:$T$111,MATCH($B11,Inspección!$A$9:$A$111,0)),"") -> Pendiente | K11: =IF(OR($J11="No conforme",$J11="Requiere reemplazo"),"SÍ — verificar destino","")
A12: GRIMM EDM180 | B12: 1.1.3 | C12: Alarmas activas | D12: Alerta | E12: Alarma «Dryer» activa: vacío o presión de la etapa de secado fuera de rango. | F12: 3 | G12: 2.4.1 | H12: Estado del Nafion | I12: Si la alarma es “Dryer”: revisar el manómetro de vacío tras la tapa del panel frontal (3.2.1) y la presión de vacío (3.2.2). Ver Cadena 2 en hoja Flujo No OK. | J12: =IFERROR(INDEX(Inspección!$T$9:$T$111,MATCH($B12,Inspección!$A$9:$A$111,0)),"") -> Pendiente | K12: =IF(OR($J12="No conforme",$J12="Requiere reemplazo"),"SÍ — verificar destino","")
A13: GRIMM EDM180 | B13: 1.3.3 | C13: Desviación relativa de masa (verificación con aire ambiente) | D13: Bloqueante | E13: Desviación de masa fuera de ±5%/±2 µg/m³ tras calibrar en torre: mismo ciclo de recalibración completo. | F13: 1 | G13: 5.2.1 | H13: Ganancia canal F | I13: Si la desviación de masa queda fuera de criterio tras calibrar en torre, el Service Training documenta el ciclo completo: pre-comparación, calibración de preamplificador/láser/flujo/umbrales, prueba de 48 h, verificación final. Ver Cadena 13. | J13: =IFERROR(INDEX(Inspección!$T$9:$T$111,MATCH($B13,Inspección!$A$9:$A$111,0)),"") -> Pendiente | K13: =IF(OR($J13="No conforme",$J13="Requiere reemplazo"),"SÍ — verificar destino","")
A14: GRIMM EDM180 | B14: 1.3.3 | C14: Desviación relativa de masa (verificación con aire ambiente) | D14: Bloqueante | E14: Desviación de masa fuera de ±5%/±2 µg/m³ tras calibrar en torre: mismo ciclo de recalibración completo. | F14: 2 | G14: 4.3.3 | H14: Respuesta a verificación con dolomita | I14: Si la desviación de masa queda fuera de criterio tras calibrar en torre, el Service Training documenta el ciclo completo: pre-comparación, calibración de preamplificador/láser/flujo/umbrales, prueba de 48 h, verificación final. Ver Cadena 13. | J14: =IFERROR(INDEX(Inspección!$T$9:$T$111,MATCH($B14,Inspección!$A$9:$A$111,0)),"") -> Pendiente | K14: =IF(OR($J14="No conforme",$J14="Requiere reemplazo"),"SÍ — verificar destino","")
A15: GRIMM EDM180 | B15: 2.2.5 | C15: O-Ring de la boquilla de entrada | D15: Cobrable | E15: Desgaste del O-Ring de la boquilla de entrada: punto habitual de fuga en la prueba de estanqueidad. | F15: 1 | G15: 3.3.1 | H15: Prueba de fugas del circuito (test de presión) | I15: Punto habitual de fuga documentado para la prueba de estanqueidad (Cadena 9). | J15: =IFERROR(INDEX(Inspección!$T$9:$T$111,MATCH($B15,Inspección!$A$9:$A$111,0)),"") -> Pendiente | K15: =IF(OR($J15="No conforme",$J15="Requiere reemplazo"),"SÍ — verificar destino","")
A16: GRIMM EDM180 | B16: 2.2.6 | C16: Soporte del tubo (Sample Pipe Holder) y tornillo de fijación | D16: Cobrable | E16: Contacto lift-soporte del tubo o switch de fin de carrera con falla. | F16: 1 | G16: 8.1.5 | H16: Mecanismo de elevación (lift) del bastidor | I16: Punto de contacto documentado en el diagnóstico del mecanismo de lift (Cadena 8) si falla el switch de fin de carrera. | J16: =IFERROR(INDEX(Inspección!$T$9:$T$111,MATCH($B16,Inspección!$A$9:$A$111,0)),"") -> Pendiente | K16: =IF(OR($J16="No conforme",$J16="Requiere reemplazo"),"SÍ — verificar destino","")
A17: GRIMM EDM180 | B17: 2.4.1 | C17: Estado del Nafion | D17: Cobrable | E17: Secador Nafion deteriorado, asociado a la alarma Dryer y a vacío fuera de rango. | F17: 1 | G17: 2.4.2 | H17: Water drain | I17: Estado del Nafion ligado a la alarma Dryer y a “vacío no OK” (Cadena 2); revisar junto con el drenaje (2.4.2). | J17: =IFERROR(INDEX(Inspección!$T$9:$T$111,MATCH($B17,Inspección!$A$9:$A$111,0)),"") -> Pendiente | K17: =IF(OR($J17="No conforme",$J17="Requiere reemplazo"),"SÍ — verificar destino","")
... A89: GRIMM EDM180 | B89: 8.1.5 | C89: Mecanismo de elevación (lift) del bastidor | D89: Cobrable | E89: Alarma «Self Test LIFT NOT OK» al levantar el bastidor. | F89: 2 | G89: 5.3.3 | H89: Cableado y conectores internos | I89: Protocolo documentado: si aparece error de lift, revisar en orden — contacto lift-soporte del tubo (2.2.6), palanca del lift, switch de fin de carrera, cableado hasta la fuente de alimentación (5.3.3). Ver Cadena 8. | J89: =IFERROR(INDEX(Inspección!$T$9:$T$111,MATCH($B89,Inspección!$A$9:$A$111,0)),"") -> Pendiente | K89: =IF(OR($J89="No conforme",$J89="Requiere reemplazo"),"SÍ — verificar destino","")
A91: 84 enlaces entre 41 ítems de origen y sus ítems relacionados — mismo contenido que las columnas N/O de Inspección y que la hoja Flujo No OK, reorganizado en tabla plana filtrable.
A92: No es un árbol de decisión formal de GRIMM: es una reconstrucción de Ambientalia a partir de mensajes de error y protocolos de servicio documentados en el notebook «ST Grimm EDM180» — misma fuente y mismo alcance (~40 de 103 ítems) que la hoja Flujo No OK.
