Workbook

Sheet Instrucciones
A1: INSPECCIÓN FÍSICA DE EQUIPO — SERIE HORIBA AP-370
A2: APMA-370 (CO) · APSA-370 (SO2) · APOA-370 (O3) · APNA-370 (NOx)
A3: Ambientalia — Servicio Técnico · v1.0 · Estructura derivada del prototipo GRIMM EDM180 v1.2
A5: Qué contiene este libro
A6: Una hoja de inspección por modelo de analizador. Cada hoja es a la vez el catálogo maestro de la
A7: jerarquía (niveles macro N1, subniveles N2 e ítems N3) y la hoja de captura de una visita, con la
A8: misma estructura de columnas del prototipo GRIMM EDM180 v1.2: las columnas A a N definen el ítem
A9: y las columnas O a S (en amarillo) son lo que diligencia el técnico en cada visita.
A11: Hojas del libro
A12: APMA-370 (CO) Analizador de monóxido de carbono HORIBA APMA-370 · NDIR con modulación de flujo cruzado
A13: 10 niveles macro, 34 subniveles y 80 ítems.
A14: APSA-370 (SO2) Analizador de dióxido de azufre HORIBA APSA-370 · Fluorescencia ultravioleta (UVF)
... A88: modelo (clic derecho → Mover o copiar → Crear una copia) antes de diligenciar las columnas O a S.

Sheet APMA-370 (CO)
A1: FASE 1 — INSPECCIÓN FÍSICA DEL EQUIPO · APMA-370 (CO) (catálogo + captura)
A3: Cliente: | D3: Principio de medición: | E3: NDIR con modulación de flujo cruzado
A4: NIT: | D4: Fecha de inspección:
A5: Equipo / Modelo: | B5: Analizador de monóxido de carbono HORIBA APMA-370 | D5: Técnico responsable:
A6: Número de serie: | D6: N.º de informe (MT):
A8: ID | B8: Nivel macro (N1) | C8: Subnivel (N2) | D8: Ítem (N3) | E8: Qué se verifica | F8: Tipo de dato | G8: Unidad | H8: Criterio de aceptación | I8: Límite inferior | J8: Límite superior | K8: Obligatorio | L8: Evidencia fotográfica requerida | M8: Repuesto / parte asociada | N8: Fuente documental | O8: Resultado | P8: Valor medido | Q8: Verificación de rango | R8: Foto adjunta | S8: Observación
A9: 1.1.1 | B9: 1. Verificación funcional inicial | C9: 1.1 Encendido y LEDs frontales | D9: LED de encendido (Power LED) | E9: Color del LED indicador de encendido en el panel frontal | F9: OK / No OK | H9: Debe iluminarse en verde fijo (operación normal). Rojo indica alarma activa | K9: Sí | L9: Sí | N9: P-ST-018-MAN OPER APMA 370 V2 | O9: Pendiente | Q9: =IF($F9<>"Numérico","",IF($P9="","Sin dato",IF(AND(OR(NOT(ISNUMBER($I9)),$P9>=$I9),OR(NOT(ISNUMBER($J9)),$P9<=$J9)),"Dentro de rango","Fuera de rango")))
A10: 1.1.2 | B10: 1. Verificación funcional inicial | C10: 1.1 Encendido y LEDs frontales | D10: LED de alarma (Alarm LED) | E10: Estado de alarma activa verificado mediante el color del indicador frontal | F10: Sí/No | H10: El LED de alarma debe permanecer apagado. Si cambia a rojo indica fallo de hardware o de parámetro | K10: Sí | L10: No | N10: P-ST-018-MAN OPER APMA 370 V2 | O10: Pendiente | Q10: =IF($F10<>"Numérico","",IF($P10="","Sin dato",IF(AND(OR(NOT(ISNUMBER($I10)),$P10>=$I10),OR(NOT(ISNUMBER($J10)),$P10<=$J10)),"Dentro de rango","Fuera de rango")))
A11: 1.1.3 | B11: 1. Verificación funcional inicial | C11: 1.1 Encendido y LEDs frontales | D11: Inicialización del display (TFT LCD) | E11: Arranque correcto y despliegue del menú MEAS. sin bloqueos ni líneas muertas | F11: OK / No OK | H11: La pantalla LCD TFT debe encender de forma estable y permitir navegación táctil | K11: Sí | L11: Sí | M11: LCD Unit chassis and LCD 3200618696 | N11: AP-370 LCD replacement / MT_191TE0NC_APMA370_241226 | O11: Pendiente | Q11: =IF($F11<>"Numérico","",IF($P11="","Sin dato",IF(AND(OR(NOT(ISNUMBER($I11)),$P11>=$I11),OR(NOT(ISNUMBER($J11)),$P11<=$J11)),"Dentro de rango","Fuera de rango")))
A12: 1.2.1 | B12: 1. Verificación funcional inicial | C12: 1.2 Autodiagnóstico de software | D12: Versión de programa (firmware) | E12: Lectura de la versión de programa en la pantalla de información de software | F12: Texto | H12: Debe coincidir con la versión homologada de fábrica (estándar AP: P1000878001) | K12: Sí | L12: No | N12: 1 - LCD design change AP EN | O12: Pendiente | Q12: =IF($F12<>"Numérico","",IF($P12="","Sin dato",IF(AND(OR(NOT(ISNUMBER($I12)),$P12>=$I12),OR(NOT(ISNUMBER($J12)),$P12<=$J12)),"Dentro de rango","Fuera de rango")))
A13: 1.3.1 | B13: 1. Verificación funcional inicial | C13: 1.3 Estabilización térmica | D13: Tiempo de calentamiento inicial (warm-up) | E13: Tiempo transcurrido desde el encendido en frío hasta la estabilización | F13: Numérico | G13: horas | H13: Mínimo 3 h de calentamiento para estabilizar banco óptico y catalizador antes de medir. Límite superior PENDIENTE DE VALIDAR | I13: 3 | K13: Sí | L13: No | N13: GZ0000117746B SM E APXX-370 (Service Manual) | O13: Pendiente | Q13: =IF($F13<>"Numérico","",IF($P13="","Sin dato",IF(AND(OR(NOT(ISNUMBER($I13)),$P13>=$I13),OR(NOT(ISNUMBER($J13)),$P13<=$J13)),"Dentro de rango","Fuera de rango"))) -> Sin dato
A14: 2.1.1 | B14: 2. Identificación y trazabilidad | C14: 2.1 Placas e identificación física | D14: Placa de número de serie frontal | E14: Presencia y legibilidad del número de serie en el panel frontal inferior | F14: Texto | H14: Debe ser legible y coincidir con el registro y la hoja de vida de la estación | K14: Sí | L14: No | N14: MT_U7D80D0J_APMA370_260116 | O14: Pendiente | Q14: =IF($F14<>"Numérico","",IF($P14="","Sin dato",IF(AND(OR(NOT(ISNUMBER($I14)),$P14>=$I14),OR(NOT(ISNUMBER($J14)),$P14<=$J14)),"Dentro de rango","Fuera de rango")))
A15: 2.1.2 | B15: 2. Identificación y trazabilidad | C15: 2.1 Placas e identificación física | D15: Placa de número de serie posterior | E15: Presencia y legibilidad de la placa de datos metálica HORIBA en el panel trasero | F15: Texto | H15: Debe ser legible y coincidir con el serial frontal y la etiqueta de la cabina | K15: Sí | L15: No | N15: MT_U7D80D0J_APMA370_260116 | O15: Pendiente | Q15: =IF($F15<>"Numérico","",IF($P15="","Sin dato",IF(AND(OR(NOT(ISNUMBER($I15)),$P15>=$I15),OR(NOT(ISNUMBER($J15)),$P15<=$J15)),"Dentro de rango","Fuera de rango")))
A16: 2.2.1 | B16: 2. Identificación y trazabilidad | C16: 2.2 Identificación lógica | D16: ID del equipo (Machine ID) | E16: Configuración del código ID del analizador para identificación en red | F16: Numérico | H16: El ID configurado en el menú SYSTEM debe coincidir con el asignado por el sistema de adquisición | I16: 0 | J16: 255 | K16: Sí | L16: No | N16: P-ST-018-MAN OPER APMA 370 V2 | O16: Pendiente | Q16: =IF($F16<>"Numérico","",IF($P16="","Sin dato",IF(AND(OR(NOT(ISNUMBER($I16)),$P16>=$I16),OR(NOT(ISNUMBER($J16)),$P16<=$J16)),"Dentro de rango","Fuera de rango"))) -> Sin dato
A17: 2.3.1 | B17: 2. Identificación y trazabilidad | C17: 2.3 Etiquetas de seguridad | D17: Señalización de choque eléctrico | E17: Etiquetas de advertencia de alto voltaje en cubiertas de placas y transformadores | F17: Presente / Ausente | H17: Deben estar adheridas y legibles las advertencias Choque eléctrico 1, 2 y 3 | K17: Sí | L17: Sí | N17: P-ST-019-MAN MTTO APMA370 V2 | O17: Pendiente | Q17: =IF($F17<>"Numérico","",IF($P17="","Sin dato",IF(AND(OR(NOT(ISNUMBER($I17)),$P17>=$I17),OR(NOT(ISNUMBER($J17)),$P17<=$J17)),"Dentro de rango","Fuera de rango")))
A18: 2.3.2 | B18: 2. Identificación y trazabilidad | C18: 2.3 Etiquetas de seguridad | D18: Señalización de componentes calientes | E18: Etiquetas adhesivas amarillas de advertencia térmica en zonas de alta temperatura | F18: Presente / Ausente | H18: Deben estar adheridas las etiquetas de calor sobre la carcasa del catalizador y de la bomba | K18: Sí | L18: Sí | N18: P-ST-019-MAN MTTO APMA370 V2 | O18: Pendiente | Q18: =IF($F18<>"Numérico","",IF($P18="","Sin dato",IF(AND(OR(NOT(ISNUMBER($I18)),$P18>=$I18),OR(NOT(ISNUMBER($J18)),$P18<=$J18)),"Dentro de rango","Fuera de rango")))
A19: 3.1.1 | B19: 3. Estado de calibración | C19: 3.1 Coeficientes de calibración | D19: Coeficiente de calibración de cero | E19: Factor de corrección de cero almacenado tras el último ajuste manual o AIC | F19: Numérico | G19: counts | H19: Debe estar dentro del rango operativo; fuera de él parpadea la alarma ZERO | I19: -3500 | J19: 3500 | K19: Sí | L19: No | N19: P-ST-018-MAN OPER APMA 370 V2 | O19: Pendiente | Q19: =IF($F19<>"Numérico","",IF($P19="","Sin dato",IF(AND(OR(NOT(ISNUMBER($I19)),$P19>=$I19),OR(NOT(ISNUMBER($J19)),$P19<=$J19)),"Dentro de rango","Fuera de rango"))) -> Sin dato
A20: 3.1.2 | B20: 3. Estado de calibración | C20: 3.1 Coeficientes de calibración | D20: Coeficiente de calibración de span | E20: Ganancia del detector de CO calibrada con gas patrón y almacenada en memoria | F20: Numérico | H20: Debe estar dentro de los límites de amplificación admitidos; fuera de él parpadea la alarma SPAN | I20: 0.5 | J20: 2 | K20: Sí | L20: No | N20: P-ST-018-MAN OPER APMA 370 V2 | O20: Pendiente | Q20: =IF($F20<>"Numérico","",IF($P20="","Sin dato",IF(AND(OR(NOT(ISNUMBER($I20)),$P20>=$I20),OR(NOT(ISNUMBER($J20)),$P20<=$J20)),"Dentro de rango","Fuera de rango"))) -> Sin dato
A21: 3.2.1 | B21: 3. Estado de calibración | C21: 3.2 Suministro de gases patrón | D21: Presión de entrada de gas patrón | E21: Presión de entrega de gases de referencia (cero y span) en las entradas traseras | F21: Numérico | G21: kPa | H21: Deben entregarse ligeramente por encima de la presión atmosférica para generar overflow | I21: 0 | J21: 0.5 | K21: Sí | L21: No | N21: P-ST-018-MAN OPER APMA 370 V2 | O21: Pendiente | Q21: =IF($F21<>"Numérico","",IF($P21="","Sin dato",IF(AND(OR(NOT(ISNUMBER($I21)),$P21>=$I21),OR(NOT(ISNUMBER($J21)),$P21<=$J21)),"Dentro de rango","Fuera de rango"))) -> Sin dato
A22: 3.2.2 | B22: 3. Estado de calibración | C22: 3.2 Suministro de gases patrón | D22: Caudal de exceso de gas de calibración (OVER FLOW) | E22: Caudal excedente medido por el sensor de flujo opcional de calibración | F22: Numérico | G22: L/min | H22: Caudal mínimo 1,2 L/min para que el analizador absorba gas patrón sin aspirar aire ambiente. Límite superior PENDIENTE DE VALIDAR | I22: 1.2 | K22: Sí | L22: No | N22: P-ST-018-MAN OPER APMA 370 V2 | O22: Pendiente | Q22: =IF($F22<>"Numérico","",IF($P22="","Sin dato",IF(AND(OR(NOT(ISNUMBER($I22)),$P22>=$I22),OR(NOT(ISNUMBER($J22)),$P22<=$J22)),"Dentro de rango","Fuera de rango"))) -> Sin dato
A23: 3.3.1 | B23: 3. Estado de calibración | C23: 3.3 Secuencia de autocalibración (AIC) | D23: Tiempo de espera (WAIT) en AIC | E23: Tiempo configurado para purgar la celda y estabilizar lecturas tras conmutar la línea de gas | F23: Numérico | G23: minutos | H23: Tiempo mínimo de retardo tras conmutar la línea de gas; el fabricante recomienda 3 min o más | I23: 3 | J23: 999 | K23: Sí | L23: No | N23: P-ST-018-MAN OPER APMA 370 V2 | O23: Pendiente | Q23: =IF($F23<>"Numérico","",IF($P23="","Sin dato",IF(AND(OR(NOT(ISNUMBER($I23)),$P23>=$I23),OR(NOT(ISNUMBER($J23)),$P23<=$J23)),"Dentro de rango","Fuera de rango"))) -> Sin dato
A24: 3.3.2 | B24: 3. Estado de calibración | C24: 3.3 Secuencia de autocalibración (AIC) | D24: Tiempo de sostenimiento (HOLD) en AIC | E24: Tiempo de retención y chequeo de lecturas de salida al finalizar el AIC | F24: Numérico | G24: minutos | H24: Tiempo de validación posterior a la calibración física de las señales analógicas | I24: 0 | J24: 999 | K24: Sí | L24: No | N24: P-ST-018-MAN OPER APMA 370 V2 | O24: Pendiente | Q24: =IF($F24<>"Numérico","",IF($P24="","Sin dato",IF(AND(OR(NOT(ISNUMBER($I24)),$P24>=$I24),OR(NOT(ISNUMBER($J24)),$P24<=$J24)),"Dentro de rango","Fuera de rango"))) -> Sin dato
A25: 3.3.3 | B25: 3. Estado de calibración | C25: 3.3 Secuencia de autocalibración (AIC) | D25: Activación de calibración (CAL) en AIC | E25: Selección de la corrección física del factor cero/span durante el AIC | F25: Sí/No | H25: Define si se corrigen factores (YES) o solo se realiza lectura de verificación (NO) | K25: Sí | L25: No | N25: P-ST-018-MAN OPER APMA 370 V2 | O25: Pendiente | Q25: =IF($F25<>"Numérico","",IF($P25="","Sin dato",IF(AND(OR(NOT(ISNUMBER($I25)),$P25>=$I25),OR(NOT(ISNUMBER($J25)),$P25<=$J25)),"Dentro de rango","Fuera de rango")))
A26: 4.1.1 | B26: 4. Línea de muestreo y acondicionamiento | C26: 4.1 Conectores neumáticos traseros | D26: Férula de Sample Inlet (Sleeve) | E26: Presencia del casquillo de teflón de sellado interno en la entrada de muestra | F26: Presente / Ausente | H26: Debe estar montada la férula para asegurar acople hermético libre de aire falso | K26: Sí | L26: Sí | M26: Sleeve SO2001-6 (3030021777) | N26: MT_P4B4CK60_APMA370_220511 | O26: Pendiente | Q26: =IF($F26<>"Numérico","",IF($P26="","Sin dato",IF(AND(OR(NOT(ISNUMBER($I26)),$P26>=$I26),OR(NOT(ISNUMBER($J26)),$P26<=$J26)),"Dentro de rango","Fuera de rango")))
A27: 4.1.2 | B27: 4. Línea de muestreo y acondicionamiento | C27: 4.1 Conectores neumáticos traseros | D27: Tuerca de Sample Inlet (Cap Nut) | E27: Presencia de la tuerca plástica de rosca fina en la entrada de muestra | F27: Presente / Ausente | H27: Debe estar presente y roscada firmemente la tuerca PVDF para sellar la tubería | K27: Sí | L27: Sí | M27: Cap Nut S020020-6PVDF (3030021779) | N27: MT_P4B4CK60_APMA370_220511 | O27: Pendiente | Q27: =IF($F27<>"Numérico","",IF($P27="","Sin dato",IF(AND(OR(NOT(ISNUMBER($I27)),$P27>=$I27),OR(NOT(ISNUMBER($J27)),$P27<=$J27)),"Dentro de rango","Fuera de rango")))
A28: 4.1.3 | B28: 4. Línea de muestreo y acondicionamiento | C28: 4.1 Conectores neumáticos traseros | D28: Férula de Exhaust (Sleeve) | E28: Presencia del casquillo de teflón de sellado interno en la salida de escape | F28: Presente / Ausente | H28: Debe estar montada la férula para evitar fugas de gases de escape hacia la cabina | K28: Sí | L28: Sí | M28: Sleeve SO2001-6 (3030021777) | N28: MT_P4B4CK60_APMA370_220511 | O28: Pendiente | Q28: =IF($F28<>"Numérico","",IF($P28="","Sin dato",IF(AND(OR(NOT(ISNUMBER($I28)),$P28>=$I28),OR(NOT(ISNUMBER($J28)),$P28<=$J28)),"Dentro de rango","Fuera de rango")))
A29: 4.1.4 | B29: 4. Línea de muestreo y acondicionamiento | C29: 4.1 Conectores neumáticos traseros | D29: Tuerca de Exhaust (Cap Nut) | E29: Presencia de la tuerca plástica de rosca fina en la salida de escape | F29: Presente / Ausente | H29: Debe estar presente y roscada firmemente la tuerca PVDF para canalizar el escape | K29: Sí | L29: Sí | M29: Cap Nut S020020-6PVDF (3030021779) | N29: MT_P4B4CK60_APMA370_220511 | O29: Pendiente | Q29: =IF($F29<>"Numérico","",IF($P29="","Sin dato",IF(AND(OR(NOT(ISNUMBER($I29)),$P29>=$I29),OR(NOT(ISNUMBER($J29)),$P29<=$J29)),"Dentro de rango","Fuera de rango")))
A30: 4.1.5 | B30: 4. Línea de muestreo y acondicionamiento | C30: 4.1 Conectores neumáticos traseros | D30: Panel Mount Union (SO21521-6 PVDF) | E30: Estado físico e integridad del racor plástico de montaje de panel | F30: OK / No OK | H30: Racor libre de fisuras en su rosca o fatiga de material por sobreajuste | K30: Sí | L30: Sí | M30: Panel mount union SO21521-6 (3030021548) | N30: MT_191TE0NC_APMA370_241226 | O30: Pendiente | Q30: =IF($F30<>"Numérico","",IF($P30="","Sin dato",IF(AND(OR(NOT(ISNUMBER($I30)),$P30>=$I30),OR(NOT(ISNUMBER($J30)),$P30<=$J30)),"Dentro de rango","Fuera de rango")))
A31: 4.2.1 | B31: 4. Línea de muestreo y acondicionamiento | C31: 4.2 Portafiltros frontal | D31: Colmatación del filtro de partículas PA-10L | E31: Nivel de colmatación, hollín, polvo o humedad en el filtro frontal de teflón de 54 mm | F31: OK / No OK | H31: Filtro de teflón blanco uniforme, sin partículas ni manchas oscuras que estrangulen el caudal | K31: Sí | L31: Sí | M31: Filter Element PA-10L (3200043947 / 3200043947-1PC) | N31: MT_56X1BA8G_APMA370_260109 | O31: Pendiente | Q31: =IF($F31<>"Numérico","",IF($P31="","Sin dato",IF(AND(OR(NOT(ISNUMBER($I31)),$P31>=$I31),OR(NOT(ISNUMBER($J31)),$P31<=$J31)),"Dentro de rango","Fuera de rango")))
A32: 4.2.2 | B32: 4. Línea de muestreo y acondicionamiento | C32: 4.2 Portafiltros frontal | D32: Empaque del filtro frontal (PA-10L) | E32: Flexibilidad y ausencia de grietas en la junta elástica plana del portafiltros | F32: OK / No OK | H32: Empaque blando, sin aplastamientos ni deformaciones permanentes que provoquen fugas | K32: Sí | L32: Sí | M32: Empaque de filtro (3200044273) | N32: P-ST-019-MAN MTTO APMA370 V2 | O32: Pendiente | Q32: =IF($F32<>"Numérico","",IF($P32="","Sin dato",IF(AND(OR(NOT(ISNUMBER($I32)),$P32>=$I32),OR(NOT(ISNUMBER($J32)),$P32<=$J32)),"Dentro de rango","Fuera de rango")))
A33: 4.2.3 | B33: 4. Línea de muestreo y acondicionamiento | C33: 4.2 Portafiltros frontal | D33: Junta tórica del portafiltros (O-Ring) | E33: Resequedad, microfisuras o deformación de la junta tórica de la tapa del filtro | F33: OK / No OK | H33: Junta de vitón elástica y ligeramente lubricada para garantizar hermetismo de la tapa | K33: Sí | L33: Sí | M33: O-ring (3200043785) | N33: P-ST-019-MAN MTTO APMA370 V2 | O33: Pendiente | Q33: =IF($F33<>"Numérico","",IF($P33="","Sin dato",IF(AND(OR(NOT(ISNUMBER($I33)),$P33>=$I33),OR(NOT(ISNUMBER($J33)),$P33<=$J33)),"Dentro de rango","Fuera de rango")))
A34: 4.3.1 | B34: 4. Línea de muestreo y acondicionamiento | C34: 4.3 Acondicionamiento de la muestra | D34: Trampa de humedad (Mist Catcher BAA) | E34: Acumulación de agua condensada y saturación del depurador de humedad | F34: OK / No OK | H34: El depósito debe estar libre de condensados y el relleno sin saturación física | K34: Sí | L34: Sí | M34: MC-1 (3200043946) | N34: MT_V440EL8D_APMA370_260430 | O34: Pendiente | Q34: =IF($F34<>"Numérico","",IF($P34="","Sin dato",IF(AND(OR(NOT(ISNUMBER($I34)),$P34>=$I34),OR(NOT(ISNUMBER($J34)),$P34<=$J34)),"Dentro de rango","Fuera de rango")))
A35: 4.3.2 | B35: 4. Línea de muestreo y acondicionamiento | C35: 4.3 Acondicionamiento de la muestra | D35: Líneas de teflón internas | E35: Estrangulamientos, dobleces agudos o acumulación de suciedad en mangueras neumáticas | F35: OK / No OK | H35: Tuberías de teflón translúcidas, firmes en sus racores y sin dobleces que restrinjan el flujo | K35: Sí | L35: Sí | N35: MT_U403C0JJ_APMA370_21033001 | O35: Pendiente | Q35: =IF($F35<>"Numérico","",IF($P35="","Sin dato",IF(AND(OR(NOT(ISNUMBER($I35)),$P35>=$I35),OR(NOT(ISNUMBER($J35)),$P35<=$J35)),"Dentro de rango","Fuera de rango")))
A36: 5.1.1 | B36: 5. Sistema neumático | C36: 5.1 Caudal y presión de muestra | D36: Caudal volumétrico de muestra (SAMPLE) | E36: Caudal de gas de muestra a través de la celda de medida en ANALOG INPUT | F36: Numérico | G36: L/min | H36: Caudal nominal de muestreo; fuera de 1,0 a 2,0 L/min se activa la alarma FLOW 1 | I36: 1 | J36: 2 | K36: Sí | L36: No | N36: P-ST-018-MAN OPER APMA 370 V2 | O36: Pendiente | Q36: =IF($F36<>"Numérico","",IF($P36="","Sin dato",IF(AND(OR(NOT(ISNUMBER($I36)),$P36>=$I36),OR(NOT(ISNUMBER($J36)),$P36<=$J36)),"Dentro de rango","Fuera de rango"))) -> Sin dato
A37: 5.1.2 | B37: 5. Sistema neumático | C37: 5.1 Caudal y presión de muestra | D37: Presión de succión de la bomba (PUMP) | E37: Presión de succión generada por la bomba de muestreo en la celda óptica | F37: Numérico | G37: kPa | H37: Lectura en ANALOG INPUT; un valor mayor o igual a 65 kPa activa la alarma PRE1 | I37: 0 | J37: 65 | K37: Sí | L37: No | N37: P-ST-018-MAN OPER APMA 370 V2 | O37: Pendiente | Q37: =IF($F37<>"Numérico","",IF($P37="","Sin dato",IF(AND(OR(NOT(ISNUMBER($I37)),$P37>=$I37),OR(NOT(ISNUMBER($J37)),$P37<=$J37)),"Dentro de rango","Fuera de rango"))) -> Sin dato
A38: 5.2.1 | B38: 5. Sistema neumático | C38: 5.2 Bomba de muestreo | D38: Vibración y ruido mecánico de la bomba (P-1-B) | E38: Estabilidad del motor y rodamientos de la bomba de muestreo (verificación auditiva y táctil) | F38: OK / No OK | H38: Operación continua y estable, sin golpes metálicos ni oscilación mecánica excesiva | K38: Sí | L38: Sí | M38: Pump unit doble cabezal P-1-B (3200043946) | N38: P-ST-019-MAN MTTO APMA370 V2 | O38: Pendiente | Q38: =IF($F38<>"Numérico","",IF($P38="","Sin dato",IF(AND(OR(NOT(ISNUMBER($I38)),$P38>=$I38),OR(NOT(ISNUMBER($J38)),$P38<=$J38)),"Dentro de rango","Fuera de rango")))
A39: 5.2.2 | B39: 5. Sistema neumático | C39: 5.2 Bomba de muestreo | D39: Desgaste de diafragmas de la bomba (P-1-D) | E39: Resequedad, porosidad o fisuras de los dos diafragmas de EPDM de la bomba | F39: OK / No OK | H39: Diafragmas de EPDM elásticos y sin fisuras, para evitar caídas de vacío y de caudal | K39: Sí | L39: Sí | M39: Diaphragm Assy GS/GD EPDM (3011026485 / 3200044033 / 3200602390) | N39: MT_2V0CY0DC_APMA370_250930 | O39: Pendiente | Q39: =IF($F39<>"Numérico","",IF($P39="","Sin dato",IF(AND(OR(NOT(ISNUMBER($I39)),$P39>=$I39),OR(NOT(ISNUMBER($J39)),$P39<=$J39)),"Dentro de rango","Fuera de rango")))
A40: 5.2.3 | B40: 5. Sistema neumático | C40: 5.2 Bomba de muestreo | D40: Limpieza de cabezales y válvulas de la bomba | E40: Acumulación de depósitos, residuos o polvo negro en las válvulas planas de teflón | F40: OK / No OK | H40: Cámaras del cabezal y charnelas de válvula limpias para garantizar sellado hermético | K40: Sí | L40: Sí | N40: MT_U403C0JJ_APMA370_21033001 | O40: Pendiente | Q40: =IF($F40<>"Numérico","",IF($P40="","Sin dato",IF(AND(OR(NOT(ISNUMBER($I40)),$P40>=$I40),OR(NOT(ISNUMBER($J40)),$P40<=$J40)),"Dentro de rango","Fuera de rango")))
A41: 5.3.1 | B41: 5. Sistema neumático | C41: 5.3 Válvulas y estanqueidad | D41: Conmutación de la válvula de modulación (SV-2) | E41: Conmutación cíclica entre gas de muestra y aire de referencia | F41: OK / No OK | H41: Debe conmutar neumáticamente de forma cíclica a una frecuencia constante de 1 Hz | K41: Sí | L41: Sí | M41: Solenoid Valve sample/Ref.-gas SV-2 (3200043946) | N41: P-ST-019-MAN MTTO APMA370 V2 | O41: Pendiente | Q41: =IF($F41<>"Numérico","",IF($P41="","Sin dato",IF(AND(OR(NOT(ISNUMBER($I41)),$P41>=$I41),OR(NOT(ISNUMBER($J41)),$P41<=$J41)),"Dentro de rango","Fuera de rango")))
A42: 5.3.2 | B42: 5. Sistema neumático | C42: 5.3 Válvulas y estanqueidad | D42: Prueba de estanqueidad (Leak Test) | E42: Mantenimiento del vacío sellando el puerto de entrada para detectar fugas | F42: OK / No OK | H42: El circuito neumático debe mantener el vacío estable sin fluctuaciones tras aislar la succión | K42: Sí | L42: Sí | N42: GZ0000117746B SM E APXX-370 (Service Manual) | O42: Pendiente | Q42: =IF($F42<>"Numérico","",IF($P42="","Sin dato",IF(AND(OR(NOT(ISNUMBER($I42)),$P42>=$I42),OR(NOT(ISNUMBER($J42)),$P42<=$J42)),"Dentro de rango","Fuera de rango")))
...

Sheet APSA-370 (SO2)
A1: FASE 1 — INSPECCIÓN FÍSICA DEL EQUIPO · APSA-370 (SO2) (catálogo + captura)
A3: Cliente: | D3: Principio de medición: | E3: Fluorescencia ultravioleta (UVF)
A4: NIT: | D4: Fecha de inspección:
A5: Equipo / Modelo: | B5: Analizador de dióxido de azufre HORIBA APSA-370 | D5: Técnico responsable:
A6: Número de serie: | D6: N.º de informe (MT):
A8: ID | B8: Nivel macro (N1) | C8: Subnivel (N2) | D8: Ítem (N3) | E8: Qué se verifica | F8: Tipo de dato | G8: Unidad | H8: Criterio de aceptación | I8: Límite inferior | J8: Límite superior | K8: Obligatorio | L8: Evidencia fotográfica requerida | M8: Repuesto / parte asociada | N8: Fuente documental | O8: Resultado | P8: Valor medido | Q8: Verificación de rango | R8: Foto adjunta | S8: Observación
A9: 1.1.1 | B9: 1. Verificación funcional inicial | C9: 1.1 Encendido y LEDs frontales | D9: LED de encendido del panel frontal | E9: Estado de iluminación del LED de encendido con el analizador energizado | F9: OK / No OK | H9: Debe iluminarse en verde en operación normal; cambia a rojo si existe alarma activa | K9: Sí | L9: Sí | N9: P-ST-030-MAN OPER APSA 370 V2 | O9: Pendiente | Q9: =IF($F9<>"Numérico","",IF($P9="","Sin dato",IF(AND(OR(NOT(ISNUMBER($I9)),$P9>=$I9),OR(NOT(ISNUMBER($J9)),$P9<=$J9)),"Dentro de rango","Fuera de rango")))
A10: 1.2.1 | B10: 1. Verificación funcional inicial | C10: 1.2 Autodiagnóstico de software | D10: Inicialización de parámetros en SRAM | E10: Carga de datos lógicos y ausencia de errores de inicialización al arrancar la CPU | F10: OK / No OK | H10: Arranque limpio sin errores de memoria y con la pantalla MEAS cargada automáticamente | K10: Sí | L10: Sí | N10: P-ST-030-MAN OPER APSA 370 V2 | O10: Pendiente | Q10: =IF($F10<>"Numérico","",IF($P10="","Sin dato",IF(AND(OR(NOT(ISNUMBER($I10)),$P10>=$I10),OR(NOT(ISNUMBER($J10)),$P10<=$J10)),"Dentro de rango","Fuera de rango")))
A11: 1.2.2 | B11: 1. Verificación funcional inicial | C11: 1.2 Autodiagnóstico de software | D11: Indicador de alarmas activas en pantalla | E11: Presencia del botón ALARM en la esquina inferior derecha de la pantalla principal | F11: Sí/No | H11: El botón de alarma no debe estar visible en la pantalla MEAS en condiciones normales | K11: Sí | L11: No | N11: P-ST-030-MAN OPER APSA 370 V2 | O11: Pendiente | Q11: =IF($F11<>"Numérico","",IF($P11="","Sin dato",IF(AND(OR(NOT(ISNUMBER($I11)),$P11>=$I11),OR(NOT(ISNUMBER($J11)),$P11<=$J11)),"Dentro de rango","Fuera de rango")))
A12: 1.2.3 | B12: 1. Verificación funcional inicial | C12: 1.2 Autodiagnóstico de software | D12: Identificación del programa en menú | E12: Versión y número de programa en la pantalla de información del sistema | F12: Texto | H12: Debe mostrar el código de programa estándar de fábrica (AP: P1000878001 / EN: P1000877001) | K12: Sí | L12: No | N12: 1 - LCD design change AP EN | O12: Pendiente | Q12: =IF($F12<>"Numérico","",IF($P12="","Sin dato",IF(AND(OR(NOT(ISNUMBER($I12)),$P12>=$I12),OR(NOT(ISNUMBER($J12)),$P12<=$J12)),"Dentro de rango","Fuera de rango")))
A13: 1.3.1 | B13: 1. Verificación funcional inicial | C13: 1.3 Estabilización térmica | D13: Tiempo de calentamiento y estabilización | E13: Tiempo transcurrido desde el encendido hasta la calibración o la medición en campo | F13: Numérico | G13: horas | H13: Mínimo 3 h de estabilización; se recomienda 24 a 48 h para mediciones de campo estables | I13: 3 | J13: 48 | K13: Sí | L13: No | N13: P-ST-030-MAN OPER APSA 370 V2 | O13: Pendiente | Q13: =IF($F13<>"Numérico","",IF($P13="","Sin dato",IF(AND(OR(NOT(ISNUMBER($I13)),$P13>=$I13),OR(NOT(ISNUMBER($J13)),$P13<=$J13)),"Dentro de rango","Fuera de rango"))) -> Sin dato
A14: 1.3.2 | B14: 1. Verificación funcional inicial | C14: 1.3 Estabilización térmica | D14: Ajuste del minuto de reset de integración | E14: Minuto del reloj en el que se ejecuta el reset de integración (RESET TIME) | F14: Numérico | G14: minutos | H14: Debe estar ajustado a 00 o 30 min según los requerimientos del sistema de adquisición | I14: 0 | J14: 30 | K14: Sí | L14: No | N14: P-ST-030-MAN OPER APSA 370 V2 | O14: Pendiente | Q14: =IF($F14<>"Numérico","",IF($P14="","Sin dato",IF(AND(OR(NOT(ISNUMBER($I14)),$P14>=$I14),OR(NOT(ISNUMBER($J14)),$P14<=$J14)),"Dentro de rango","Fuera de rango"))) -> Sin dato
A15: 2.1.1 | B15: 2. Identificación y trazabilidad | C15: 2.1 Placas e identificación física | D15: Número de serie del analizador | E15: Legibilidad e integridad del serial del fabricante en la placa posterior metálica | F15: Texto | H15: Debe ser legible y registrarse en la hoja de campo | K15: Sí | L15: No | N15: MT_829WE09R_APSA370_221102 | O15: Pendiente | Q15: =IF($F15<>"Numérico","",IF($P15="","Sin dato",IF(AND(OR(NOT(ISNUMBER($I15)),$P15>=$I15),OR(NOT(ISNUMBER($J15)),$P15<=$J15)),"Dentro de rango","Fuera de rango")))
A16: 2.1.2 | B16: 2. Identificación y trazabilidad | C16: 2.1 Placas e identificación física | D16: Número HGS del analizador | E16: Identificación del número HGS del analizador y del sistema para trazabilidad de repuestos | F16: Texto | H16: El número HGS debe estar identificado en la placa del equipo o en la documentación de fábrica | K16: Sí | L16: No | N16: 1 - LCD design change AP EN | O16: Pendiente | Q16: =IF($F16<>"Numérico","",IF($P16="","Sin dato",IF(AND(OR(NOT(ISNUMBER($I16)),$P16>=$I16),OR(NOT(ISNUMBER($J16)),$P16<=$J16)),"Dentro de rango","Fuera de rango")))
A17: 2.2.1 | B17: 2. Identificación y trazabilidad | C17: 2.2 Etiquetas de seguridad | D17: Etiqueta de advertencia de alto voltaje (lámpara) | E17: Presencia y legibilidad de la etiqueta de peligro de choque eléctrico cerca de la lámpara | F17: Presente / Ausente | H17: La etiqueta Choque Eléctrico 1 debe estar adherida y legible cerca del bloque óptico | K17: Sí | L17: Sí | N17: P-ST-029-MAN MTTO APSA370 V2 | O17: Pendiente | Q17: =IF($F17<>"Numérico","",IF($P17="","Sin dato",IF(AND(OR(NOT(ISNUMBER($I17)),$P17>=$I17),OR(NOT(ISNUMBER($J17)),$P17<=$J17)),"Dentro de rango","Fuera de rango")))
A18: 2.2.2 | B18: 2. Identificación y trazabilidad | C18: 2.2 Etiquetas de seguridad | D18: Etiqueta de advertencia de alta temperatura | E18: Etiqueta de peligro de quemadura térmica en componentes que acumulan calor | F18: Presente / Ausente | H18: La etiqueta de componente caliente debe estar visible en la bomba y en el HC Cutter | K18: Sí | L18: Sí | N18: P-ST-029-MAN MTTO APSA370 V2 | O18: Pendiente | Q18: =IF($F18<>"Numérico","",IF($P18="","Sin dato",IF(AND(OR(NOT(ISNUMBER($I18)),$P18>=$I18),OR(NOT(ISNUMBER($J18)),$P18<=$J18)),"Dentro de rango","Fuera de rango")))
A19: 3.1.1 | B19: 3. Estado de calibración | C19: 3.1 Coeficientes de calibración | D19: Coeficiente de calibración de cero (ZERO ADJUST) | E19: Coeficiente almacenado en el menú de calibración para el ajuste de cero | F19: Numérico | G19: counts | H19: Debe encontrarse dentro de los límites de tolerancia lógicos definidos por firmware | I19: -3500 | J19: 3500 | K19: Sí | L19: No | N19: P-ST-030-MAN OPER APSA 370 V2 | O19: Pendiente | Q19: =IF($F19<>"Numérico","",IF($P19="","Sin dato",IF(AND(OR(NOT(ISNUMBER($I19)),$P19>=$I19),OR(NOT(ISNUMBER($J19)),$P19<=$J19)),"Dentro de rango","Fuera de rango"))) -> Sin dato
A20: 3.1.2 | B20: 3. Estado de calibración | C20: 3.1 Coeficientes de calibración | D20: Coeficiente de calibración de span (SPAN ADJUST) | E20: Coeficiente de ganancia de pendiente almacenado tras la calibración de span | F20: Numérico | H20: Dentro de la tolerancia de ganancia de software; en campo se ubica típicamente entre 0,9 y 1,3 | I20: 0.5 | J20: 2 | K20: Sí | L20: No | N20: P-ST-030-MAN OPER APSA 370 V2 | O20: Pendiente | Q20: =IF($F20<>"Numérico","",IF($P20="","Sin dato",IF(AND(OR(NOT(ISNUMBER($I20)),$P20>=$I20),OR(NOT(ISNUMBER($J20)),$P20<=$J20)),"Dentro de rango","Fuera de rango"))) -> Sin dato
A21: 3.1.3 | B21: 3. Estado de calibración | C21: 3.1 Coeficientes de calibración | D21: Concentración de gas de span configurada (SPAN CONC) | E21: Ajuste de la concentración de gas patrón en la pantalla de edición de span | F21: Numérico | G21: ppm | H21: Debe configurarse el valor nominal exacto del cilindro de gas patrón de SO2 a utilizar | I21: 1e-05 | J21: 99999 | K21: Sí | L21: No | N21: P-ST-030-MAN OPER APSA 370 V2 | O21: Pendiente | Q21: =IF($F21<>"Numérico","",IF($P21="","Sin dato",IF(AND(OR(NOT(ISNUMBER($I21)),$P21>=$I21),OR(NOT(ISNUMBER($J21)),$P21<=$J21)),"Dentro de rango","Fuera de rango"))) -> Sin dato
A22: 3.2.1 | B22: 3. Estado de calibración | C22: 3.2 Suministro de gases patrón | D22: Presión del gas en el puerto posterior de calibración | E22: Estabilidad de la presión de suministro en la entrada de gas de calibración | F22: Numérico | G22: Pa | H22: La presión del gas de calibración debe mantenerse regulada para asegurar estabilidad neumática | I22: -500 | J22: 500 | K22: Sí | L22: No | N22: P-ST-030-MAN OPER APSA 370 V2 | O22: Pendiente | Q22: =IF($F22<>"Numérico","",IF($P22="","Sin dato",IF(AND(OR(NOT(ISNUMBER($I22)),$P22>=$I22),OR(NOT(ISNUMBER($J22)),$P22<=$J22)),"Dentro de rango","Fuera de rango"))) -> Sin dato
A23: 3.3.1 | B23: 3. Estado de calibración | C23: 3.3 Secuencia de autocalibración (AIC) | D23: Tiempo de espera para estabilización en AIC (WAIT) | E23: Tiempo de estabilización tras la conmutación de líneas de gas en calibración automática | F23: Numérico | G23: minutos | H23: Ajuste de tiempo para garantizar purga y estabilización completa de las lecturas | I23: 20 | J23: 999 | K23: Sí | L23: No | N23: P-ST-030-MAN OPER APSA 370 V2 | O23: Pendiente | Q23: =IF($F23<>"Numérico","",IF($P23="","Sin dato",IF(AND(OR(NOT(ISNUMBER($I23)),$P23>=$I23),OR(NOT(ISNUMBER($J23)),$P23<=$J23)),"Dentro de rango","Fuera de rango"))) -> Sin dato
A24: 3.3.2 | B24: 3. Estado de calibración | C24: 3.3 Secuencia de autocalibración (AIC) | D24: Tiempo de retención en AIC (HOLD) | E24: Tiempo de validación para registrar y verificar lecturas tras volver a MEAS | F24: Numérico | G24: minutos | H24: Tiempo configurado para la verificación posterior a la calibración | I24: 0 | J24: 999 | K24: Sí | L24: No | N24: P-ST-030-MAN OPER APSA 370 V2 | O24: Pendiente | Q24: =IF($F24<>"Numérico","",IF($P24="","Sin dato",IF(AND(OR(NOT(ISNUMBER($I24)),$P24>=$I24),OR(NOT(ISNUMBER($J24)),$P24<=$J24)),"Dentro de rango","Fuera de rango"))) -> Sin dato
A25: 3.3.3 | B25: 3. Estado de calibración | C25: 3.3 Secuencia de autocalibración (AIC) | D25: Habilitación de calibración en AIC (CAL YES/NO) | E25: Especificación de si se permite actualizar los coeficientes tras el AIC | F25: Sí/No | H25: YES actualiza automáticamente los coeficientes; NO solo calcula las derivas sin alterarlos | K25: Sí | L25: No | N25: P-ST-030-MAN OPER APSA 370 V2 | O25: Pendiente | Q25: =IF($F25<>"Numérico","",IF($P25="","Sin dato",IF(AND(OR(NOT(ISNUMBER($I25)),$P25>=$I25),OR(NOT(ISNUMBER($J25)),$P25<=$J25)),"Dentro de rango","Fuera de rango")))
A26: 3.4.1 | B26: 3. Estado de calibración | C26: 3.4 Deriva de cero (Zero Drift) | D26: Deriva diaria de cero en rangos bajos (rango menor o igual a 0,2 ppm) | E26: Deriva diaria de cero máxima permitida en rangos menores o iguales a 0,2 ppm | F26: Numérico | G26: ppb/día | H26: Desviación máxima diaria de la lectura del cero en rangos bajos | I26: -1 | J26: 1 | K26: Sí | L26: No | N26: P-ST-030-MAN OPER APSA 370 V2 | O26: Pendiente | Q26: =IF($F26<>"Numérico","",IF($P26="","Sin dato",IF(AND(OR(NOT(ISNUMBER($I26)),$P26>=$I26),OR(NOT(ISNUMBER($J26)),$P26<=$J26)),"Dentro de rango","Fuera de rango"))) -> Sin dato
A27: 3.4.2 | B27: 3. Estado de calibración | C27: 3.4 Deriva de cero (Zero Drift) | D27: Deriva semanal de cero en rangos bajos (rango menor o igual a 0,2 ppm) | E27: Deriva semanal de cero máxima permitida en rangos menores o iguales a 0,2 ppm | F27: Numérico | G27: ppb/semana | H27: Desviación máxima semanal de la lectura del cero en rangos bajos | I27: -1 | J27: 1 | K27: Sí | L27: No | N27: P-ST-030-MAN OPER APSA 370 V2 | O27: Pendiente | Q27: =IF($F27<>"Numérico","",IF($P27="","Sin dato",IF(AND(OR(NOT(ISNUMBER($I27)),$P27>=$I27),OR(NOT(ISNUMBER($J27)),$P27<=$J27)),"Dentro de rango","Fuera de rango"))) -> Sin dato
A28: 3.4.3 | B28: 3. Estado de calibración | C28: 3.4 Deriva de cero (Zero Drift) | D28: Deriva diaria de cero en rangos altos (rango mayor a 0,2 ppm) | E28: Deriva diaria de cero máxima permitida en rangos superiores a 0,2 ppm | F28: Numérico | G28: % F.S. | H28: Desviación máxima diaria del cero respecto al fondo de escala, en rangos altos | I28: -1 | J28: 1 | K28: Sí | L28: No | N28: P-ST-030-MAN OPER APSA 370 V2 | O28: Pendiente | Q28: =IF($F28<>"Numérico","",IF($P28="","Sin dato",IF(AND(OR(NOT(ISNUMBER($I28)),$P28>=$I28),OR(NOT(ISNUMBER($J28)),$P28<=$J28)),"Dentro de rango","Fuera de rango"))) -> Sin dato
A29: 3.4.4 | B29: 3. Estado de calibración | C29: 3.4 Deriva de cero (Zero Drift) | D29: Deriva semanal de cero en rangos altos (rango mayor a 0,2 ppm) | E29: Deriva semanal de cero máxima permitida en rangos superiores a 0,2 ppm | F29: Numérico | G29: % F.S. | H29: Desviación máxima semanal del cero respecto al fondo de escala, en rangos altos | I29: -2 | J29: 2 | K29: Sí | L29: No | N29: P-ST-030-MAN OPER APSA 370 V2 | O29: Pendiente | Q29: =IF($F29<>"Numérico","",IF($P29="","Sin dato",IF(AND(OR(NOT(ISNUMBER($I29)),$P29>=$I29),OR(NOT(ISNUMBER($J29)),$P29<=$J29)),"Dentro de rango","Fuera de rango"))) -> Sin dato
A30: 3.5.1 | B30: 3. Estado de calibración | C30: 3.5 Deriva de span (Span Drift) | D30: Deriva diaria de span (todos los rangos) | E30: Deriva diaria de span máxima permitida con variación térmica dentro de 5 °C | F30: Numérico | G30: % F.S. | H30: Desviación diaria máxima tolerada de la lectura de span | I30: -1 | J30: 1 | K30: Sí | L30: No | N30: P-ST-030-MAN OPER APSA 370 V2 | O30: Pendiente | Q30: =IF($F30<>"Numérico","",IF($P30="","Sin dato",IF(AND(OR(NOT(ISNUMBER($I30)),$P30>=$I30),OR(NOT(ISNUMBER($J30)),$P30<=$J30)),"Dentro de rango","Fuera de rango"))) -> Sin dato
A31: 3.5.2 | B31: 3. Estado de calibración | C31: 3.5 Deriva de span (Span Drift) | D31: Deriva semanal de span (todos los rangos) | E31: Deriva semanal de span máxima permitida con variación térmica dentro de 5 °C | F31: Numérico | G31: % F.S. | H31: Desviación semanal máxima tolerada de la lectura de span | I31: -2 | J31: 2 | K31: Sí | L31: No | N31: P-ST-030-MAN OPER APSA 370 V2 | O31: Pendiente | Q31: =IF($F31<>"Numérico","",IF($P31="","Sin dato",IF(AND(OR(NOT(ISNUMBER($I31)),$P31>=$I31),OR(NOT(ISNUMBER($J31)),$P31<=$J31)),"Dentro de rango","Fuera de rango"))) -> Sin dato
A32: 3.6.1 | B32: 3. Estado de calibración | C32: 3.6 Linealidad | D32: Criterio de linealidad de calibración (diferencia de mejor ajuste) | E32: Desviación máxima de cada punto de una calibración multipunto respecto a la recta de regresión | F32: Numérico | G32: % F.S. | H32: Diferencia máxima respecto a la línea de mejor ajuste, conforme a la normativa de calibración | I32: -2 | J32: 2 | K32: Sí | L32: No | N32: P-ST-030-MAN OPER APSA 370 V2 | O32: Pendiente | Q32: =IF($F32<>"Numérico","",IF($P32="","Sin dato",IF(AND(OR(NOT(ISNUMBER($I32)),$P32>=$I32),OR(NOT(ISNUMBER($J32)),$P32<=$J32)),"Dentro de rango","Fuera de rango"))) -> Sin dato
A33: 4.1.1 | B33: 4. Línea de muestreo y acondicionamiento | C33: 4.1 Portafiltros frontal | D33: Estado del elemento filtrante PA-10L | E33: Grado de saturación y oscurecimiento del filtro de teflón de 54 mm del panel frontal | F33: OK / No OK | H33: Debe verse limpio, sin hollín ni decoloración marrón; reemplazar cada 2 semanas | K33: Sí | L33: Sí | M33: Filter Element PA-10L (3200043947 / 3200043947-1PC) | N33: P-ST-029-MAN MTTO APSA370 V2 | O33: Pendiente | Q33: =IF($F33<>"Numérico","",IF($P33="","Sin dato",IF(AND(OR(NOT(ISNUMBER($I33)),$P33>=$I33),OR(NOT(ISNUMBER($J33)),$P33<=$J33)),"Dentro de rango","Fuera de rango")))
A34: 4.1.2 | B34: 4. Línea de muestreo y acondicionamiento | C34: 4.1 Portafiltros frontal | D34: Junta tórica del portafiltros (O-Ring) | E34: Elasticidad y sellado del O-ring de la tapa del portafiltros frontal | F34: OK / No OK | H34: Sin resequedad, fisuras ni deformación por aplastamiento; reemplazar cada 1 año | K34: Sí | L34: Sí | M34: O-Ring (3014059499) | N34: P-ST-029-MAN MTTO APSA370 V2 | O34: Pendiente | Q34: =IF($F34<>"Numérico","",IF($P34="","Sin dato",IF(AND(OR(NOT(ISNUMBER($I34)),$P34>=$I34),OR(NOT(ISNUMBER($J34)),$P34<=$J34)),"Dentro de rango","Fuera de rango")))
A35: 4.1.3 | B35: 4. Línea de muestreo y acondicionamiento | C35: 4.1 Portafiltros frontal | D35: Humedad en el portafiltros | E35: Presencia de condensación de agua líquida en la caja del portafiltros frontal | F35: Sí/No | H35: Debe estar completamente seco; la presencia de agua indica falla en trampas de condensado previas | K35: Sí | L35: No | N35: MT_B8RUT7HE_APSA370_20111702 | O35: Pendiente | Q35: =IF($F35<>"Numérico","",IF($P35="","Sin dato",IF(AND(OR(NOT(ISNUMBER($I35)),$P35>=$I35),OR(NOT(ISNUMBER($J35)),$P35<=$J35)),"Dentro de rango","Fuera de rango")))
A36: 4.2.1 | B36: 4. Línea de muestreo y acondicionamiento | C36: 4.2 Sonda y líneas de muestreo | D36: Integridad de la línea de teflón | E36: Estrangulamientos, fisuras o fugas físicas en la tubería de muestreo | F36: OK / No OK | H36: Tubería de teflón de 6 mm OD libre de dobleces agudos y bien ajustada | K36: Sí | L36: Sí | N36: P-ST-030-MAN OPER APSA 370 V2 | O36: Pendiente | Q36: =IF($F36<>"Numérico","",IF($P36="","Sin dato",IF(AND(OR(NOT(ISNUMBER($I36)),$P36>=$I36),OR(NOT(ISNUMBER($J36)),$P36<=$J36)),"Dentro de rango","Fuera de rango")))
A37: 4.2.2 | B37: 4. Línea de muestreo y acondicionamiento | C37: 4.2 Sonda y líneas de muestreo | D37: Protección térmica de las líneas | E37: Aislamiento de las tuberías de muestra frente a corrientes de aire frío directo | F37: OK / No OK | H37: No deben estar expuestas a corrientes de aire frío (p. ej. aire acondicionado) para evitar condensados | K37: Sí | L37: Sí | N37: P-ST-030-MAN OPER APSA 370 V2 | O37: Pendiente | Q37: =IF($F37<>"Numérico","",IF($P37="","Sin dato",IF(AND(OR(NOT(ISNUMBER($I37)),$P37>=$I37),OR(NOT(ISNUMBER($J37)),$P37<=$J37)),"Dentro de rango","Fuera de rango")))
A38: 4.3.1 | B38: 4. Línea de muestreo y acondicionamiento | C38: 4.3 Conexiones neumáticas traseras | D38: Férulas (Sleeve) en puertos de entrada y salida | E38: Presencia y estado del casquillo de soporte en las uniones de teflón posteriores | F38: Presente / Ausente | H38: Los casquillos de 6 mm deben estar presentes en las uniones traseras para garantizar el sellado | K38: Sí | L38: Sí | M38: Sleeve SO2001-6 (3030021777) | N38: MT_829WE09R_APSA370_221102 | O38: Pendiente | Q38: =IF($F38<>"Numérico","",IF($P38="","Sin dato",IF(AND(OR(NOT(ISNUMBER($I38)),$P38>=$I38),OR(NOT(ISNUMBER($J38)),$P38<=$J38)),"Dentro de rango","Fuera de rango")))
A39: 4.3.2 | B39: 4. Línea de muestreo y acondicionamiento | C39: 4.3 Conexiones neumáticas traseras | D39: Tuercas de compresión PVDF (Cap Nut) en puertos traseros | E39: Presencia y torque de las tuercas plásticas para tuberías de teflón de 6 mm | F39: Presente / Ausente | H39: Deben estar completas y debidamente ajustadas para evitar fugas neumáticas | K39: Sí | L39: Sí | M39: Cap Nut S020020-6PVDF (3030021779) | N39: MT_829WE09R_APSA370_221102 | O39: Pendiente | Q39: =IF($F39<>"Numérico","",IF($P39="","Sin dato",IF(AND(OR(NOT(ISNUMBER($I39)),$P39>=$I39),OR(NOT(ISNUMBER($J39)),$P39<=$J39)),"Dentro de rango","Fuera de rango")))
A40: 5.1.1 | B40: 5. Sistema neumático | C40: 5.1 Bomba y caudal de muestra | D40: Caudal de gas de muestra (SAMPLE) | E40: Flujo del gas de muestra a través de la celda óptica medido por el analizador | F40: Numérico | G40: L/min | H40: El flujo debe mantenerse estable dentro de los límites de diseño neumático | I40: 0.6 | J40: 1 | K40: Sí | L40: No | M40: Unidad de bomba (3014059491) | N40: P-ST-030-MAN OPER APSA 370 V2 | O40: Pendiente | Q40: =IF($F40<>"Numérico","",IF($P40="","Sin dato",IF(AND(OR(NOT(ISNUMBER($I40)),$P40>=$I40),OR(NOT(ISNUMBER($J40)),$P40<=$J40)),"Dentro de rango","Fuera de rango"))) -> Sin dato
A41: 5.1.2 | B41: 5. Sistema neumático | C41: 5.1 Bomba y caudal de muestra | D41: Presión de succión de la bomba (PUMP) | E41: Vacío de arrastre absoluto generado en la succión interna del analizador | F41: Numérico | G41: kPa | H41: Debe mantenerse por debajo del umbral de alarma; la alarma PRE1 se activa a 65 kPa o más | J41: 65 | K41: Sí | L41: No | M41: Diafragma EPDM (3011026485) | N41: P-ST-030-MAN OPER APSA 370 V2 | O41: Pendiente | Q41: =IF($F41<>"Numérico","",IF($P41="","Sin dato",IF(AND(OR(NOT(ISNUMBER($I41)),$P41>=$I41),OR(NOT(ISNUMBER($J41)),$P41<=$J41)),"Dentro de rango","Fuera de rango"))) -> Sin dato
A42: 5.1.3 | B42: 5. Sistema neumático | C42: 5.1 Bomba y caudal de muestra | D42: Integridad del diafragma de la bomba | E42: Estado de las membranas de diafragma de doble cabezal de la bomba | F42: OK / No OK | H42: Sin fisuras, grietas ni roturas; el desgaste causa baja de vacío, ruidos y disminución de flujo | K42: Sí | L42: Sí | M42: Diaphragm Assy (3011026485 / 3200602390) | N42: MT_829WE09R_APSA370_21041205 | O42: Pendiente | Q42: =IF($F42<>"Numérico","",IF($P42="","Sin dato",IF(AND(OR(NOT(ISNUMBER($I42)),$P42>=$I42),OR(NOT(ISNUMBER($J42)),$P42<=$J42)),"Dentro de rango","Fuera de rango")))
...

Sheet APOA-370 (O3)
A1: FASE 1 — INSPECCIÓN FÍSICA DEL EQUIPO · APOA-370 (O3) (catálogo + captura)
A3: Cliente: | D3: Principio de medición: | E3: Absorción UV no dispersiva (NDUV)
A4: NIT: | D4: Fecha de inspección:
A5: Equipo / Modelo: | B5: Analizador de ozono HORIBA APOA-370 | D5: Técnico responsable:
A6: Número de serie: | D6: N.º de informe (MT):
A8: ID | B8: Nivel macro (N1) | C8: Subnivel (N2) | D8: Ítem (N3) | E8: Qué se verifica | F8: Tipo de dato | G8: Unidad | H8: Criterio de aceptación | I8: Límite inferior | J8: Límite superior | K8: Obligatorio | L8: Evidencia fotográfica requerida | M8: Repuesto / parte asociada | N8: Fuente documental | O8: Resultado | P8: Valor medido | Q8: Verificación de rango | R8: Foto adjunta | S8: Observación
A9: 1.1.1 | B9: 1. Verificación funcional inicial | C9: 1.1 Encendido y LEDs frontales | D9: LED de alimentación (panel frontal) | E9: Color del indicador de encendido tras activar el interruptor de alimentación | F9: OK / No OK | H9: Debe iluminarse en verde en operación normal y en rojo bajo condición de alarma | K9: Sí | L9: Sí | N9: P-ST-001-MAN OPER APOA 370 V2 | O9: Pendiente | Q9: =IF($F9<>"Numérico","",IF($P9="","Sin dato",IF(AND(OR(NOT(ISNUMBER($I9)),$P9>=$I9),OR(NOT(ISNUMBER($J9)),$P9<=$J9)),"Dentro de rango","Fuera de rango")))
A10: 1.1.2 | B10: 1. Verificación funcional inicial | C10: 1.1 Encendido y LEDs frontales | D10: Inicialización del visualizador táctil | E10: Que la pantalla de medición MEAS. se visualice automáticamente al encender | F10: Sí/No | H10: La pantalla MEAS. se despliega correctamente y el equipo inicia las mediciones | K10: Sí | L10: No | N10: P-ST-001-MAN OPER APOA 370 V2 | O10: Pendiente | Q10: =IF($F10<>"Numérico","",IF($P10="","Sin dato",IF(AND(OR(NOT(ISNUMBER($I10)),$P10>=$I10),OR(NOT(ISNUMBER($J10)),$P10<=$J10)),"Dentro de rango","Fuera de rango")))
A11: 1.1.3 | B11: 1. Verificación funcional inicial | C11: 1.1 Encendido y LEDs frontales | D11: Verificación de la pantalla de inicio | E11: Que la pantalla muestre el logotipo oficial HORIBA u OEM antes del modo MEAS. | F11: OK / No OK | H11: El logotipo oficial se despliega correctamente, sin distorsión ni corrupción gráfica | K11: Sí | L11: Sí | N11: GZ0000117746B SM E APXX-370 (Service Manual) | O11: Pendiente | Q11: =IF($F11<>"Numérico","",IF($P11="","Sin dato",IF(AND(OR(NOT(ISNUMBER($I11)),$P11>=$I11),OR(NOT(ISNUMBER($J11)),$P11<=$J11)),"Dentro de rango","Fuera de rango")))
A12: 1.2.1 | B12: 1. Verificación funcional inicial | C12: 1.2 Autodiagnóstico | D12: Iconos y botones de alarma en pantalla | E12: Presencia de iconos de alarma en la barra superior o del botón ALARM en la esquina inferior derecha | F12: Sí/No | H12: Ausencia completa de alarmas activas; el LED del panel frontal debe estar verde fijo | K12: Sí | L12: No | N12: P-ST-001-MAN OPER APOA 370 V2 | O12: Pendiente | Q12: =IF($F12<>"Numérico","",IF($P12="","Sin dato",IF(AND(OR(NOT(ISNUMBER($I12)),$P12>=$I12),OR(NOT(ISNUMBER($J12)),$P12<=$J12)),"Dentro de rango","Fuera de rango")))
A13: 1.2.2 | B13: 1. Verificación funcional inicial | C13: 1.2 Autodiagnóstico | D13: Verificación de intensidad inicial de la lámpara | E13: Que el autodiagnóstico no reporte error de intensidad de la lámpara UV al inicio | F13: OK / No OK | H13: El equipo no presenta error de intensidad LAMP durante la fase de inicialización | K13: Sí | L13: Sí | M13: UV Lamp (3014036635 / 9022009700) | N13: P-ST-001-MAN OPER APOA 370 V2 | O13: Pendiente | Q13: =IF($F13<>"Numérico","",IF($P13="","Sin dato",IF(AND(OR(NOT(ISNUMBER($I13)),$P13>=$I13),OR(NOT(ISNUMBER($J13)),$P13<=$J13)),"Dentro de rango","Fuera de rango")))
A14: 1.2.3 | B14: 1. Verificación funcional inicial | C14: 1.2 Autodiagnóstico | D14: Modulación de flujo cruzado a 1 Hz | E14: Sonido regular de conmutación de la electroválvula de flujo cruzado | F14: OK / No OK | H14: Sonido rítmico y constante de conmutación de la válvula a una frecuencia de 1 Hz | K14: Sí | L14: Sí | M14: Solenoid Valve SV-2 (3014034340 / 9022009300) | N14: P-ST-001-MAN OPER APOA 370 V2 | O14: Pendiente | Q14: =IF($F14<>"Numérico","",IF($P14="","Sin dato",IF(AND(OR(NOT(ISNUMBER($I14)),$P14>=$I14),OR(NOT(ISNUMBER($J14)),$P14<=$J14)),"Dentro de rango","Fuera de rango")))
A15: 1.3.1 | B15: 1. Verificación funcional inicial | C15: 1.3 Estabilización térmica | D15: Calentamiento inicial (warm-up) | E15: Tiempo de espera tras el encendido antes de calibrar o medir | F15: Numérico | G15: horas | H15: Mínimo 3 h para la estabilización térmica y óptica de celda, catalizador y lámpara. Límite superior PENDIENTE DE VALIDAR | I15: 3 | K15: Sí | L15: No | N15: P-ST-001-MAN OPER APOA 370 V2 | O15: Pendiente | Q15: =IF($F15<>"Numérico","",IF($P15="","Sin dato",IF(AND(OR(NOT(ISNUMBER($I15)),$P15>=$I15),OR(NOT(ISNUMBER($J15)),$P15<=$J15)),"Dentro de rango","Fuera de rango"))) -> Sin dato
A16: 2.1.1 | B16: 2. Identificación y trazabilidad | C16: 2.1 Placas e identificación física | D16: Número de serie del analizador | E16: Que el número de serie de la etiqueta trasera y del chasis coincida con la hoja de vida | F16: Texto | H16: Serial legible y coincidente con los registros del sistema de monitoreo | K16: Sí | L16: No | N16: MT_1T71YRV7_APOA370_220221 | O16: Pendiente | Q16: =IF($F16<>"Numérico","",IF($P16="","Sin dato",IF(AND(OR(NOT(ISNUMBER($I16)),$P16>=$I16),OR(NOT(ISNUMBER($J16)),$P16<=$J16)),"Dentro de rango","Fuera de rango")))
A17: 2.2.1 | B17: 2. Identificación y trazabilidad | C17: 2.2 Trazabilidad de software | D17: Versión del firmware (ROM) | E17: Versión del firmware cargado en la CPU, en el menú de sistema | F17: Texto | H17: La versión estándar debe mostrar P1000878001 más el número de parche | K17: Sí | L17: No | N17: GZ0000117746B SM E APXX-370 (Service Manual) | O17: Pendiente | Q17: =IF($F17<>"Numérico","",IF($P17="","Sin dato",IF(AND(OR(NOT(ISNUMBER($I17)),$P17>=$I17),OR(NOT(ISNUMBER($J17)),$P17<=$J17)),"Dentro de rango","Fuera de rango")))
A18: 2.2.2 | B18: 2. Identificación y trazabilidad | C18: 2.2 Trazabilidad de software | D18: Código HGS del sistema | E18: Confirmación del número HGS del analizador y del sistema mediante verificación HTS | F18: Texto | H18: HGS correcto y correspondiente al tipo de analizador instalado | K18: Sí | L18: No | N18: 1 - LCD design change AP EN | O18: Pendiente | Q18: =IF($F18<>"Numérico","",IF($P18="","Sin dato",IF(AND(OR(NOT(ISNUMBER($I18)),$P18>=$I18),OR(NOT(ISNUMBER($J18)),$P18<=$J18)),"Dentro de rango","Fuera de rango")))
A19: 2.3.1 | B19: 2. Identificación y trazabilidad | C19: 2.3 Etiquetas de seguridad | D19: Etiqueta de advertencia de alta temperatura | E19: Presencia y legibilidad de la etiqueta HOT COMPONENT en la carcasa de la bomba y del catalizador | F19: Presente / Ausente | H19: Etiqueta presente y visible, advirtiendo peligro de quemadura por superficies calientes | K19: Sí | L19: Sí | N19: APOA-370 Maintenance manual | O19: Pendiente | Q19: =IF($F19<>"Numérico","",IF($P19="","Sin dato",IF(AND(OR(NOT(ISNUMBER($I19)),$P19>=$I19),OR(NOT(ISNUMBER($J19)),$P19<=$J19)),"Dentro de rango","Fuera de rango")))
A20: 2.3.2 | B20: 2. Identificación y trazabilidad | C20: 2.3 Etiquetas de seguridad | D20: Etiqueta de advertencia de lámpara UV y mercurio | E20: Presencia y legibilidad de la etiqueta Contains Mercury cerca de la celda de medida | F20: Presente / Ausente | H20: Etiqueta de peligro de radiación UV y presencia de mercurio perfectamente legible | K20: Sí | L20: Sí | N20: P-ST-002-MAN MTTO APOA370 V2 | O20: Pendiente | Q20: =IF($F20<>"Numérico","",IF($P20="","Sin dato",IF(AND(OR(NOT(ISNUMBER($I20)),$P20>=$I20),OR(NOT(ISNUMBER($J20)),$P20<=$J20)),"Dentro de rango","Fuera de rango")))
A21: 2.4.1 | B21: 2. Identificación y trazabilidad | C21: 2.4 Identificación de puertos | D21: Marcación de conectores en el panel trasero | E21: Marcas serigrafiadas de SAMPLE INLET, CAL GAS INLET y EXHAUST | F21: OK / No OK | H21: Etiquetas e identificadores de puertos limpios, legibles y sin daños físicos | K21: Sí | L21: Sí | N21: P-ST-001-MAN OPER APOA 370 V2 | O21: Pendiente | Q21: =IF($F21<>"Numérico","",IF($P21="","Sin dato",IF(AND(OR(NOT(ISNUMBER($I21)),$P21>=$I21),OR(NOT(ISNUMBER($J21)),$P21<=$J21)),"Dentro de rango","Fuera de rango")))
A22: 3.1.1 | B22: 3. Estado de calibración | C22: 3.1 Coeficientes de calibración | D22: Coeficiente de calibración de cero (User Zero) | E22: Valor de corrimiento de cero almacenado en la pantalla CAL. | F22: Numérico | G22: counts | H22: El valor del ajuste de cero debe encontrarse dentro del rango permitido | I22: -3500 | J22: 3500 | K22: Sí | L22: No | N22: P-ST-001-MAN OPER APOA 370 V2 | O22: Pendiente | Q22: =IF($F22<>"Numérico","",IF($P22="","Sin dato",IF(AND(OR(NOT(ISNUMBER($I22)),$P22>=$I22),OR(NOT(ISNUMBER($J22)),$P22<=$J22)),"Dentro de rango","Fuera de rango"))) -> Sin dato
A23: 3.1.2 | B23: 3. Estado de calibración | C23: 3.1 Coeficientes de calibración | D23: Coeficiente de calibración de span (User Span) | E23: Factor de multiplicación de calibración de span en la pantalla CAL. | F23: Numérico | H23: El coeficiente de ganancia de span debe encontrarse dentro de los límites de aceptación | I23: 0.5 | J23: 2 | K23: Sí | L23: No | N23: P-ST-001-MAN OPER APOA 370 V2 | O23: Pendiente | Q23: =IF($F23<>"Numérico","",IF($P23="","Sin dato",IF(AND(OR(NOT(ISNUMBER($I23)),$P23>=$I23),OR(NOT(ISNUMBER($J23)),$P23<=$J23)),"Dentro de rango","Fuera de rango"))) -> Sin dato
A24: 3.2.1 | B24: 3. Estado de calibración | C24: 3.2 Límites de calibración de fábrica | D24: Coeficiente de cero de fábrica (Factory Zero) | E24: Coeficiente de cero de fábrica en la pantalla F.CAL de mantenimiento de servicio | F24: Numérico | G24: counts | H24: El coeficiente F.ZERO debe estar dentro del rango de conteo del ADC | I24: -32768 | J24: 32767 | K24: Sí | L24: No | N24: GZ0000117746B SM E APXX-370 (Service Manual) | O24: Pendiente | Q24: =IF($F24<>"Numérico","",IF($P24="","Sin dato",IF(AND(OR(NOT(ISNUMBER($I24)),$P24>=$I24),OR(NOT(ISNUMBER($J24)),$P24<=$J24)),"Dentro de rango","Fuera de rango"))) -> Sin dato
A25: 3.2.2 | B25: 3. Estado de calibración | C25: 3.2 Límites de calibración de fábrica | D25: Coeficiente de span de fábrica (Factory Span) | E25: Factor de multiplicación de fábrica en el menú de servicio | F25: Numérico | H25: El coeficiente F.SPAN estándar debe estar comprendido entre 0,7 y 1,3 | I25: 0.7 | J25: 1.3 | K25: Sí | L25: No | N25: GZ0000117746B SM E APXX-370 (Service Manual) | O25: Pendiente | Q25: =IF($F25<>"Numérico","",IF($P25="","Sin dato",IF(AND(OR(NOT(ISNUMBER($I25)),$P25>=$I25),OR(NOT(ISNUMBER($J25)),$P25<=$J25)),"Dentro de rango","Fuera de rango"))) -> Sin dato
A26: 3.3.1 | B26: 3. Estado de calibración | C26: 3.3 Suministro de gases patrón | D26: Presión de entrega de gas cero y de span | E26: Presión de introducción del gas cero o del gas patrón | F26: Numérico | G26: Pa | H26: La presión de suministro debe controlarse de forma estable respecto a la atmósfera | I26: -500 | J26: 500 | K26: Sí | L26: No | N26: P-ST-001-MAN OPER APOA 370 V2 | O26: Pendiente | Q26: =IF($F26<>"Numérico","",IF($P26="","Sin dato",IF(AND(OR(NOT(ISNUMBER($I26)),$P26>=$I26),OR(NOT(ISNUMBER($J26)),$P26<=$J26)),"Dentro de rango","Fuera de rango"))) -> Sin dato
A27: 3.3.2 | B27: 3. Estado de calibración | C27: 3.3 Suministro de gases patrón | D27: Lámpara del ozonizador interno (opcional) | E27: Si está equipado con generador de ozono interno, que la lámpara encienda al activar el span | F27: OK / No OK | H27: Lámpara del ozonizador interno operativa y estable, sin parpadeos anómalos. Repuesto PENDIENTE DE VALIDAR | K27: Sí | L27: Sí | N27: P-ST-001-MAN OPER APOA 370 V2 | O27: Pendiente | Q27: =IF($F27<>"Numérico","",IF($P27="","Sin dato",IF(AND(OR(NOT(ISNUMBER($I27)),$P27>=$I27),OR(NOT(ISNUMBER($J27)),$P27<=$J27)),"Dentro de rango","Fuera de rango")))
A28: 3.4.1 | B28: 3. Estado de calibración | C28: 3.4 Estabilidad de lectura | D28: Estabilidad de la lectura de cero | E28: Lectura de concentración con aire cero, para comprobar ruido y deriva | F28: Numérico | G28: ppb | H28: Lectura del analizador estabilizada cerca de cero | I28: -1 | J28: 1 | K28: Sí | L28: No | N28: P-ST-001-MAN OPER APOA 370 V2 | O28: Pendiente | Q28: =IF($F28<>"Numérico","",IF($P28="","Sin dato",IF(AND(OR(NOT(ISNUMBER($I28)),$P28>=$I28),OR(NOT(ISNUMBER($J28)),$P28<=$J28)),"Dentro de rango","Fuera de rango"))) -> Sin dato
A29: 4.1.1 | B29: 4. Línea de muestreo y acondicionamiento | C29: 4.1 Portafiltros frontal | D29: Filtro de partículas de teflón (PA-10L) | E29: Grado de suciedad, cambio de color o humedad del filtro de partículas | F29: OK / No OK | H29: El elemento filtrante debe estar limpio, de color blanco y completamente seco (cambio cada 2 semanas) | K29: Sí | L29: Sí | M29: Filter Element PA-10L (3200043947 / 9022003900) | N29: P-ST-002-MAN MTTO APOA370 V2 | O29: Pendiente | Q29: =IF($F29<>"Numérico","",IF($P29="","Sin dato",IF(AND(OR(NOT(ISNUMBER($I29)),$P29>=$I29),OR(NOT(ISNUMBER($J29)),$P29<=$J29)),"Dentro de rango","Fuera de rango")))
A30: 4.1.2 | B30: 4. Línea de muestreo y acondicionamiento | C30: 4.1 Portafiltros frontal | D30: Junta tórica del portafiltros (O-Ring G50) | E30: Estado físico, deformación o grietas de la junta tórica del vaso del portafiltros | F30: OK / No OK | H30: Junta elástica, sin aplastamientos ni resequedad, asegurando un sellado hermético | K30: Sí | L30: Sí | M30: O-Ring JISB2401 G50 (3014059499 / 9022005900) | N30: P-ST-002-MAN MTTO APOA370 V2 | O30: Pendiente | Q30: =IF($F30<>"Numérico","",IF($P30="","Sin dato",IF(AND(OR(NOT(ISNUMBER($I30)),$P30>=$I30),OR(NOT(ISNUMBER($J30)),$P30<=$J30)),"Dentro de rango","Fuera de rango")))
A31: 4.1.3 | B31: 4. Línea de muestreo y acondicionamiento | C31: 4.1 Portafiltros frontal | D31: Empaque de teflón del filtro | E31: Estado de la junta plana interna de asiento del filtro | F31: OK / No OK | H31: Empaque plano sin deformaciones, cortes ni residuos de suciedad. Repuesto PENDIENTE DE VALIDAR | K31: Sí | L31: Sí | N31: P-ST-002-MAN MTTO APOA370 V2 | O31: Pendiente | Q31: =IF($F31<>"Numérico","",IF($P31="","Sin dato",IF(AND(OR(NOT(ISNUMBER($I31)),$P31>=$I31),OR(NOT(ISNUMBER($J31)),$P31<=$J31)),"Dentro de rango","Fuera de rango")))
A32: 4.2.1 | B32: 4. Línea de muestreo y acondicionamiento | C32: 4.2 Humedad en la línea | D32: Humedad o condensación en el portafiltros | E32: Presencia de agua libre en las mangueras neumáticas y en el vaso del portafiltros | F32: OK / No OK | H32: Líneas neumáticas completamente secas y libres de goteo o acumulación de agua | K32: Sí | L32: Sí | N32: MT_H53MWBT2_APOA370_250428 | O32: Pendiente | Q32: =IF($F32<>"Numérico","",IF($P32="","Sin dato",IF(AND(OR(NOT(ISNUMBER($I32)),$P32>=$I32),OR(NOT(ISNUMBER($J32)),$P32<=$J32)),"Dentro de rango","Fuera de rango")))
A33: 4.3.1 | B33: 4. Línea de muestreo y acondicionamiento | C33: 4.3 Conexiones neumáticas | D33: Férula de teflón (Sleeve / SO2001-6) | E33: Presencia y estado de la férula de teflón de 6 mm en los acoples INLET y EXHAUST | F33: Presente / Ausente | H33: Férulas presentes en todas las uniones de mangueras de 6 mm, para evitar fugas | K33: Sí | L33: Sí | M33: Sleeve SO2001-6 (3030021777) | N33: MT_1T71YRV7_APOA370_220221 | O33: Pendiente | Q33: =IF($F33<>"Numérico","",IF($P33="","Sin dato",IF(AND(OR(NOT(ISNUMBER($I33)),$P33>=$I33),OR(NOT(ISNUMBER($J33)),$P33<=$J33)),"Dentro de rango","Fuera de rango")))
A34: 4.3.2 | B34: 4. Línea de muestreo y acondicionamiento | C34: 4.3 Conexiones neumáticas | D34: Tuerca de sellado PVDF (Cap Nut) | E34: Estado físico de la tuerca plástica de acople rápido PVDF en la entrada | F34: OK / No OK | H34: Tuerca sin fisuras, roscas barridas ni deformaciones que afecten el sellado | K34: Sí | L34: Sí | M34: Panel mount union SO21521-6 (3030021548) | N34: MT_4UFVB4RH_APOA370_221031 | O34: Pendiente | Q34: =IF($F34<>"Numérico","",IF($P34="","Sin dato",IF(AND(OR(NOT(ISNUMBER($I34)),$P34>=$I34),OR(NOT(ISNUMBER($J34)),$P34<=$J34)),"Dentro de rango","Fuera de rango")))
A35: 4.3.3 | B35: 4. Línea de muestreo y acondicionamiento | C35: 4.3 Conexiones neumáticas | D35: Racor de entrada frontal de muestra | E35: Estado del acople pasamuros frontal de entrada de muestra | F35: OK / No OK | H35: Racor completo, sin grietas, mellas ni fugas | K35: Sí | L35: Sí | M35: Panel mount union SO21521-6 (3030021548) | N35: MT_WKKT596N_APOA370_220225 | O35: Pendiente | Q35: =IF($F35<>"Numérico","",IF($P35="","Sin dato",IF(AND(OR(NOT(ISNUMBER($I35)),$P35>=$I35),OR(NOT(ISNUMBER($J35)),$P35<=$J35)),"Dentro de rango","Fuera de rango")))
