Workbook

Sheet Instrucciones
A1: INSPECCIÓN FÍSICA DEL EQUIPO — GRIMM EDM180 (C/D)
A2: Prototipo de estructura jerárquica en Excel · Ambientalia — Servicio Técnico · v3
A4: Novedades de la v3
A5: 1) Se incorporaron 15 ítems nuevos hallados al revisar 'Service Training NEW [Version 0.8]',
A6: el documento más extenso del notebook y el único con diagrama interno detallado. El hallazgo
A7: más relevante: el equipo tiene una Bomba de muestra (Sample Pump) física, distinta de la bomba
A8: de vacío/secado (antes la única bomba registrada) — ver ítem 3.1.5. Los demás 14 ítems cubren
A9: soporte del tubo, paso de techo, calefactor opcional del cabezal, trampa de agua, depósito de
A10: compensación, presostatos, válvula y filtro del ciclo self-test, tarjeta driver del láser y tarjeta
A11: LED, filtros CQ (selftest/vacío), el procedimiento de reinicio del contador de filtro a 60.000 µg,
A12: puertos RS-232 y las etiquetas físicas del equipo (ítem 1.2.4).
A13: 2) Catálogo e Inspección se fusionaron en UNA sola hoja/tabla (antes eran dos hojas enlazadas
... A53: no uno publicado por GRIMM; se deja igual, pero sin fuente oficial confirmada.
A54: ID | B54: Ítem | C54: Resultado | D54: Valor medido | E54: Foto | F54: Observación
A55: 3.1.1 | B55: Flujo de la bomba de secado | C55: Requiere reemplazo | D55: 2.45 | E55: Sí | F55: Flujo cercano al límite de reemplazo; desgaste en el empaque del pistón.

Sheet Listas
A1: Resultado | B1: Foto adjunta | C1: Obligatorio
A2: Conforme | B2: Sí | C2: Sí
A3: No conforme | B3: No | C3: No
A4: Requiere reemplazo | B4: No aplica
A5: No aplica
A6: Pendiente

Sheet Inspección
A1: FASE 1 — INSPECCIÓN FÍSICA DEL EQUIPO (catálogo + captura)
A3: Cliente: | D3: Serie del espectrómetro:
A4: NIT: | D4: Fecha de inspección:
A5: Equipo / Modelo: | B5: Monitor de partículas GRIMM EDM180 | D5: Técnico responsable:
A6: Número de serie: | D6: N.º de informe (MT):
A8: ID | B8: Nivel macro (N1) | C8: Subnivel (N2) | D8: Ítem (N3) | E8: Qué se verifica | F8: Tipo de dato | G8: Unidad | H8: Criterio de aceptación | I8: Límite inferior | J8: Límite superior | K8: Obligatorio | L8: Evidencia fotográfica requerida | M8: Repuesto / parte asociada | N8: Informe de referencia | O8: Resultado | P8: Valor medido | Q8: Verificación de rango | R8: Foto adjunta | S8: Observación
A9: 1.1.1 | B9: 1. Verificación funcional inicial | C9: 1.1 Encendido y autodiagnóstico | D9: Ciclo self-test | E9: El equipo enciende y supera el ciclo self test | F9: Sí/No | H9: Debe superar el self test | K9: Sí | L9: No | N9: MT_18A12051_260811 | O9: Pendiente | Q9: =IF($F9<>"Numérico","",IF($P9="","Sin dato",IF(AND(OR(NOT(ISNUMBER($I9)),$P9>=$I9),OR(NOT(ISNUMBER($J9)),$P9<=$J9)),"Dentro de rango","Fuera de rango")))
A10: 1.1.2 | B10: 1. Verificación funcional inicial | C10: 1.1 Encendido y autodiagnóstico | D10: Inicio de medición | E10: El equipo comienza a medir tras el self test | F10: Sí/No | H10: Debe iniciar medición | K10: Sí | L10: No | N10: MT_18A12051_260811 | O10: Pendiente | Q10: =IF($F10<>"Numérico","",IF($P10="","Sin dato",IF(AND(OR(NOT(ISNUMBER($I10)),$P10>=$I10),OR(NOT(ISNUMBER($J10)),$P10<=$J10)),"Dentro de rango","Fuera de rango")))
A11: 1.1.3 | B11: 1. Verificación funcional inicial | C11: 1.1 Encendido y autodiagnóstico | D11: Alarmas activas | E11: Alarmas o avisos en pantalla al arranque (p. ej. alerta "Dryer") | F11: Texto | H11: Sin alarmas activas | K11: Sí | L11: Sí | N11: MT_18A21062_260227 | O11: Pendiente | Q11: =IF($F11<>"Numérico","",IF($P11="","Sin dato",IF(AND(OR(NOT(ISNUMBER($I11)),$P11>=$I11),OR(NOT(ISNUMBER($J11)),$P11<=$J11)),"Dentro de rango","Fuera de rango")))
A12: 1.2.1 | B12: 1. Verificación funcional inicial | C12: 1.2 Identificación y trazabilidad | D12: Serial del monitor | E12: El serial del monitor coincide con la placa y con la orden de servicio | F12: Sí/No | H12: Debe coincidir | K12: Sí | L12: Sí | N12: MT_18A19035_260727 | O12: Pendiente | Q12: =IF($F12<>"Numérico","",IF($P12="","Sin dato",IF(AND(OR(NOT(ISNUMBER($I12)),$P12>=$I12),OR(NOT(ISNUMBER($J12)),$P12<=$J12)),"Dentro de rango","Fuera de rango")))
A13: 1.2.2 | B13: 1. Verificación funcional inicial | C13: 1.2 Identificación y trazabilidad | D13: Serial del espectrómetro | E13: El espectrómetro instalado corresponde al del equipo (no de otro monitor) | F13: Sí/No | H13: Debe corresponder | K13: Sí | L13: Sí | N13: MT_18A19035_260727 | O13: Pendiente | Q13: =IF($F13<>"Numérico","",IF($P13="","Sin dato",IF(AND(OR(NOT(ISNUMBER($I13)),$P13>=$I13),OR(NOT(ISNUMBER($J13)),$P13<=$J13)),"Dentro de rango","Fuera de rango")))
A14: 1.2.3 | B14: 1. Verificación funcional inicial | C14: 1.2 Identificación y trazabilidad | D14: Accesorios recibidos | E14: Inventario de accesorios: tubo de muestra, cabezal TSP, sensor T/HR, cables | F14: Texto | H14: Inventario completo | K14: Sí | L14: Sí | N14: MT_18A19035_260727 | O14: Pendiente | Q14: =IF($F14<>"Numérico","",IF($P14="","Sin dato",IF(AND(OR(NOT(ISNUMBER($I14)),$P14>=$I14),OR(NOT(ISNUMBER($J14)),$P14<=$J14)),"Dentro de rango","Fuera de rango")))
A15: 1.2.4 | B15: 1. Verificación funcional inicial | C15: 1.2 Identificación y trazabilidad | D15: Etiquetas físicas (Type Label / etiqueta de calibración) | E15: Presencia y legibilidad de la etiqueta de tipo y de la etiqueta de calibración vigente | F15: OK / No OK | H15: Presentes y legibles | K15: No | L15: Sí | N15: Service Training NEW v0.8 | O15: Pendiente | Q15: =IF($F15<>"Numérico","",IF($P15="","Sin dato",IF(AND(OR(NOT(ISNUMBER($I15)),$P15>=$I15),OR(NOT(ISNUMBER($J15)),$P15<=$J15)),"Dentro de rango","Fuera de rango")))
A16: 1.3.1 | B16: 1. Verificación funcional inicial | C16: 1.3 Estado de calibración | D16: Vigencia de calibración en Torre GRIMM | E16: Fecha de la última calibración en torre patrón | F16: Fecha | H16: Vigencia máxima 12 meses | K16: Sí | L16: No | M16: AMB-STCALENVIRO-01 | N16: MT_18A12051_260811 | O16: Pendiente | Q16: =IF($F16<>"Numérico","",IF($P16="","Sin dato",IF(AND(OR(NOT(ISNUMBER($I16)),$P16>=$I16),OR(NOT(ISNUMBER($J16)),$P16<=$J16)),"Dentro de rango","Fuera de rango")))
A17: 1.3.2 | B17: 1. Verificación funcional inicial | C17: 1.3 Estado de calibración | D17: Certificado disponible | E17: Existe certificado de la última calibración | F17: Sí/No | H17: Debe existir | K17: No | L17: No | N17: MT_18A19035_260727 | O17: Pendiente | Q17: =IF($F17<>"Numérico","",IF($P17="","Sin dato",IF(AND(OR(NOT(ISNUMBER($I17)),$P17>=$I17),OR(NOT(ISNUMBER($J17)),$P17<=$J17)),"Dentro de rango","Fuera de rango")))
A18: 1.3.3 | B18: 1. Verificación funcional inicial | C18: 1.3 Estado de calibración | D18: Desviación relativa de masa (verificación con aire ambiente) | E18: Diferencia entre el candidato y el espectrómetro de referencia al verificar con aire ambiente tras la calibración en torre | F18: Numérico | G18: % o µg/m³ | H18: Criterio de fábrica: ±3% o ±2µg/m³. Criterio para cliente/campo: ±5% o ±2µg/m³ (correo GRIMM 25-nov-2021) | I18: -5 | J18: 5 | K18: Sí | L18: Sí | N18: Correo EDM180C Calibration desviación (nov-2021) | O18: Pendiente | Q18: =IF($F18<>"Numérico","",IF($P18="","Sin dato",IF(AND(OR(NOT(ISNUMBER($I18)),$P18>=$I18),OR(NOT(ISNUMBER($J18)),$P18<=$J18)),"Dentro de rango","Fuera de rango"))) -> Sin dato
A19: 2.1.1 | B19: 2. Línea de muestreo y cabezal | C19: 2.1 Cabezal TSP | D19: Estado físico del cabezal | E19: Golpes, deformación, corrosión del cabezal TSP | F19: OK / No OK | H19: Sin deformación ni corrosión | K19: Sí | L19: Sí | N19: MT_18A20087_260512 | O19: Pendiente | Q19: =IF($F19<>"Numérico","",IF($P19="","Sin dato",IF(AND(OR(NOT(ISNUMBER($I19)),$P19>=$I19),OR(NOT(ISNUMBER($J19)),$P19<=$J19)),"Dentro de rango","Fuera de rango")))
A20: 2.1.2 | B20: 2. Línea de muestreo y cabezal | C20: 2.1 Cabezal TSP | D20: Tornillo de seguridad del cabezal | E20: Presencia y estado del tornillo de seguridad del cabezal TSP | F20: Presente / Ausente | H20: Debe estar presente | K20: Sí | L20: Sí | M20: M02M2X4D912A4 | N20: MT_18A20087_260512 | O20: Pendiente | Q20: =IF($F20<>"Numérico","",IF($P20="","Sin dato",IF(AND(OR(NOT(ISNUMBER($I20)),$P20>=$I20),OR(NOT(ISNUMBER($J20)),$P20<=$J20)),"Dentro de rango","Fuera de rango")))
A21: 2.1.3 | B21: 2. Línea de muestreo y cabezal | C21: 2.1 Cabezal TSP | D21: Limpieza interna del cabezal | E21: Acumulación de material particulado en el interior del cabezal | F21: OK / No OK | H21: Libre de acumulación | K21: Sí | L21: No | N21: MT_18A20087_260512 | O21: Pendiente | Q21: =IF($F21<>"Numérico","",IF($P21="","Sin dato",IF(AND(OR(NOT(ISNUMBER($I21)),$P21>=$I21),OR(NOT(ISNUMBER($J21)),$P21<=$J21)),"Dentro de rango","Fuera de rango")))
A22: 2.1.4 | B22: 2. Línea de muestreo y cabezal | C22: 2.1 Cabezal TSP | D22: Malla fly-mesh de la sonda | E22: Estado de la malla de protección (fly-mesh) del cabezal de muestreo | F22: OK / No OK | H22: Sin obstrucción ni rotura | K22: No | L22: No | N22: Service Training.pdf | O22: Pendiente | Q22: =IF($F22<>"Numérico","",IF($P22="","Sin dato",IF(AND(OR(NOT(ISNUMBER($I22)),$P22>=$I22),OR(NOT(ISNUMBER($J22)),$P22<=$J22)),"Dentro de rango","Fuera de rango")))
A23: 2.1.5 | B23: 2. Línea de muestreo y cabezal | C23: 2.1 Cabezal TSP | D23: Calefactor opcional del cabezal (head heater) | E23: Presencia y funcionamiento del calefactor opcional del cabezal de muestreo, en los equipos que lo incorporen | F23: Presente / Ausente | H23: Aplica solo si el equipo trae la opción instalada; de ser así, debe operar sin falla | K23: No | L23: No | N23: Service Training NEW v0.8 | O23: Pendiente | Q23: =IF($F23<>"Numérico","",IF($P23="","Sin dato",IF(AND(OR(NOT(ISNUMBER($I23)),$P23>=$I23),OR(NOT(ISNUMBER($J23)),$P23<=$J23)),"Dentro de rango","Fuera de rango")))
A24: 2.2.1 | B24: 2. Línea de muestreo y cabezal | C24: 2.2 Tubo de muestra (1.5 m) | D24: Rectitud del tubo | E24: Deformación o torcedura del tubo de muestra | F24: OK / No OK | H24: Sin deformación mecánica | K24: Sí | L24: Sí | M24: GR-TI-01 | N24: MT_18A12051_260811 | O24: Pendiente | Q24: =IF($F24<>"Numérico","",IF($P24="","Sin dato",IF(AND(OR(NOT(ISNUMBER($I24)),$P24>=$I24),OR(NOT(ISNUMBER($J24)),$P24<=$J24)),"Dentro de rango","Fuera de rango")))
A25: 2.2.2 | B25: 2. Línea de muestreo y cabezal | C25: 2.2 Tubo de muestra (1.5 m) | D25: Fugas internas | E25: Prueba de estanqueidad del tubo de muestra | F25: OK / No OK | H25: Sin fugas | K25: Sí | L25: No | N25: MT_18A12051_260811 | O25: Pendiente | Q25: =IF($F25<>"Numérico","",IF($P25="","Sin dato",IF(AND(OR(NOT(ISNUMBER($I25)),$P25>=$I25),OR(NOT(ISNUMBER($J25)),$P25<=$J25)),"Dentro de rango","Fuera de rango")))
A26: 2.2.3 | B26: 2. Línea de muestreo y cabezal | C26: 2.2 Tubo de muestra (1.5 m) | D26: Estructura interna de bronce | E26: Integridad de la estructura de bronce y su base respecto a las líneas neumáticas | F26: OK / No OK | H26: Base unida a las líneas neumáticas | K26: Sí | L26: Sí | M26: GR-TI-01 | N26: MT_18A12051_260811 | O26: Pendiente | Q26: =IF($F26<>"Numérico","",IF($P26="","Sin dato",IF(AND(OR(NOT(ISNUMBER($I26)),$P26>=$I26),OR(NOT(ISNUMBER($J26)),$P26<=$J26)),"Dentro de rango","Fuera de rango")))
A27: 2.2.4 | B27: 2. Línea de muestreo y cabezal | C27: 2.2 Tubo de muestra (1.5 m) | D27: Tornillería del tubo | E27: Deformación mecánica de la tornillería del tubo de muestra | F27: OK / No OK | H27: Sin deformación | K27: Sí | L27: Sí | M27: 4037489 / M00M3X3D913A2 | N27: MT_18A20087_260512 | O27: Pendiente | Q27: =IF($F27<>"Numérico","",IF($P27="","Sin dato",IF(AND(OR(NOT(ISNUMBER($I27)),$P27>=$I27),OR(NOT(ISNUMBER($J27)),$P27<=$J27)),"Dentro de rango","Fuera de rango")))
A28: 2.2.5 | B28: 2. Línea de muestreo y cabezal | C28: 2.2 Tubo de muestra (1.5 m) | D28: O-Ring de la boquilla de entrada | E28: Desgaste de la junta tórica interna de la boquilla de ingreso de muestreo | F28: OK / No OK | H28: Sin desgaste que genere fuga | K28: Sí | L28: Sí | M28: C0004x1 | N28: MT_18A21062_260227 | O28: Pendiente | Q28: =IF($F28<>"Numérico","",IF($P28="","Sin dato",IF(AND(OR(NOT(ISNUMBER($I28)),$P28>=$I28),OR(NOT(ISNUMBER($J28)),$P28<=$J28)),"Dentro de rango","Fuera de rango")))
A29: 2.2.6 | B29: 2. Línea de muestreo y cabezal | C29: 2.2 Tubo de muestra (1.5 m) | D29: Soporte del tubo (Sample Pipe Holder) y tornillo de fijación | E29: Presencia y estado del soporte que fija el tubo de muestra y de su tornillo de fijación | F29: OK / No OK | H29: Presente y firme | K29: Sí | L29: Sí | N29: Service Training NEW v0.8 | O29: Pendiente | Q29: =IF($F29<>"Numérico","",IF($P29="","Sin dato",IF(AND(OR(NOT(ISNUMBER($I29)),$P29>=$I29),OR(NOT(ISNUMBER($J29)),$P29<=$J29)),"Dentro de rango","Fuera de rango")))
A30: 2.3.1 | B30: 2. Línea de muestreo y cabezal | C30: 2.3 Protección contra intemperie | D30: Rain protector / deflector | E30: Presencia e integridad del protector de lluvia del tubo de muestra | F30: Presente / Ausente | H30: Presente y sin roturas | K30: Sí | L30: Sí | M30: 4019827 | N30: MT_18A20087_260512 | O30: Pendiente | Q30: =IF($F30<>"Numérico","",IF($P30="","Sin dato",IF(AND(OR(NOT(ISNUMBER($I30)),$P30>=$I30),OR(NOT(ISNUMBER($J30)),$P30<=$J30)),"Dentro de rango","Fuera de rango")))
A31: 2.3.2 | B31: 2. Línea de muestreo y cabezal | C31: 2.3 Protección contra intemperie | D31: Acople de sellado tubo–shelter | E31: Acople de protección para filtrado de agua hacia el shelter | F31: OK / No OK | H31: Acople original instalado | K31: Sí | L31: Sí | N31: MT_18A20087_260512 | O31: Pendiente | Q31: =IF($F31<>"Numérico","",IF($P31="","Sin dato",IF(AND(OR(NOT(ISNUMBER($I31)),$P31>=$I31),OR(NOT(ISNUMBER($J31)),$P31<=$J31)),"Dentro de rango","Fuera de rango")))
A32: 2.3.3 | B32: 2. Línea de muestreo y cabezal | C32: 2.3 Protección contra intemperie | D32: Sellados provisionales | E32: Uso de cinta u otros sellos provisionales en la conexión | F32: Sí/No | H32: No debe haber sellos provisionales | K32: Sí | L32: Sí | N32: MT_18A20087_260512 | O32: Pendiente | Q32: =IF($F32<>"Numérico","",IF($P32="","Sin dato",IF(AND(OR(NOT(ISNUMBER($I32)),$P32>=$I32),OR(NOT(ISNUMBER($J32)),$P32<=$J32)),"Dentro de rango","Fuera de rango")))
A33: 2.3.4 | B33: 2. Línea de muestreo y cabezal | C33: 2.3 Protección contra intemperie | D33: Paso de techo (roof lead through) | E33: Estado del pasamuros/paso de techo por donde ingresa el tubo de muestra a la caseta | F33: OK / No OK | H33: Sellado y sin daño | K33: Sí | L33: Sí | N33: Service Training NEW v0.8 | O33: Pendiente | Q33: =IF($F33<>"Numérico","",IF($P33="","Sin dato",IF(AND(OR(NOT(ISNUMBER($I33)),$P33>=$I33),OR(NOT(ISNUMBER($J33)),$P33<=$J33)),"Dentro de rango","Fuera de rango")))
A34: 2.4.1 | B34: 2. Línea de muestreo y cabezal | C34: 2.4 Secador Nafion y drenaje | D34: Estado del Nafion | E34: Deterioro del secador Nafion integrado | F34: OK / No OK | H34: Sin deterioro | K34: Sí | L34: Sí | N34: MT_18A12051_260811 | O34: Pendiente | Q34: =IF($F34<>"Numérico","",IF($P34="","Sin dato",IF(AND(OR(NOT(ISNUMBER($I34)),$P34>=$I34),OR(NOT(ISNUMBER($J34)),$P34<=$J34)),"Dentro de rango","Fuera de rango")))
A35: 2.4.2 | B35: 2. Línea de muestreo y cabezal | C35: 2.4 Secador Nafion y drenaje | D35: Water drain | E35: Drenaje de agua despejado y operativo | F35: OK / No OK | H35: Despejado | K35: Sí | L35: No | N35: MT_18A12051_260811 | O35: Pendiente | Q35: =IF($F35<>"Numérico","",IF($P35="","Sin dato",IF(AND(OR(NOT(ISNUMBER($I35)),$P35>=$I35),OR(NOT(ISNUMBER($J35)),$P35<=$J35)),"Dentro de rango","Fuera de rango")))
A36: 2.4.3 | B36: 2. Línea de muestreo y cabezal | C36: 2.4 Secador Nafion y drenaje | D36: Mangueras de la línea neumática | E36: Roturas, fisuras o endurecimiento de las mangueras | F36: OK / No OK | H36: Sin roturas | K36: Sí | L36: Sí | N36: MT_18A12051_260811 | O36: Pendiente | Q36: =IF($F36<>"Numérico","",IF($P36="","Sin dato",IF(AND(OR(NOT(ISNUMBER($I36)),$P36>=$I36),OR(NOT(ISNUMBER($J36)),$P36<=$J36)),"Dentro de rango","Fuera de rango")))
A37: 2.4.4 | B37: 2. Línea de muestreo y cabezal | C37: 2.4 Secador Nafion y drenaje | D37: Prueba de luz "First Aid" (obstrucción del tubo) | E37: Pasar una luz LED por el tubo de muestra: la luz debe atravesarlo completo, sin bloqueos ni residuos visibles; limpiar con aire comprimido si hay obstrucción | F37: OK / No OK | H37: La luz debe pasar completa por el tubo | K37: No | L37: Sí | N37: Correo GRIMM EDM180 TEST FIRST AID 18A12046 | O37: Pendiente | Q37: =IF($F37<>"Numérico","",IF($P37="","Sin dato",IF(AND(OR(NOT(ISNUMBER($I37)),$P37>=$I37),OR(NOT(ISNUMBER($J37)),$P37<=$J37)),"Dentro de rango","Fuera de rango")))
A38: 2.4.5 | B38: 2. Línea de muestreo y cabezal | C38: 2.4 Secador Nafion y drenaje | D38: Trampa de agua y racor de salida (water trap / condensate outlet) | E38: Integridad física de la trampa de agua y del racor de salida de condensado, como componentes distintos del secador Nafion | F38: OK / No OK | H38: Sin daño ni fugas | K38: No | L38: No | N38: Service Training NEW v0.8 | O38: Pendiente | Q38: =IF($F38<>"Numérico","",IF($P38="","Sin dato",IF(AND(OR(NOT(ISNUMBER($I38)),$P38>=$I38),OR(NOT(ISNUMBER($J38)),$P38<=$J38)),"Dentro de rango","Fuera de rango")))
A39: 3.1.1 | B39: 3. Sistema neumático y etapa de secado | C39: 3.1 Bombas (vacío/secado y muestra) | D39: Flujo de la bomba de secado (vacuum flow) | E39: Medición del flujo de la bomba de secado en la salida de condensado (condensate outlet) | F39: Numérico | G39: L/min | H39: Manual: ~1,8 L/min (válvula de aguja, equipos antiguos) o 2,0-2,2 L/min (tobera crítica, desde 2004). Service Training: 2,0 ±0,1 L/min. 2,45 L/min se registró en campo como valor cercano al límite de reemplazo | I39: 1.8 | J39: 2.3 | K39: Sí | L39: No | M39: 1205273 | N39: SER-MAN DUST MONITOR 180 / Service Training.pdf / MT_18A24064_260609 | O39: Requiere reemplazo | P39: 2.45 | Q39: =IF($F39<>"Numérico","",IF($P39="","Sin dato",IF(AND(OR(NOT(ISNUMBER($I39)),$P39>=$I39),OR(NOT(ISNUMBER($J39)),$P39<=$J39)),"Dentro de rango","Fuera de rango"))) -> Fuera de rango | R39: Sí | S39: EJEMPLO — Flujo en el límite superior del rango; desgaste en el empaque del pistón. Borrar antes de usar el formato.
A40: 3.1.2 | B40: 3. Sistema neumático y etapa de secado | C40: 3.1 Bombas (vacío/secado y muestra) | D40: Estado del kit de la bomba (bomba de vacío/secado) | E40: Desgaste de los componentes internos del kit de la bomba de vacío | F40: OK / No OK | H40: Sin desgaste significativo | K40: Sí | L40: Sí | M40: 1205273 | N40: MT_18A20087_260512 | O40: Pendiente | Q40: =IF($F40<>"Numérico","",IF($P40="","Sin dato",IF(AND(OR(NOT(ISNUMBER($I40)),$P40>=$I40),OR(NOT(ISNUMBER($J40)),$P40<=$J40)),"Dentro de rango","Fuera de rango")))
A41: 3.1.3 | B41: 3. Sistema neumático y etapa de secado | C41: 3.1 Bombas (vacío/secado y muestra) | D41: Empaque del pistón (sealing sleeve) de la bomba de vacío/secado | E41: Desgaste del empaque del pistón de la bomba de secado | F41: OK / No OK | H41: Sin desgaste | K41: Sí | L41: Sí | M41: 1204480 | N41: MT_18A24064_260609 | O41: Pendiente | Q41: =IF($F41<>"Numérico","",IF($P41="","Sin dato",IF(AND(OR(NOT(ISNUMBER($I41)),$P41>=$I41),OR(NOT(ISNUMBER($J41)),$P41<=$J41)),"Dentro de rango","Fuera de rango")))
A42: 3.1.4 | B42: 3. Sistema neumático y etapa de secado | C42: 3.1 Bombas (vacío/secado y muestra) | D42: Ruido y vibración de la bomba de vacío/secado | E42: Ruido o vibración anómala de la bomba | F42: OK / No OK | H42: Sin ruido anómalo | K42: No | L42: No | N42: Derivado | O42: Pendiente | Q42: =IF($F42<>"Numérico","",IF($P42="","Sin dato",IF(AND(OR(NOT(ISNUMBER($I42)),$P42>=$I42),OR(NOT(ISNUMBER($J42)),$P42<=$J42)),"Dentro de rango","Fuera de rango")))
...

Sheet Resumen
A1: RESUMEN DE CONFORMIDAD POR NIVEL MACRO
A2: Calculado automáticamente sobre la hoja Inspección.
A4: Nivel macro (N1) | B4: Ítems | C4: Conforme | D4: No conforme | E4: Requiere reemplazo | F4: No aplica | G4: Pendiente | H4: % conformidad | I4: Fuera de rango
A5: 1. Verificación funcional inicial | B5: =COUNTIF(Inspección!$B$9:$B$111,$A5) -> 10 | C5: =COUNTIFS(Inspección!$B$9:$B$111,$A5,Inspección!$O$9:$O$111,"Conforme") -> 0 | D5: =COUNTIFS(Inspección!$B$9:$B$111,$A5,Inspección!$O$9:$O$111,"No conforme") -> 0 | E5: =COUNTIFS(Inspección!$B$9:$B$111,$A5,Inspección!$O$9:$O$111,"Requiere reemplazo") -> 0 | F5: =COUNTIFS(Inspección!$B$9:$B$111,$A5,Inspección!$O$9:$O$111,"No aplica") -> 0 | G5: =COUNTIFS(Inspección!$B$9:$B$111,$A5,Inspección!$O$9:$O$111,"Pendiente") -> 10 | H5: =IFERROR($C5/($B5-$F5-$G5),"") | I5: =COUNTIFS(Inspección!$B$9:$B$111,$A5,Inspección!$Q$9:$Q$111,"Fuera de rango") -> 0
A6: 2. Línea de muestreo y cabezal | B6: =COUNTIF(Inspección!$B$9:$B$111,$A6) -> 20 | C6: =COUNTIFS(Inspección!$B$9:$B$111,$A6,Inspección!$O$9:$O$111,"Conforme") -> 0 | D6: =COUNTIFS(Inspección!$B$9:$B$111,$A6,Inspección!$O$9:$O$111,"No conforme") -> 0 | E6: =COUNTIFS(Inspección!$B$9:$B$111,$A6,Inspección!$O$9:$O$111,"Requiere reemplazo") -> 0 | F6: =COUNTIFS(Inspección!$B$9:$B$111,$A6,Inspección!$O$9:$O$111,"No aplica") -> 0 | G6: =COUNTIFS(Inspección!$B$9:$B$111,$A6,Inspección!$O$9:$O$111,"Pendiente") -> 20 | H6: =IFERROR($C6/($B6-$F6-$G6),"") | I6: =COUNTIFS(Inspección!$B$9:$B$111,$A6,Inspección!$Q$9:$Q$111,"Fuera de rango") -> 0
A7: 3. Sistema neumático y etapa de secado | B7: =COUNTIF(Inspección!$B$9:$B$111,$A7) -> 18 | C7: =COUNTIFS(Inspección!$B$9:$B$111,$A7,Inspección!$O$9:$O$111,"Conforme") -> 0 | D7: =COUNTIFS(Inspección!$B$9:$B$111,$A7,Inspección!$O$9:$O$111,"No conforme") -> 0 | E7: =COUNTIFS(Inspección!$B$9:$B$111,$A7,Inspección!$O$9:$O$111,"Requiere reemplazo") -> 1 | F7: =COUNTIFS(Inspección!$B$9:$B$111,$A7,Inspección!$O$9:$O$111,"No aplica") -> 0 | G7: =COUNTIFS(Inspección!$B$9:$B$111,$A7,Inspección!$O$9:$O$111,"Pendiente") -> 17 | H7: =IFERROR($C7/($B7-$F7-$G7),"") -> 0 | I7: =COUNTIFS(Inspección!$B$9:$B$111,$A7,Inspección!$Q$9:$Q$111,"Fuera de rango") -> 1
A8: 4. Espectrómetro: cámara de medida y óptica | B8: =COUNTIF(Inspección!$B$9:$B$111,$A8) -> 14 | C8: =COUNTIFS(Inspección!$B$9:$B$111,$A8,Inspección!$O$9:$O$111,"Conforme") -> 0 | D8: =COUNTIFS(Inspección!$B$9:$B$111,$A8,Inspección!$O$9:$O$111,"No conforme") -> 0 | E8: =COUNTIFS(Inspección!$B$9:$B$111,$A8,Inspección!$O$9:$O$111,"Requiere reemplazo") -> 0 | F8: =COUNTIFS(Inspección!$B$9:$B$111,$A8,Inspección!$O$9:$O$111,"No aplica") -> 0 | G8: =COUNTIFS(Inspección!$B$9:$B$111,$A8,Inspección!$O$9:$O$111,"Pendiente") -> 14 | H8: =IFERROR($C8/($B8-$F8-$G8),"") | I8: =COUNTIFS(Inspección!$B$9:$B$111,$A8,Inspección!$Q$9:$Q$111,"Fuera de rango") -> 0
A9: 5. Electrónica y control | B9: =COUNTIF(Inspección!$B$9:$B$111,$A9) -> 15 | C9: =COUNTIFS(Inspección!$B$9:$B$111,$A9,Inspección!$O$9:$O$111,"Conforme") -> 0 | D9: =COUNTIFS(Inspección!$B$9:$B$111,$A9,Inspección!$O$9:$O$111,"No conforme") -> 0 | E9: =COUNTIFS(Inspección!$B$9:$B$111,$A9,Inspección!$O$9:$O$111,"Requiere reemplazo") -> 0 | F9: =COUNTIFS(Inspección!$B$9:$B$111,$A9,Inspección!$O$9:$O$111,"No aplica") -> 0 | G9: =COUNTIFS(Inspección!$B$9:$B$111,$A9,Inspección!$O$9:$O$111,"Pendiente") -> 15 | H9: =IFERROR($C9/($B9-$F9-$G9),"") | I9: =COUNTIFS(Inspección!$B$9:$B$111,$A9,Inspección!$Q$9:$Q$111,"Fuera de rango") -> 0
A10: 6. Filtros y consumibles | B10: =COUNTIF(Inspección!$B$9:$B$111,$A10) -> 9 | C10: =COUNTIFS(Inspección!$B$9:$B$111,$A10,Inspección!$O$9:$O$111,"Conforme") -> 0 | D10: =COUNTIFS(Inspección!$B$9:$B$111,$A10,Inspección!$O$9:$O$111,"No conforme") -> 0 | E10: =COUNTIFS(Inspección!$B$9:$B$111,$A10,Inspección!$O$9:$O$111,"Requiere reemplazo") -> 0 | F10: =COUNTIFS(Inspección!$B$9:$B$111,$A10,Inspección!$O$9:$O$111,"No aplica") -> 0 | G10: =COUNTIFS(Inspección!$B$9:$B$111,$A10,Inspección!$O$9:$O$111,"Pendiente") -> 9 | H10: =IFERROR($C10/($B10-$F10-$G10),"") | I10: =COUNTIFS(Inspección!$B$9:$B$111,$A10,Inspección!$Q$9:$Q$111,"Fuera de rango") -> 0
A11: 7. Sensores auxiliares | B11: =COUNTIF(Inspección!$B$9:$B$111,$A11) -> 6 | C11: =COUNTIFS(Inspección!$B$9:$B$111,$A11,Inspección!$O$9:$O$111,"Conforme") -> 0 | D11: =COUNTIFS(Inspección!$B$9:$B$111,$A11,Inspección!$O$9:$O$111,"No conforme") -> 0 | E11: =COUNTIFS(Inspección!$B$9:$B$111,$A11,Inspección!$O$9:$O$111,"Requiere reemplazo") -> 0 | F11: =COUNTIFS(Inspección!$B$9:$B$111,$A11,Inspección!$O$9:$O$111,"No aplica") -> 0 | G11: =COUNTIFS(Inspección!$B$9:$B$111,$A11,Inspección!$O$9:$O$111,"Pendiente") -> 6 | H11: =IFERROR($C11/($B11-$F11-$G11),"") | I11: =COUNTIFS(Inspección!$B$9:$B$111,$A11,Inspección!$Q$9:$Q$111,"Fuera de rango") -> 0
A12: 8. Gabinete, montaje e instalación | B12: =COUNTIF(Inspección!$B$9:$B$111,$A12) -> 11 | C12: =COUNTIFS(Inspección!$B$9:$B$111,$A12,Inspección!$O$9:$O$111,"Conforme") -> 0 | D12: =COUNTIFS(Inspección!$B$9:$B$111,$A12,Inspección!$O$9:$O$111,"No conforme") -> 0 | E12: =COUNTIFS(Inspección!$B$9:$B$111,$A12,Inspección!$O$9:$O$111,"Requiere reemplazo") -> 0 | F12: =COUNTIFS(Inspección!$B$9:$B$111,$A12,Inspección!$O$9:$O$111,"No aplica") -> 0 | G12: =COUNTIFS(Inspección!$B$9:$B$111,$A12,Inspección!$O$9:$O$111,"Pendiente") -> 11 | H12: =IFERROR($C12/($B12-$F12-$G12),"") | I12: =COUNTIFS(Inspección!$B$9:$B$111,$A12,Inspección!$Q$9:$Q$111,"Fuera de rango") -> 0
A13: TOTAL | B13: =SUM(B5:B12) -> 103 | C13: =SUM(C5:C12) -> 0 | D13: =SUM(D5:D12) -> 0 | E13: =SUM(E5:E12) -> 1 | F13: =SUM(F5:F12) -> 0 | G13: =SUM(G5:G12) -> 102 | H13: =IFERROR($C13/($B13-$F13-$G13),"") -> 0 | I13: =SUM(I5:I12) -> 1
A15: % conformidad = Conforme / (Ítems − No aplica − Pendiente).
A16: Nota: con la hoja recién abierta todos los ítems están en «Pendiente», por lo que el % queda vacío hasta diligenciar.
