Workbook

Sheet Instrucciones
A1: INSPECCIÓN FÍSICA DEL EQUIPO — GRIMM EDM180 (C/D)
A2: Prototipo de estructura jerárquica en Excel · Ambientalia — Servicio Técnico
A4: Origen de la estructura
A5: Los niveles macro, subniveles e ítems se derivaron de los informes de mantenimiento (MT) del
A6: notebook «ST Grimm EDM180» en NotebookLM (223 fuentes). Los informes actuales son narrativos:
A7: no existe hoy una lista de chequeo formalizada, por lo que esta jerarquía es una propuesta
A8: construida a partir de los hallazgos que se repiten en ellos.
A10: Cómo está organizado el libro
A11: Catálogo Maestro de la jerarquía: 8 niveles macro (N1), 24 subniveles (N2) y 69 ítems (N3).
A12: Es la única fuente de verdad. Para añadir o quitar ítems se edita AQUÍ.
A13: Inspección Hoja de captura de una visita. Las columnas B–J y P se traen del Catálogo con
A14: fórmulas; el técnico solo diligencia las celdas en amarillo.
... A24: Ejemplo de diligenciamiento
A25: ID | B25: Ítem | C25: Resultado | D25: Valor medido | E25: Foto | F25: Observación
A26: 3.1.1 | B26: Flujo de la bomba de secado | C26: Requiere reemplazo | D26: 2.45 | E26: Sí | F26: Flujo cercano al límite de reemplazo; desgaste en el empaque del pistón.
A27: Los únicos criterios numéricos explícitos en los informes son: ganancias de los canales F y G
A28: entre -2 % y +5 % respecto al espectrómetro de referencia, y el flujo de la bomba de secado, donde
A29: 2,45 L/min se registró como valor cercano al límite de reemplazo. El resto de límites inferiores y
A30: superiores del Catálogo están marcados como PENDIENTE DE VALIDAR: deben confirmarse contra el
A31: manual de servicio GRIMM antes de usar el formato en campo.

Sheet Listas
A1: Resultado | B1: Foto adjunta | C1: Obligatorio
A2: Conforme | B2: Sí | C2: Sí
A3: No conforme | B3: No | C3: No
A4: Requiere reemplazo | B4: No aplica
A5: No aplica
A6: Pendiente

Sheet Catálogo
A1: CATÁLOGO MAESTRO DE INSPECCIÓN FÍSICA — GRIMM EDM180
A2: Fuente: informes MT del notebook «ST Grimm EDM180» (NotebookLM). Los límites sin criterio explícito en los informes están marcados como PENDIENTE DE VALIDAR.
A4: ID | B4: Nivel macro (N1) | C4: Subnivel (N2) | D4: Ítem (N3) | E4: Qué se verifica | F4: Tipo de dato | G4: Unidad | H4: Criterio de aceptación | I4: Límite inferior | J4: Límite superior | K4: Obligatorio | L4: Evidencia fotográfica | M4: Repuesto / parte asociada | N4: Informe de referencia
A5: 1.1.1 | B5: 1. Verificación funcional inicial | C5: 1.1 Encendido y autodiagnóstico | D5: Ciclo self-test | E5: El equipo enciende y supera el ciclo self test | F5: Sí/No | H5: Debe superar el self test | K5: Sí | L5: No | N5: MT_18A12051_260811
A6: 1.1.2 | B6: 1. Verificación funcional inicial | C6: 1.1 Encendido y autodiagnóstico | D6: Inicio de medición | E6: El equipo comienza a medir tras el self test | F6: Sí/No | H6: Debe iniciar medición | K6: Sí | L6: No | N6: MT_18A12051_260811
A7: 1.1.3 | B7: 1. Verificación funcional inicial | C7: 1.1 Encendido y autodiagnóstico | D7: Alarmas activas | E7: Alarmas o avisos en pantalla al arranque (p. ej. alerta "Dryer") | F7: Texto | H7: Sin alarmas activas | K7: Sí | L7: Sí | N7: MT_18A21062_260227
A8: 1.2.1 | B8: 1. Verificación funcional inicial | C8: 1.2 Identificación y trazabilidad | D8: Serial del monitor | E8: El serial del monitor coincide con la placa y con la orden de servicio | F8: Sí/No | H8: Debe coincidir | K8: Sí | L8: Sí | N8: MT_18A19035_260727
A9: 1.2.2 | B9: 1. Verificación funcional inicial | C9: 1.2 Identificación y trazabilidad | D9: Serial del espectrómetro | E9: El espectrómetro instalado corresponde al del equipo (no de otro monitor) | F9: Sí/No | H9: Debe corresponder | K9: Sí | L9: Sí | N9: MT_18A19035_260727
A10: 1.2.3 | B10: 1. Verificación funcional inicial | C10: 1.2 Identificación y trazabilidad | D10: Accesorios recibidos | E10: Inventario de accesorios: tubo de muestra, cabezal TSP, sensor T/HR, cables | F10: Texto | H10: Inventario completo | K10: Sí | L10: Sí | N10: MT_18A19035_260727
A11: 1.3.1 | B11: 1. Verificación funcional inicial | C11: 1.3 Estado de calibración | D11: Vigencia de calibración en Torre GRIMM | E11: Fecha de la última calibración en torre patrón | F11: Fecha | H11: Vigencia máxima 12 meses | K11: Sí | L11: No | M11: AMB-STCALENVIRO-01 | N11: MT_18A12051_260811
A12: 1.3.2 | B12: 1. Verificación funcional inicial | C12: 1.3 Estado de calibración | D12: Certificado disponible | E12: Existe certificado de la última calibración | F12: Sí/No | H12: Debe existir | K12: No | L12: No | N12: MT_18A19035_260727
A13: 2.1.1 | B13: 2. Línea de muestreo y cabezal | C13: 2.1 Cabezal TSP | D13: Estado físico del cabezal | E13: Golpes, deformación, corrosión del cabezal TSP | F13: OK / No OK | H13: Sin deformación ni corrosión | K13: Sí | L13: Sí | N13: MT_18A20087_260512
A14: 2.1.2 | B14: 2. Línea de muestreo y cabezal | C14: 2.1 Cabezal TSP | D14: Tornillo de seguridad del cabezal | E14: Presencia y estado del tornillo de seguridad del cabezal TSP | F14: Presente / Ausente | H14: Debe estar presente | K14: Sí | L14: Sí | M14: M02M2X4D912A4 | N14: MT_18A20087_260512
A15: 2.1.3 | B15: 2. Línea de muestreo y cabezal | C15: 2.1 Cabezal TSP | D15: Limpieza interna del cabezal | E15: Acumulación de material particulado en el interior del cabezal | F15: OK / No OK | H15: Libre de acumulación | K15: Sí | L15: No | N15: MT_18A20087_260512
A16: 2.2.1 | B16: 2. Línea de muestreo y cabezal | C16: 2.2 Tubo de muestra (1.5 m) | D16: Rectitud del tubo | E16: Deformación o torcedura del tubo de muestra | F16: OK / No OK | H16: Sin deformación mecánica | K16: Sí | L16: Sí | M16: GR-TI-01 | N16: MT_18A12051_260811
A17: 2.2.2 | B17: 2. Línea de muestreo y cabezal | C17: 2.2 Tubo de muestra (1.5 m) | D17: Fugas internas | E17: Prueba de estanqueidad del tubo de muestra | F17: OK / No OK | H17: Sin fugas | K17: Sí | L17: No | N17: MT_18A12051_260811
A18: 2.2.3 | B18: 2. Línea de muestreo y cabezal | C18: 2.2 Tubo de muestra (1.5 m) | D18: Estructura interna de bronce | E18: Integridad de la estructura de bronce y su base respecto a las líneas neumáticas | F18: OK / No OK | H18: Base unida a las líneas neumáticas | K18: Sí | L18: Sí | M18: GR-TI-01 | N18: MT_18A12051_260811
A19: 2.2.4 | B19: 2. Línea de muestreo y cabezal | C19: 2.2 Tubo de muestra (1.5 m) | D19: Tornillería del tubo | E19: Deformación mecánica de la tornillería del tubo de muestra | F19: OK / No OK | H19: Sin deformación | K19: Sí | L19: Sí | M19: 4037489 / M00M3X3D913A2 | N19: MT_18A20087_260512
A20: 2.2.5 | B20: 2. Línea de muestreo y cabezal | C20: 2.2 Tubo de muestra (1.5 m) | D20: O-Ring de la boquilla de entrada | E20: Desgaste de la junta tórica interna de la boquilla de ingreso de muestreo | F20: OK / No OK | H20: Sin desgaste que genere fuga | K20: Sí | L20: Sí | M20: C0004x1 | N20: MT_18A21062_260227
A21: 2.3.1 | B21: 2. Línea de muestreo y cabezal | C21: 2.3 Protección contra intemperie | D21: Rain protector / deflector | E21: Presencia e integridad del protector de lluvia del tubo de muestra | F21: Presente / Ausente | H21: Presente y sin roturas | K21: Sí | L21: Sí | M21: 4019827 | N21: MT_18A20087_260512
A22: 2.3.2 | B22: 2. Línea de muestreo y cabezal | C22: 2.3 Protección contra intemperie | D22: Acople de sellado tubo–shelter | E22: Acople de protección para filtrado de agua hacia el shelter | F22: OK / No OK | H22: Acople original instalado | K22: Sí | L22: Sí | N22: MT_18A20087_260512
A23: 2.3.3 | B23: 2. Línea de muestreo y cabezal | C23: 2.3 Protección contra intemperie | D23: Sellados provisionales | E23: Uso de cinta u otros sellos provisionales en la conexión | F23: Sí/No | H23: No debe haber sellos provisionales | K23: Sí | L23: Sí | N23: MT_18A20087_260512
A24: 2.4.1 | B24: 2. Línea de muestreo y cabezal | C24: 2.4 Secador Nafion y drenaje | D24: Estado del Nafion | E24: Deterioro del secador Nafion integrado | F24: OK / No OK | H24: Sin deterioro | K24: Sí | L24: Sí | N24: MT_18A12051_260811
A25: 2.4.2 | B25: 2. Línea de muestreo y cabezal | C25: 2.4 Secador Nafion y drenaje | D25: Water drain | E25: Drenaje de agua despejado y operativo | F25: OK / No OK | H25: Despejado | K25: Sí | L25: No | N25: MT_18A12051_260811
A26: 2.4.3 | B26: 2. Línea de muestreo y cabezal | C26: 2.4 Secador Nafion y drenaje | D26: Mangueras de la línea neumática | E26: Roturas, fisuras o endurecimiento de las mangueras | F26: OK / No OK | H26: Sin roturas | K26: Sí | L26: Sí | N26: MT_18A12051_260811
A27: 3.1.1 | B27: 3. Sistema neumático y etapa de secado | C27: 3.1 Bomba de vacío / secado | D27: Flujo de la bomba de secado | E27: Medición del flujo de la bomba de secado | F27: Numérico | G27: L/min | H27: Dentro del rango del fabricante; 2,45 L/min es el valor registrado como cercano al límite de reemplazo | I27: 1.8 | J27: 2.45 | K27: Sí | L27: No | M27: 1205273 | N27: MT_18A24064_260609
A28: 3.1.2 | B28: 3. Sistema neumático y etapa de secado | C28: 3.1 Bomba de vacío / secado | D28: Estado del kit de la bomba | E28: Desgaste de los componentes internos del kit de la bomba de vacío | F28: OK / No OK | H28: Sin desgaste significativo | K28: Sí | L28: Sí | M28: 1205273 | N28: MT_18A20087_260512
A29: 3.1.3 | B29: 3. Sistema neumático y etapa de secado | C29: 3.1 Bomba de vacío / secado | D29: Empaque del pistón (sealing sleeve) | E29: Desgaste del empaque del pistón de la bomba de secado | F29: OK / No OK | H29: Sin desgaste | K29: Sí | L29: Sí | M29: 1204480 | N29: MT_18A24064_260609
A30: 3.1.4 | B30: 3. Sistema neumático y etapa de secado | C30: 3.1 Bomba de vacío / secado | D30: Ruido y vibración | E30: Ruido o vibración anómala de la bomba | F30: OK / No OK | H30: Sin ruido anómalo | K30: No | L30: No | N30: Derivado
A31: 3.2.1 | B31: 3. Sistema neumático y etapa de secado | C31: 3.2 Instrumentación de presión | D31: Manómetro de vacío | E31: El manómetro entrega lectura y no presenta falla mecánica | F31: OK / No OK | H31: Debe entregar lectura | K31: Sí | L31: Sí | M31: 1201007 | N31: MT_18A19035_260727
A32: 3.2.2 | B32: 3. Sistema neumático y etapa de secado | C32: 3.2 Instrumentación de presión | D32: Presión negativa de succión | E32: Presión negativa generada por la etapa de secado | F32: Numérico | G32: bar | H32: Dentro del rango del fabricante | I32: PENDIENTE DE VALIDAR | J32: PENDIENTE DE VALIDAR | K32: Sí | L32: No | N32: MT_18A19035_260727
A33: 3.3.1 | B33: 3. Sistema neumático y etapa de secado | C33: 3.3 Estanqueidad | D33: Prueba de fugas del circuito | E33: Prueba de fugas del circuito neumático completo | F33: OK / No OK | H33: Sin fugas | K33: Sí | L33: No | N33: MT_18A18033_260108
A34: 3.3.2 | B34: 3. Sistema neumático y etapa de secado | C34: 3.3 Estanqueidad | D34: O-Rings y conectores del holder | E34: Estado de los O-Rings y conectores del cabezal de muestra (holder) | F34: OK / No OK | H34: Sin desgaste | K34: Sí | L34: Sí | M34: C0004x1.2N70 / 1201011 | N34: MT_18A12051_260811
A35: 3.3.3 | B35: 3. Sistema neumático y etapa de secado | C35: 3.3 Estanqueidad | D35: Alerta "Dryer" | E35: Alerta activa de la etapa de secado en el equipo | F35: Sí/No | H35: No debe estar activa | K35: Sí | L35: Sí | N35: MT_18A21062_260227
A36: 4.1.1 | B36: 4. Espectrómetro: cámara de medida y óptica | C36: 4.1 Estado del recinto | D36: Humedad / condensación | E36: Presencia de humedad o condensación en el gabinete del espectrómetro | F36: Sí/No | H36: Ausencia de humedad | K36: Sí | L36: Sí | N36: MT_18A18033_260108
A37: 4.1.2 | B37: 4. Espectrómetro: cámara de medida y óptica | C37: 4.1 Estado del recinto | D37: Óxido y corrosión | E37: Óxido o corrosión en componentes internos por ingreso de humedad | F37: Sí/No | H37: Sin óxido ni corrosión | K37: Sí | L37: Sí | N37: MT_18A18033_260108
A38: 4.1.3 | B38: 4. Espectrómetro: cámara de medida y óptica | C38: 4.1 Estado del recinto | D38: Limpieza de la cámara de medida | E38: Necesidad de limpieza integral de la cámara de medición | F38: OK / No OK | H38: Cámara limpia | K38: Sí | L38: Sí | N38: MT_18A24064_260609
A39: 4.2.1 | B39: 4. Espectrómetro: cámara de medida y óptica | C39: 4.2 Componentes ópticos | D39: Espejo y tornillo del espejo | E39: Estado del espejo y de su O-Ring de montaje | F39: OK / No OK | H39: Sin daño ni fuga | K39: Sí | L39: Sí | M39: C00014x2.5NBR70 | N39: MT_18A20087_260512
A40: 4.2.2 | B40: 4. Espectrómetro: cámara de medida y óptica | C40: 4.2 Componentes ópticos | D40: Manchas en la óptica | E40: Manchas o suciedad que generen ruido electrónico en la medida | F40: Sí/No | H40: Óptica libre de manchas | K40: Sí | L40: Sí | N40: MT_18A20034_250703_Mantenimiento
A41: 4.2.3 | B41: 4. Espectrómetro: cámara de medida y óptica | C41: 4.2 Componentes ópticos | D41: Boquilla de ingreso de material particulado | E41: Estado de la boquilla y su sello neumático | F41: OK / No OK | H41: Sello neumático íntegro | K41: Sí | L41: Sí | M41: C0004x1 | N41: MT_18A18033_260108
...

Sheet Inspección
A1: FASE 1 — INSPECCIÓN FÍSICA DEL EQUIPO
A3: Cliente: | D3: Serie del espectrómetro:
A4: NIT: | D4: Fecha de inspección:
A5: Equipo / Modelo: | B5: Monitor de partículas GRIMM EDM180 | D5: Técnico responsable:
A6: Número de serie: | D6: N.º de informe (MT):
A8: ID | B8: Nivel macro (N1) | C8: Subnivel (N2) | D8: Ítem (N3) | E8: Qué se verifica | F8: Tipo | G8: Unidad | H8: Criterio de aceptación | I8: LI | J8: LS | K8: Resultado | L8: Valor medido | M8: Verificación de rango | N8: Foto adjunta | O8: Observación | P8: Repuesto / parte asociada
A9: 1.1.1 | B9: =IF(INDEX(Catálogo!B$5:B$73,MATCH($A9,Catálogo!$A$5:$A$73,0))="","",INDEX(Catálogo!B$5:B$73,MATCH($A9,Catálogo!$A$5:$A$73,0))) -> 1. Verificación funcional inicial | C9: =IF(INDEX(Catálogo!C$5:C$73,MATCH($A9,Catálogo!$A$5:$A$73,0))="","",INDEX(Catálogo!C$5:C$73,MATCH($A9,Catálogo!$A$5:$A$73,0))) -> 1.1 Encendido y autodiagnóstico | D9: =IF(INDEX(Catálogo!D$5:D$73,MATCH($A9,Catálogo!$A$5:$A$73,0))="","",INDEX(Catálogo!D$5:D$73,MATCH($A9,Catálogo!$A$5:$A$73,0))) -> Ciclo self-test | E9: =IF(INDEX(Catálogo!E$5:E$73,MATCH($A9,Catálogo!$A$5:$A$73,0))="","",INDEX(Catálogo!E$5:E$73,MATCH($A9,Catálogo!$A$5:$A$73,0))) -> El equipo enciende y supera el ciclo self test | F9: =IF(INDEX(Catálogo!F$5:F$73,MATCH($A9,Catálogo!$A$5:$A$73,0))="","",INDEX(Catálogo!F$5:F$73,MATCH($A9,Catálogo!$A$5:$A$73,0))) -> Sí/No | G9: =IF(INDEX(Catálogo!G$5:G$73,MATCH($A9,Catálogo!$A$5:$A$73,0))="","",INDEX(Catálogo!G$5:G$73,MATCH($A9,Catálogo!$A$5:$A$73,0))) | H9: =IF(INDEX(Catálogo!H$5:H$73,MATCH($A9,Catálogo!$A$5:$A$73,0))="","",INDEX(Catálogo!H$5:H$73,MATCH($A9,Catálogo!$A$5:$A$73,0))) -> Debe superar el self test | I9: =IF(INDEX(Catálogo!I$5:I$73,MATCH($A9,Catálogo!$A$5:$A$73,0))="","",INDEX(Catálogo!I$5:I$73,MATCH($A9,Catálogo!$A$5:$A$73,0))) | J9: =IF(INDEX(Catálogo!J$5:J$73,MATCH($A9,Catálogo!$A$5:$A$73,0))="","",INDEX(Catálogo!J$5:J$73,MATCH($A9,Catálogo!$A$5:$A$73,0))) | K9: Pendiente | M9: =IF($F9<>"Numérico","",IF($L9="","Sin dato",IF(AND(OR(NOT(ISNUMBER($I9)),$L9>=$I9),OR(NOT(ISNUMBER($J9)),$L9<=$J9)),"Dentro de rango","Fuera de rango"))) | P9: =IF(INDEX(Catálogo!M$5:M$73,MATCH($A9,Catálogo!$A$5:$A$73,0))="","",INDEX(Catálogo!M$5:M$73,MATCH($A9,Catálogo!$A$5:$A$73,0)))
A10: 1.1.2 | B10: =IF(INDEX(Catálogo!B$5:B$73,MATCH($A10,Catálogo!$A$5:$A$73,0))="","",INDEX(Catálogo!B$5:B$73,MATCH($A10,Catálogo!$A$5:$A$73,0))) -> 1. Verificación funcional inicial | C10: =IF(INDEX(Catálogo!C$5:C$73,MATCH($A10,Catálogo!$A$5:$A$73,0))="","",INDEX(Catálogo!C$5:C$73,MATCH($A10,Catálogo!$A$5:$A$73,0))) -> 1.1 Encendido y autodiagnóstico | D10: =IF(INDEX(Catálogo!D$5:D$73,MATCH($A10,Catálogo!$A$5:$A$73,0))="","",INDEX(Catálogo!D$5:D$73,MATCH($A10,Catálogo!$A$5:$A$73,0))) -> Inicio de medición | E10: =IF(INDEX(Catálogo!E$5:E$73,MATCH($A10,Catálogo!$A$5:$A$73,0))="","",INDEX(Catálogo!E$5:E$73,MATCH($A10,Catálogo!$A$5:$A$73,0))) -> El equipo comienza a medir tras el self test | F10: =IF(INDEX(Catálogo!F$5:F$73,MATCH($A10,Catálogo!$A$5:$A$73,0))="","",INDEX(Catálogo!F$5:F$73,MATCH($A10,Catálogo!$A$5:$A$73,0))) -> Sí/No | G10: =IF(INDEX(Catálogo!G$5:G$73,MATCH($A10,Catálogo!$A$5:$A$73,0))="","",INDEX(Catálogo!G$5:G$73,MATCH($A10,Catálogo!$A$5:$A$73,0))) | H10: =IF(INDEX(Catálogo!H$5:H$73,MATCH($A10,Catálogo!$A$5:$A$73,0))="","",INDEX(Catálogo!H$5:H$73,MATCH($A10,Catálogo!$A$5:$A$73,0))) -> Debe iniciar medición | I10: =IF(INDEX(Catálogo!I$5:I$73,MATCH($A10,Catálogo!$A$5:$A$73,0))="","",INDEX(Catálogo!I$5:I$73,MATCH($A10,Catálogo!$A$5:$A$73,0))) | J10: =IF(INDEX(Catálogo!J$5:J$73,MATCH($A10,Catálogo!$A$5:$A$73,0))="","",INDEX(Catálogo!J$5:J$73,MATCH($A10,Catálogo!$A$5:$A$73,0))) | K10: Pendiente | M10: =IF($F10<>"Numérico","",IF($L10="","Sin dato",IF(AND(OR(NOT(ISNUMBER($I10)),$L10>=$I10),OR(NOT(ISNUMBER($J10)),$L10<=$J10)),"Dentro de rango","Fuera de rango"))) | P10: =IF(INDEX(Catálogo!M$5:M$73,MATCH($A10,Catálogo!$A$5:$A$73,0))="","",INDEX(Catálogo!M$5:M$73,MATCH($A10,Catálogo!$A$5:$A$73,0)))
A11: 1.1.3 | B11: =IF(INDEX(Catálogo!B$5:B$73,MATCH($A11,Catálogo!$A$5:$A$73,0))="","",INDEX(Catálogo!B$5:B$73,MATCH($A11,Catálogo!$A$5:$A$73,0))) -> 1. Verificación funcional inicial | C11: =IF(INDEX(Catálogo!C$5:C$73,MATCH($A11,Catálogo!$A$5:$A$73,0))="","",INDEX(Catálogo!C$5:C$73,MATCH($A11,Catálogo!$A$5:$A$73,0))) -> 1.1 Encendido y autodiagnóstico | D11: =IF(INDEX(Catálogo!D$5:D$73,MATCH($A11,Catálogo!$A$5:$A$73,0))="","",INDEX(Catálogo!D$5:D$73,MATCH($A11,Catálogo!$A$5:$A$73,0))) -> Alarmas activas | E11: =IF(INDEX(Catálogo!E$5:E$73,MATCH($A11,Catálogo!$A$5:$A$73,0))="","",INDEX(Catálogo!E$5:E$73,MATCH($A11,Catálogo!$A$5:$A$73,0))) -> Alarmas o avisos en pantalla al arranque (p. ej. alerta "Dryer") | F11: =IF(INDEX(Catálogo!F$5:F$73,MATCH($A11,Catálogo!$A$5:$A$73,0))="","",INDEX(Catálogo!F$5:F$73,MATCH($A11,Catálogo!$A$5:$A$73,0))) -> Texto | G11: =IF(INDEX(Catálogo!G$5:G$73,MATCH($A11,Catálogo!$A$5:$A$73,0))="","",INDEX(Catálogo!G$5:G$73,MATCH($A11,Catálogo!$A$5:$A$73,0))) | H11: =IF(INDEX(Catálogo!H$5:H$73,MATCH($A11,Catálogo!$A$5:$A$73,0))="","",INDEX(Catálogo!H$5:H$73,MATCH($A11,Catálogo!$A$5:$A$73,0))) -> Sin alarmas activas | I11: =IF(INDEX(Catálogo!I$5:I$73,MATCH($A11,Catálogo!$A$5:$A$73,0))="","",INDEX(Catálogo!I$5:I$73,MATCH($A11,Catálogo!$A$5:$A$73,0))) | J11: =IF(INDEX(Catálogo!J$5:J$73,MATCH($A11,Catálogo!$A$5:$A$73,0))="","",INDEX(Catálogo!J$5:J$73,MATCH($A11,Catálogo!$A$5:$A$73,0))) | K11: Pendiente | M11: =IF($F11<>"Numérico","",IF($L11="","Sin dato",IF(AND(OR(NOT(ISNUMBER($I11)),$L11>=$I11),OR(NOT(ISNUMBER($J11)),$L11<=$J11)),"Dentro de rango","Fuera de rango"))) | P11: =IF(INDEX(Catálogo!M$5:M$73,MATCH($A11,Catálogo!$A$5:$A$73,0))="","",INDEX(Catálogo!M$5:M$73,MATCH($A11,Catálogo!$A$5:$A$73,0)))
A12: 1.2.1 | B12: =IF(INDEX(Catálogo!B$5:B$73,MATCH($A12,Catálogo!$A$5:$A$73,0))="","",INDEX(Catálogo!B$5:B$73,MATCH($A12,Catálogo!$A$5:$A$73,0))) -> 1. Verificación funcional inicial | C12: =IF(INDEX(Catálogo!C$5:C$73,MATCH($A12,Catálogo!$A$5:$A$73,0))="","",INDEX(Catálogo!C$5:C$73,MATCH($A12,Catálogo!$A$5:$A$73,0))) -> 1.2 Identificación y trazabilidad | D12: =IF(INDEX(Catálogo!D$5:D$73,MATCH($A12,Catálogo!$A$5:$A$73,0))="","",INDEX(Catálogo!D$5:D$73,MATCH($A12,Catálogo!$A$5:$A$73,0))) -> Serial del monitor | E12: =IF(INDEX(Catálogo!E$5:E$73,MATCH($A12,Catálogo!$A$5:$A$73,0))="","",INDEX(Catálogo!E$5:E$73,MATCH($A12,Catálogo!$A$5:$A$73,0))) -> El serial del monitor coincide con la placa y con la orden de servicio | F12: =IF(INDEX(Catálogo!F$5:F$73,MATCH($A12,Catálogo!$A$5:$A$73,0))="","",INDEX(Catálogo!F$5:F$73,MATCH($A12,Catálogo!$A$5:$A$73,0))) -> Sí/No | G12: =IF(INDEX(Catálogo!G$5:G$73,MATCH($A12,Catálogo!$A$5:$A$73,0))="","",INDEX(Catálogo!G$5:G$73,MATCH($A12,Catálogo!$A$5:$A$73,0))) | H12: =IF(INDEX(Catálogo!H$5:H$73,MATCH($A12,Catálogo!$A$5:$A$73,0))="","",INDEX(Catálogo!H$5:H$73,MATCH($A12,Catálogo!$A$5:$A$73,0))) -> Debe coincidir | I12: =IF(INDEX(Catálogo!I$5:I$73,MATCH($A12,Catálogo!$A$5:$A$73,0))="","",INDEX(Catálogo!I$5:I$73,MATCH($A12,Catálogo!$A$5:$A$73,0))) | J12: =IF(INDEX(Catálogo!J$5:J$73,MATCH($A12,Catálogo!$A$5:$A$73,0))="","",INDEX(Catálogo!J$5:J$73,MATCH($A12,Catálogo!$A$5:$A$73,0))) | K12: Pendiente | M12: =IF($F12<>"Numérico","",IF($L12="","Sin dato",IF(AND(OR(NOT(ISNUMBER($I12)),$L12>=$I12),OR(NOT(ISNUMBER($J12)),$L12<=$J12)),"Dentro de rango","Fuera de rango"))) | P12: =IF(INDEX(Catálogo!M$5:M$73,MATCH($A12,Catálogo!$A$5:$A$73,0))="","",INDEX(Catálogo!M$5:M$73,MATCH($A12,Catálogo!$A$5:$A$73,0)))
A13: 1.2.2 | B13: =IF(INDEX(Catálogo!B$5:B$73,MATCH($A13,Catálogo!$A$5:$A$73,0))="","",INDEX(Catálogo!B$5:B$73,MATCH($A13,Catálogo!$A$5:$A$73,0))) -> 1. Verificación funcional inicial | C13: =IF(INDEX(Catálogo!C$5:C$73,MATCH($A13,Catálogo!$A$5:$A$73,0))="","",INDEX(Catálogo!C$5:C$73,MATCH($A13,Catálogo!$A$5:$A$73,0))) -> 1.2 Identificación y trazabilidad | D13: =IF(INDEX(Catálogo!D$5:D$73,MATCH($A13,Catálogo!$A$5:$A$73,0))="","",INDEX(Catálogo!D$5:D$73,MATCH($A13,Catálogo!$A$5:$A$73,0))) -> Serial del espectrómetro | E13: =IF(INDEX(Catálogo!E$5:E$73,MATCH($A13,Catálogo!$A$5:$A$73,0))="","",INDEX(Catálogo!E$5:E$73,MATCH($A13,Catálogo!$A$5:$A$73,0))) -> El espectrómetro instalado corresponde al del equipo (no de otro monitor) | F13: =IF(INDEX(Catálogo!F$5:F$73,MATCH($A13,Catálogo!$A$5:$A$73,0))="","",INDEX(Catálogo!F$5:F$73,MATCH($A13,Catálogo!$A$5:$A$73,0))) -> Sí/No | G13: =IF(INDEX(Catálogo!G$5:G$73,MATCH($A13,Catálogo!$A$5:$A$73,0))="","",INDEX(Catálogo!G$5:G$73,MATCH($A13,Catálogo!$A$5:$A$73,0))) | H13: =IF(INDEX(Catálogo!H$5:H$73,MATCH($A13,Catálogo!$A$5:$A$73,0))="","",INDEX(Catálogo!H$5:H$73,MATCH($A13,Catálogo!$A$5:$A$73,0))) -> Debe corresponder | I13: =IF(INDEX(Catálogo!I$5:I$73,MATCH($A13,Catálogo!$A$5:$A$73,0))="","",INDEX(Catálogo!I$5:I$73,MATCH($A13,Catálogo!$A$5:$A$73,0))) | J13: =IF(INDEX(Catálogo!J$5:J$73,MATCH($A13,Catálogo!$A$5:$A$73,0))="","",INDEX(Catálogo!J$5:J$73,MATCH($A13,Catálogo!$A$5:$A$73,0))) | K13: Pendiente | M13: =IF($F13<>"Numérico","",IF($L13="","Sin dato",IF(AND(OR(NOT(ISNUMBER($I13)),$L13>=$I13),OR(NOT(ISNUMBER($J13)),$L13<=$J13)),"Dentro de rango","Fuera de rango"))) | P13: =IF(INDEX(Catálogo!M$5:M$73,MATCH($A13,Catálogo!$A$5:$A$73,0))="","",INDEX(Catálogo!M$5:M$73,MATCH($A13,Catálogo!$A$5:$A$73,0)))
A14: 1.2.3 | B14: =IF(INDEX(Catálogo!B$5:B$73,MATCH($A14,Catálogo!$A$5:$A$73,0))="","",INDEX(Catálogo!B$5:B$73,MATCH($A14,Catálogo!$A$5:$A$73,0))) -> 1. Verificación funcional inicial | C14: =IF(INDEX(Catálogo!C$5:C$73,MATCH($A14,Catálogo!$A$5:$A$73,0))="","",INDEX(Catálogo!C$5:C$73,MATCH($A14,Catálogo!$A$5:$A$73,0))) -> 1.2 Identificación y trazabilidad | D14: =IF(INDEX(Catálogo!D$5:D$73,MATCH($A14,Catálogo!$A$5:$A$73,0))="","",INDEX(Catálogo!D$5:D$73,MATCH($A14,Catálogo!$A$5:$A$73,0))) -> Accesorios recibidos | E14: =IF(INDEX(Catálogo!E$5:E$73,MATCH($A14,Catálogo!$A$5:$A$73,0))="","",INDEX(Catálogo!E$5:E$73,MATCH($A14,Catálogo!$A$5:$A$73,0))) -> Inventario de accesorios: tubo de muestra, cabezal TSP, sensor T/HR, cables | F14: =IF(INDEX(Catálogo!F$5:F$73,MATCH($A14,Catálogo!$A$5:$A$73,0))="","",INDEX(Catálogo!F$5:F$73,MATCH($A14,Catálogo!$A$5:$A$73,0))) -> Texto | G14: =IF(INDEX(Catálogo!G$5:G$73,MATCH($A14,Catálogo!$A$5:$A$73,0))="","",INDEX(Catálogo!G$5:G$73,MATCH($A14,Catálogo!$A$5:$A$73,0))) | H14: =IF(INDEX(Catálogo!H$5:H$73,MATCH($A14,Catálogo!$A$5:$A$73,0))="","",INDEX(Catálogo!H$5:H$73,MATCH($A14,Catálogo!$A$5:$A$73,0))) -> Inventario completo | I14: =IF(INDEX(Catálogo!I$5:I$73,MATCH($A14,Catálogo!$A$5:$A$73,0))="","",INDEX(Catálogo!I$5:I$73,MATCH($A14,Catálogo!$A$5:$A$73,0))) | J14: =IF(INDEX(Catálogo!J$5:J$73,MATCH($A14,Catálogo!$A$5:$A$73,0))="","",INDEX(Catálogo!J$5:J$73,MATCH($A14,Catálogo!$A$5:$A$73,0))) | K14: Pendiente | M14: =IF($F14<>"Numérico","",IF($L14="","Sin dato",IF(AND(OR(NOT(ISNUMBER($I14)),$L14>=$I14),OR(NOT(ISNUMBER($J14)),$L14<=$J14)),"Dentro de rango","Fuera de rango"))) | P14: =IF(INDEX(Catálogo!M$5:M$73,MATCH($A14,Catálogo!$A$5:$A$73,0))="","",INDEX(Catálogo!M$5:M$73,MATCH($A14,Catálogo!$A$5:$A$73,0)))
A15: 1.3.1 | B15: =IF(INDEX(Catálogo!B$5:B$73,MATCH($A15,Catálogo!$A$5:$A$73,0))="","",INDEX(Catálogo!B$5:B$73,MATCH($A15,Catálogo!$A$5:$A$73,0))) -> 1. Verificación funcional inicial | C15: =IF(INDEX(Catálogo!C$5:C$73,MATCH($A15,Catálogo!$A$5:$A$73,0))="","",INDEX(Catálogo!C$5:C$73,MATCH($A15,Catálogo!$A$5:$A$73,0))) -> 1.3 Estado de calibración | D15: =IF(INDEX(Catálogo!D$5:D$73,MATCH($A15,Catálogo!$A$5:$A$73,0))="","",INDEX(Catálogo!D$5:D$73,MATCH($A15,Catálogo!$A$5:$A$73,0))) -> Vigencia de calibración en Torre GRIMM | E15: =IF(INDEX(Catálogo!E$5:E$73,MATCH($A15,Catálogo!$A$5:$A$73,0))="","",INDEX(Catálogo!E$5:E$73,MATCH($A15,Catálogo!$A$5:$A$73,0))) -> Fecha de la última calibración en torre patrón | F15: =IF(INDEX(Catálogo!F$5:F$73,MATCH($A15,Catálogo!$A$5:$A$73,0))="","",INDEX(Catálogo!F$5:F$73,MATCH($A15,Catálogo!$A$5:$A$73,0))) -> Fecha | G15: =IF(INDEX(Catálogo!G$5:G$73,MATCH($A15,Catálogo!$A$5:$A$73,0))="","",INDEX(Catálogo!G$5:G$73,MATCH($A15,Catálogo!$A$5:$A$73,0))) | H15: =IF(INDEX(Catálogo!H$5:H$73,MATCH($A15,Catálogo!$A$5:$A$73,0))="","",INDEX(Catálogo!H$5:H$73,MATCH($A15,Catálogo!$A$5:$A$73,0))) -> Vigencia máxima 12 meses | I15: =IF(INDEX(Catálogo!I$5:I$73,MATCH($A15,Catálogo!$A$5:$A$73,0))="","",INDEX(Catálogo!I$5:I$73,MATCH($A15,Catálogo!$A$5:$A$73,0))) | J15: =IF(INDEX(Catálogo!J$5:J$73,MATCH($A15,Catálogo!$A$5:$A$73,0))="","",INDEX(Catálogo!J$5:J$73,MATCH($A15,Catálogo!$A$5:$A$73,0))) | K15: Pendiente | M15: =IF($F15<>"Numérico","",IF($L15="","Sin dato",IF(AND(OR(NOT(ISNUMBER($I15)),$L15>=$I15),OR(NOT(ISNUMBER($J15)),$L15<=$J15)),"Dentro de rango","Fuera de rango"))) | P15: =IF(INDEX(Catálogo!M$5:M$73,MATCH($A15,Catálogo!$A$5:$A$73,0))="","",INDEX(Catálogo!M$5:M$73,MATCH($A15,Catálogo!$A$5:$A$73,0))) -> AMB-STCALENVIRO-01
A16: 1.3.2 | B16: =IF(INDEX(Catálogo!B$5:B$73,MATCH($A16,Catálogo!$A$5:$A$73,0))="","",INDEX(Catálogo!B$5:B$73,MATCH($A16,Catálogo!$A$5:$A$73,0))) -> 1. Verificación funcional inicial | C16: =IF(INDEX(Catálogo!C$5:C$73,MATCH($A16,Catálogo!$A$5:$A$73,0))="","",INDEX(Catálogo!C$5:C$73,MATCH($A16,Catálogo!$A$5:$A$73,0))) -> 1.3 Estado de calibración | D16: =IF(INDEX(Catálogo!D$5:D$73,MATCH($A16,Catálogo!$A$5:$A$73,0))="","",INDEX(Catálogo!D$5:D$73,MATCH($A16,Catálogo!$A$5:$A$73,0))) -> Certificado disponible | E16: =IF(INDEX(Catálogo!E$5:E$73,MATCH($A16,Catálogo!$A$5:$A$73,0))="","",INDEX(Catálogo!E$5:E$73,MATCH($A16,Catálogo!$A$5:$A$73,0))) -> Existe certificado de la última calibración | F16: =IF(INDEX(Catálogo!F$5:F$73,MATCH($A16,Catálogo!$A$5:$A$73,0))="","",INDEX(Catálogo!F$5:F$73,MATCH($A16,Catálogo!$A$5:$A$73,0))) -> Sí/No | G16: =IF(INDEX(Catálogo!G$5:G$73,MATCH($A16,Catálogo!$A$5:$A$73,0))="","",INDEX(Catálogo!G$5:G$73,MATCH($A16,Catálogo!$A$5:$A$73,0))) | H16: =IF(INDEX(Catálogo!H$5:H$73,MATCH($A16,Catálogo!$A$5:$A$73,0))="","",INDEX(Catálogo!H$5:H$73,MATCH($A16,Catálogo!$A$5:$A$73,0))) -> Debe existir | I16: =IF(INDEX(Catálogo!I$5:I$73,MATCH($A16,Catálogo!$A$5:$A$73,0))="","",INDEX(Catálogo!I$5:I$73,MATCH($A16,Catálogo!$A$5:$A$73,0))) | J16: =IF(INDEX(Catálogo!J$5:J$73,MATCH($A16,Catálogo!$A$5:$A$73,0))="","",INDEX(Catálogo!J$5:J$73,MATCH($A16,Catálogo!$A$5:$A$73,0))) | K16: Pendiente | M16: =IF($F16<>"Numérico","",IF($L16="","Sin dato",IF(AND(OR(NOT(ISNUMBER($I16)),$L16>=$I16),OR(NOT(ISNUMBER($J16)),$L16<=$J16)),"Dentro de rango","Fuera de rango"))) | P16: =IF(INDEX(Catálogo!M$5:M$73,MATCH($A16,Catálogo!$A$5:$A$73,0))="","",INDEX(Catálogo!M$5:M$73,MATCH($A16,Catálogo!$A$5:$A$73,0)))
A17: 2.1.1 | B17: =IF(INDEX(Catálogo!B$5:B$73,MATCH($A17,Catálogo!$A$5:$A$73,0))="","",INDEX(Catálogo!B$5:B$73,MATCH($A17,Catálogo!$A$5:$A$73,0))) -> 2. Línea de muestreo y cabezal | C17: =IF(INDEX(Catálogo!C$5:C$73,MATCH($A17,Catálogo!$A$5:$A$73,0))="","",INDEX(Catálogo!C$5:C$73,MATCH($A17,Catálogo!$A$5:$A$73,0))) -> 2.1 Cabezal TSP | D17: =IF(INDEX(Catálogo!D$5:D$73,MATCH($A17,Catálogo!$A$5:$A$73,0))="","",INDEX(Catálogo!D$5:D$73,MATCH($A17,Catálogo!$A$5:$A$73,0))) -> Estado físico del cabezal | E17: =IF(INDEX(Catálogo!E$5:E$73,MATCH($A17,Catálogo!$A$5:$A$73,0))="","",INDEX(Catálogo!E$5:E$73,MATCH($A17,Catálogo!$A$5:$A$73,0))) -> Golpes, deformación, corrosión del cabezal TSP | F17: =IF(INDEX(Catálogo!F$5:F$73,MATCH($A17,Catálogo!$A$5:$A$73,0))="","",INDEX(Catálogo!F$5:F$73,MATCH($A17,Catálogo!$A$5:$A$73,0))) -> OK / No OK | G17: =IF(INDEX(Catálogo!G$5:G$73,MATCH($A17,Catálogo!$A$5:$A$73,0))="","",INDEX(Catálogo!G$5:G$73,MATCH($A17,Catálogo!$A$5:$A$73,0))) | H17: =IF(INDEX(Catálogo!H$5:H$73,MATCH($A17,Catálogo!$A$5:$A$73,0))="","",INDEX(Catálogo!H$5:H$73,MATCH($A17,Catálogo!$A$5:$A$73,0))) -> Sin deformación ni corrosión | I17: =IF(INDEX(Catálogo!I$5:I$73,MATCH($A17,Catálogo!$A$5:$A$73,0))="","",INDEX(Catálogo!I$5:I$73,MATCH($A17,Catálogo!$A$5:$A$73,0))) | J17: =IF(INDEX(Catálogo!J$5:J$73,MATCH($A17,Catálogo!$A$5:$A$73,0))="","",INDEX(Catálogo!J$5:J$73,MATCH($A17,Catálogo!$A$5:$A$73,0))) | K17: Pendiente | M17: =IF($F17<>"Numérico","",IF($L17="","Sin dato",IF(AND(OR(NOT(ISNUMBER($I17)),$L17>=$I17),OR(NOT(ISNUMBER($J17)),$L17<=$J17)),"Dentro de rango","Fuera de rango"))) | P17: =IF(INDEX(Catálogo!M$5:M$73,MATCH($A17,Catálogo!$A$5:$A$73,0))="","",INDEX(Catálogo!M$5:M$73,MATCH($A17,Catálogo!$A$5:$A$73,0)))
A18: 2.1.2 | B18: =IF(INDEX(Catálogo!B$5:B$73,MATCH($A18,Catálogo!$A$5:$A$73,0))="","",INDEX(Catálogo!B$5:B$73,MATCH($A18,Catálogo!$A$5:$A$73,0))) -> 2. Línea de muestreo y cabezal | C18: =IF(INDEX(Catálogo!C$5:C$73,MATCH($A18,Catálogo!$A$5:$A$73,0))="","",INDEX(Catálogo!C$5:C$73,MATCH($A18,Catálogo!$A$5:$A$73,0))) -> 2.1 Cabezal TSP | D18: =IF(INDEX(Catálogo!D$5:D$73,MATCH($A18,Catálogo!$A$5:$A$73,0))="","",INDEX(Catálogo!D$5:D$73,MATCH($A18,Catálogo!$A$5:$A$73,0))) -> Tornillo de seguridad del cabezal | E18: =IF(INDEX(Catálogo!E$5:E$73,MATCH($A18,Catálogo!$A$5:$A$73,0))="","",INDEX(Catálogo!E$5:E$73,MATCH($A18,Catálogo!$A$5:$A$73,0))) -> Presencia y estado del tornillo de seguridad del cabezal TSP | F18: =IF(INDEX(Catálogo!F$5:F$73,MATCH($A18,Catálogo!$A$5:$A$73,0))="","",INDEX(Catálogo!F$5:F$73,MATCH($A18,Catálogo!$A$5:$A$73,0))) -> Presente / Ausente | G18: =IF(INDEX(Catálogo!G$5:G$73,MATCH($A18,Catálogo!$A$5:$A$73,0))="","",INDEX(Catálogo!G$5:G$73,MATCH($A18,Catálogo!$A$5:$A$73,0))) | H18: =IF(INDEX(Catálogo!H$5:H$73,MATCH($A18,Catálogo!$A$5:$A$73,0))="","",INDEX(Catálogo!H$5:H$73,MATCH($A18,Catálogo!$A$5:$A$73,0))) -> Debe estar presente | I18: =IF(INDEX(Catálogo!I$5:I$73,MATCH($A18,Catálogo!$A$5:$A$73,0))="","",INDEX(Catálogo!I$5:I$73,MATCH($A18,Catálogo!$A$5:$A$73,0))) | J18: =IF(INDEX(Catálogo!J$5:J$73,MATCH($A18,Catálogo!$A$5:$A$73,0))="","",INDEX(Catálogo!J$5:J$73,MATCH($A18,Catálogo!$A$5:$A$73,0))) | K18: Pendiente | M18: =IF($F18<>"Numérico","",IF($L18="","Sin dato",IF(AND(OR(NOT(ISNUMBER($I18)),$L18>=$I18),OR(NOT(ISNUMBER($J18)),$L18<=$J18)),"Dentro de rango","Fuera de rango"))) | P18: =IF(INDEX(Catálogo!M$5:M$73,MATCH($A18,Catálogo!$A$5:$A$73,0))="","",INDEX(Catálogo!M$5:M$73,MATCH($A18,Catálogo!$A$5:$A$73,0))) -> M02M2X4D912A4
A19: 2.1.3 | B19: =IF(INDEX(Catálogo!B$5:B$73,MATCH($A19,Catálogo!$A$5:$A$73,0))="","",INDEX(Catálogo!B$5:B$73,MATCH($A19,Catálogo!$A$5:$A$73,0))) -> 2. Línea de muestreo y cabezal | C19: =IF(INDEX(Catálogo!C$5:C$73,MATCH($A19,Catálogo!$A$5:$A$73,0))="","",INDEX(Catálogo!C$5:C$73,MATCH($A19,Catálogo!$A$5:$A$73,0))) -> 2.1 Cabezal TSP | D19: =IF(INDEX(Catálogo!D$5:D$73,MATCH($A19,Catálogo!$A$5:$A$73,0))="","",INDEX(Catálogo!D$5:D$73,MATCH($A19,Catálogo!$A$5:$A$73,0))) -> Limpieza interna del cabezal | E19: =IF(INDEX(Catálogo!E$5:E$73,MATCH($A19,Catálogo!$A$5:$A$73,0))="","",INDEX(Catálogo!E$5:E$73,MATCH($A19,Catálogo!$A$5:$A$73,0))) -> Acumulación de material particulado en el interior del cabezal | F19: =IF(INDEX(Catálogo!F$5:F$73,MATCH($A19,Catálogo!$A$5:$A$73,0))="","",INDEX(Catálogo!F$5:F$73,MATCH($A19,Catálogo!$A$5:$A$73,0))) -> OK / No OK | G19: =IF(INDEX(Catálogo!G$5:G$73,MATCH($A19,Catálogo!$A$5:$A$73,0))="","",INDEX(Catálogo!G$5:G$73,MATCH($A19,Catálogo!$A$5:$A$73,0))) | H19: =IF(INDEX(Catálogo!H$5:H$73,MATCH($A19,Catálogo!$A$5:$A$73,0))="","",INDEX(Catálogo!H$5:H$73,MATCH($A19,Catálogo!$A$5:$A$73,0))) -> Libre de acumulación | I19: =IF(INDEX(Catálogo!I$5:I$73,MATCH($A19,Catálogo!$A$5:$A$73,0))="","",INDEX(Catálogo!I$5:I$73,MATCH($A19,Catálogo!$A$5:$A$73,0))) | J19: =IF(INDEX(Catálogo!J$5:J$73,MATCH($A19,Catálogo!$A$5:$A$73,0))="","",INDEX(Catálogo!J$5:J$73,MATCH($A19,Catálogo!$A$5:$A$73,0))) | K19: Pendiente | M19: =IF($F19<>"Numérico","",IF($L19="","Sin dato",IF(AND(OR(NOT(ISNUMBER($I19)),$L19>=$I19),OR(NOT(ISNUMBER($J19)),$L19<=$J19)),"Dentro de rango","Fuera de rango"))) | P19: =IF(INDEX(Catálogo!M$5:M$73,MATCH($A19,Catálogo!$A$5:$A$73,0))="","",INDEX(Catálogo!M$5:M$73,MATCH($A19,Catálogo!$A$5:$A$73,0)))
A20: 2.2.1 | B20: =IF(INDEX(Catálogo!B$5:B$73,MATCH($A20,Catálogo!$A$5:$A$73,0))="","",INDEX(Catálogo!B$5:B$73,MATCH($A20,Catálogo!$A$5:$A$73,0))) -> 2. Línea de muestreo y cabezal | C20: =IF(INDEX(Catálogo!C$5:C$73,MATCH($A20,Catálogo!$A$5:$A$73,0))="","",INDEX(Catálogo!C$5:C$73,MATCH($A20,Catálogo!$A$5:$A$73,0))) -> 2.2 Tubo de muestra (1.5 m) | D20: =IF(INDEX(Catálogo!D$5:D$73,MATCH($A20,Catálogo!$A$5:$A$73,0))="","",INDEX(Catálogo!D$5:D$73,MATCH($A20,Catálogo!$A$5:$A$73,0))) -> Rectitud del tubo | E20: =IF(INDEX(Catálogo!E$5:E$73,MATCH($A20,Catálogo!$A$5:$A$73,0))="","",INDEX(Catálogo!E$5:E$73,MATCH($A20,Catálogo!$A$5:$A$73,0))) -> Deformación o torcedura del tubo de muestra | F20: =IF(INDEX(Catálogo!F$5:F$73,MATCH($A20,Catálogo!$A$5:$A$73,0))="","",INDEX(Catálogo!F$5:F$73,MATCH($A20,Catálogo!$A$5:$A$73,0))) -> OK / No OK | G20: =IF(INDEX(Catálogo!G$5:G$73,MATCH($A20,Catálogo!$A$5:$A$73,0))="","",INDEX(Catálogo!G$5:G$73,MATCH($A20,Catálogo!$A$5:$A$73,0))) | H20: =IF(INDEX(Catálogo!H$5:H$73,MATCH($A20,Catálogo!$A$5:$A$73,0))="","",INDEX(Catálogo!H$5:H$73,MATCH($A20,Catálogo!$A$5:$A$73,0))) -> Sin deformación mecánica | I20: =IF(INDEX(Catálogo!I$5:I$73,MATCH($A20,Catálogo!$A$5:$A$73,0))="","",INDEX(Catálogo!I$5:I$73,MATCH($A20,Catálogo!$A$5:$A$73,0))) | J20: =IF(INDEX(Catálogo!J$5:J$73,MATCH($A20,Catálogo!$A$5:$A$73,0))="","",INDEX(Catálogo!J$5:J$73,MATCH($A20,Catálogo!$A$5:$A$73,0))) | K20: Pendiente | M20: =IF($F20<>"Numérico","",IF($L20="","Sin dato",IF(AND(OR(NOT(ISNUMBER($I20)),$L20>=$I20),OR(NOT(ISNUMBER($J20)),$L20<=$J20)),"Dentro de rango","Fuera de rango"))) | P20: =IF(INDEX(Catálogo!M$5:M$73,MATCH($A20,Catálogo!$A$5:$A$73,0))="","",INDEX(Catálogo!M$5:M$73,MATCH($A20,Catálogo!$A$5:$A$73,0))) -> GR-TI-01
... A30: 2.4.3 | B30: =IF(INDEX(Catálogo!B$5:B$73,MATCH($A30,Catálogo!$A$5:$A$73,0))="","",INDEX(Catálogo!B$5:B$73,MATCH($A30,Catálogo!$A$5:$A$73,0))) -> 2. Línea de muestreo y cabezal | C30: =IF(INDEX(Catálogo!C$5:C$73,MATCH($A30,Catálogo!$A$5:$A$73,0))="","",INDEX(Catálogo!C$5:C$73,MATCH($A30,Catálogo!$A$5:$A$73,0))) -> 2.4 Secador Nafion y drenaje | D30: =IF(INDEX(Catálogo!D$5:D$73,MATCH($A30,Catálogo!$A$5:$A$73,0))="","",INDEX(Catálogo!D$5:D$73,MATCH($A30,Catálogo!$A$5:$A$73,0))) -> Mangueras de la línea neumática | E30: =IF(INDEX(Catálogo!E$5:E$73,MATCH($A30,Catálogo!$A$5:$A$73,0))="","",INDEX(Catálogo!E$5:E$73,MATCH($A30,Catálogo!$A$5:$A$73,0))) -> Roturas, fisuras o endurecimiento de las mangueras | F30: =IF(INDEX(Catálogo!F$5:F$73,MATCH($A30,Catálogo!$A$5:$A$73,0))="","",INDEX(Catálogo!F$5:F$73,MATCH($A30,Catálogo!$A$5:$A$73,0))) -> OK / No OK | G30: =IF(INDEX(Catálogo!G$5:G$73,MATCH($A30,Catálogo!$A$5:$A$73,0))="","",INDEX(Catálogo!G$5:G$73,MATCH($A30,Catálogo!$A$5:$A$73,0))) | H30: =IF(INDEX(Catálogo!H$5:H$73,MATCH($A30,Catálogo!$A$5:$A$73,0))="","",INDEX(Catálogo!H$5:H$73,MATCH($A30,Catálogo!$A$5:$A$73,0))) -> Sin roturas | I30: =IF(INDEX(Catálogo!I$5:I$73,MATCH($A30,Catálogo!$A$5:$A$73,0))="","",INDEX(Catálogo!I$5:I$73,MATCH($A30,Catálogo!$A$5:$A$73,0))) | J30: =IF(INDEX(Catálogo!J$5:J$73,MATCH($A30,Catálogo!$A$5:$A$73,0))="","",INDEX(Catálogo!J$5:J$73,MATCH($A30,Catálogo!$A$5:$A$73,0))) | K30: Pendiente | M30: =IF($F30<>"Numérico","",IF($L30="","Sin dato",IF(AND(OR(NOT(ISNUMBER($I30)),$L30>=$I30),OR(NOT(ISNUMBER($J30)),$L30<=$J30)),"Dentro de rango","Fuera de rango"))) | P30: =IF(INDEX(Catálogo!M$5:M$73,MATCH($A30,Catálogo!$A$5:$A$73,0))="","",INDEX(Catálogo!M$5:M$73,MATCH($A30,Catálogo!$A$5:$A$73,0)))
A31: 3.1.1 | B31: =IF(INDEX(Catálogo!B$5:B$73,MATCH($A31,Catálogo!$A$5:$A$73,0))="","",INDEX(Catálogo!B$5:B$73,MATCH($A31,Catálogo!$A$5:$A$73,0))) -> 3. Sistema neumático y etapa de secado | C31: =IF(INDEX(Catálogo!C$5:C$73,MATCH($A31,Catálogo!$A$5:$A$73,0))="","",INDEX(Catálogo!C$5:C$73,MATCH($A31,Catálogo!$A$5:$A$73,0))) -> 3.1 Bomba de vacío / secado | D31: =IF(INDEX(Catálogo!D$5:D$73,MATCH($A31,Catálogo!$A$5:$A$73,0))="","",INDEX(Catálogo!D$5:D$73,MATCH($A31,Catálogo!$A$5:$A$73,0))) -> Flujo de la bomba de secado | E31: =IF(INDEX(Catálogo!E$5:E$73,MATCH($A31,Catálogo!$A$5:$A$73,0))="","",INDEX(Catálogo!E$5:E$73,MATCH($A31,Catálogo!$A$5:$A$73,0))) -> Medición del flujo de la bomba de secado | F31: =IF(INDEX(Catálogo!F$5:F$73,MATCH($A31,Catálogo!$A$5:$A$73,0))="","",INDEX(Catálogo!F$5:F$73,MATCH($A31,Catálogo!$A$5:$A$73,0))) -> Numérico | G31: =IF(INDEX(Catálogo!G$5:G$73,MATCH($A31,Catálogo!$A$5:$A$73,0))="","",INDEX(Catálogo!G$5:G$73,MATCH($A31,Catálogo!$A$5:$A$73,0))) -> L/min | H31: =IF(INDEX(Catálogo!H$5:H$73,MATCH($A31,Catálogo!$A$5:$A$73,0))="","",INDEX(Catálogo!H$5:H$73,MATCH($A31,Catálogo!$A$5:$A$73,0))) -> Dentro del rango del fabricante; 2,45 L/min es el valor registrado como cercano al límite de reemplazo | I31: =IF(INDEX(Catálogo!I$5:I$73,MATCH($A31,Catálogo!$A$5:$A$73,0))="","",INDEX(Catálogo!I$5:I$73,MATCH($A31,Catálogo!$A$5:$A$73,0))) -> 1.8 | J31: =IF(INDEX(Catálogo!J$5:J$73,MATCH($A31,Catálogo!$A$5:$A$73,0))="","",INDEX(Catálogo!J$5:J$73,MATCH($A31,Catálogo!$A$5:$A$73,0))) -> 2.45 | K31: Requiere reemplazo | L31: 2.45 | M31: =IF($F31<>"Numérico","",IF($L31="","Sin dato",IF(AND(OR(NOT(ISNUMBER($I31)),$L31>=$I31),OR(NOT(ISNUMBER($J31)),$L31<=$J31)),"Dentro de rango","Fuera de rango"))) -> Dentro de rango | N31: Sí | O31: EJEMPLO — Flujo en el límite superior del rango; desgaste en el empaque del pistón. Borrar antes de usar el formato. | P31: =IF(INDEX(Catálogo!M$5:M$73,MATCH($A31,Catálogo!$A$5:$A$73,0))="","",INDEX(Catálogo!M$5:M$73,MATCH($A31,Catálogo!$A$5:$A$73,0))) -> 1205273
A32: 3.1.2 | B32: =IF(INDEX(Catálogo!B$5:B$73,MATCH($A32,Catálogo!$A$5:$A$73,0))="","",INDEX(Catálogo!B$5:B$73,MATCH($A32,Catálogo!$A$5:$A$73,0))) -> 3. Sistema neumático y etapa de secado | C32: =IF(INDEX(Catálogo!C$5:C$73,MATCH($A32,Catálogo!$A$5:$A$73,0))="","",INDEX(Catálogo!C$5:C$73,MATCH($A32,Catálogo!$A$5:$A$73,0))) -> 3.1 Bomba de vacío / secado | D32: =IF(INDEX(Catálogo!D$5:D$73,MATCH($A32,Catálogo!$A$5:$A$73,0))="","",INDEX(Catálogo!D$5:D$73,MATCH($A32,Catálogo!$A$5:$A$73,0))) -> Estado del kit de la bomba | E32: =IF(INDEX(Catálogo!E$5:E$73,MATCH($A32,Catálogo!$A$5:$A$73,0))="","",INDEX(Catálogo!E$5:E$73,MATCH($A32,Catálogo!$A$5:$A$73,0))) -> Desgaste de los componentes internos del kit de la bomba de vacío | F32: =IF(INDEX(Catálogo!F$5:F$73,MATCH($A32,Catálogo!$A$5:$A$73,0))="","",INDEX(Catálogo!F$5:F$73,MATCH($A32,Catálogo!$A$5:$A$73,0))) -> OK / No OK | G32: =IF(INDEX(Catálogo!G$5:G$73,MATCH($A32,Catálogo!$A$5:$A$73,0))="","",INDEX(Catálogo!G$5:G$73,MATCH($A32,Catálogo!$A$5:$A$73,0))) | H32: =IF(INDEX(Catálogo!H$5:H$73,MATCH($A32,Catálogo!$A$5:$A$73,0))="","",INDEX(Catálogo!H$5:H$73,MATCH($A32,Catálogo!$A$5:$A$73,0))) -> Sin desgaste significativo | I32: =IF(INDEX(Catálogo!I$5:I$73,MATCH($A32,Catálogo!$A$5:$A$73,0))="","",INDEX(Catálogo!I$5:I$73,MATCH($A32,Catálogo!$A$5:$A$73,0))) | J32: =IF(INDEX(Catálogo!J$5:J$73,MATCH($A32,Catálogo!$A$5:$A$73,0))="","",INDEX(Catálogo!J$5:J$73,MATCH($A32,Catálogo!$A$5:$A$73,0))) | K32: Pendiente | M32: =IF($F32<>"Numérico","",IF($L32="","Sin dato",IF(AND(OR(NOT(ISNUMBER($I32)),$L32>=$I32),OR(NOT(ISNUMBER($J32)),$L32<=$J32)),"Dentro de rango","Fuera de rango"))) | P32: =IF(INDEX(Catálogo!M$5:M$73,MATCH($A32,Catálogo!$A$5:$A$73,0))="","",INDEX(Catálogo!M$5:M$73,MATCH($A32,Catálogo!$A$5:$A$73,0))) -> 1205273
A33: 3.1.3 | B33: =IF(INDEX(Catálogo!B$5:B$73,MATCH($A33,Catálogo!$A$5:$A$73,0))="","",INDEX(Catálogo!B$5:B$73,MATCH($A33,Catálogo!$A$5:$A$73,0))) -> 3. Sistema neumático y etapa de secado | C33: =IF(INDEX(Catálogo!C$5:C$73,MATCH($A33,Catálogo!$A$5:$A$73,0))="","",INDEX(Catálogo!C$5:C$73,MATCH($A33,Catálogo!$A$5:$A$73,0))) -> 3.1 Bomba de vacío / secado | D33: =IF(INDEX(Catálogo!D$5:D$73,MATCH($A33,Catálogo!$A$5:$A$73,0))="","",INDEX(Catálogo!D$5:D$73,MATCH($A33,Catálogo!$A$5:$A$73,0))) -> Empaque del pistón (sealing sleeve) | E33: =IF(INDEX(Catálogo!E$5:E$73,MATCH($A33,Catálogo!$A$5:$A$73,0))="","",INDEX(Catálogo!E$5:E$73,MATCH($A33,Catálogo!$A$5:$A$73,0))) -> Desgaste del empaque del pistón de la bomba de secado | F33: =IF(INDEX(Catálogo!F$5:F$73,MATCH($A33,Catálogo!$A$5:$A$73,0))="","",INDEX(Catálogo!F$5:F$73,MATCH($A33,Catálogo!$A$5:$A$73,0))) -> OK / No OK | G33: =IF(INDEX(Catálogo!G$5:G$73,MATCH($A33,Catálogo!$A$5:$A$73,0))="","",INDEX(Catálogo!G$5:G$73,MATCH($A33,Catálogo!$A$5:$A$73,0))) | H33: =IF(INDEX(Catálogo!H$5:H$73,MATCH($A33,Catálogo!$A$5:$A$73,0))="","",INDEX(Catálogo!H$5:H$73,MATCH($A33,Catálogo!$A$5:$A$73,0))) -> Sin desgaste | I33: =IF(INDEX(Catálogo!I$5:I$73,MATCH($A33,Catálogo!$A$5:$A$73,0))="","",INDEX(Catálogo!I$5:I$73,MATCH($A33,Catálogo!$A$5:$A$73,0))) | J33: =IF(INDEX(Catálogo!J$5:J$73,MATCH($A33,Catálogo!$A$5:$A$73,0))="","",INDEX(Catálogo!J$5:J$73,MATCH($A33,Catálogo!$A$5:$A$73,0))) | K33: Pendiente | M33: =IF($F33<>"Numérico","",IF($L33="","Sin dato",IF(AND(OR(NOT(ISNUMBER($I33)),$L33>=$I33),OR(NOT(ISNUMBER($J33)),$L33<=$J33)),"Dentro de rango","Fuera de rango"))) | P33: =IF(INDEX(Catálogo!M$5:M$73,MATCH($A33,Catálogo!$A$5:$A$73,0))="","",INDEX(Catálogo!M$5:M$73,MATCH($A33,Catálogo!$A$5:$A$73,0))) -> 1204480
A34: 3.1.4 | B34: =IF(INDEX(Catálogo!B$5:B$73,MATCH($A34,Catálogo!$A$5:$A$73,0))="","",INDEX(Catálogo!B$5:B$73,MATCH($A34,Catálogo!$A$5:$A$73,0))) -> 3. Sistema neumático y etapa de secado | C34: =IF(INDEX(Catálogo!C$5:C$73,MATCH($A34,Catálogo!$A$5:$A$73,0))="","",INDEX(Catálogo!C$5:C$73,MATCH($A34,Catálogo!$A$5:$A$73,0))) -> 3.1 Bomba de vacío / secado | D34: =IF(INDEX(Catálogo!D$5:D$73,MATCH($A34,Catálogo!$A$5:$A$73,0))="","",INDEX(Catálogo!D$5:D$73,MATCH($A34,Catálogo!$A$5:$A$73,0))) -> Ruido y vibración | E34: =IF(INDEX(Catálogo!E$5:E$73,MATCH($A34,Catálogo!$A$5:$A$73,0))="","",INDEX(Catálogo!E$5:E$73,MATCH($A34,Catálogo!$A$5:$A$73,0))) -> Ruido o vibración anómala de la bomba | F34: =IF(INDEX(Catálogo!F$5:F$73,MATCH($A34,Catálogo!$A$5:$A$73,0))="","",INDEX(Catálogo!F$5:F$73,MATCH($A34,Catálogo!$A$5:$A$73,0))) -> OK / No OK | G34: =IF(INDEX(Catálogo!G$5:G$73,MATCH($A34,Catálogo!$A$5:$A$73,0))="","",INDEX(Catálogo!G$5:G$73,MATCH($A34,Catálogo!$A$5:$A$73,0))) | H34: =IF(INDEX(Catálogo!H$5:H$73,MATCH($A34,Catálogo!$A$5:$A$73,0))="","",INDEX(Catálogo!H$5:H$73,MATCH($A34,Catálogo!$A$5:$A$73,0))) -> Sin ruido anómalo | I34: =IF(INDEX(Catálogo!I$5:I$73,MATCH($A34,Catálogo!$A$5:$A$73,0))="","",INDEX(Catálogo!I$5:I$73,MATCH($A34,Catálogo!$A$5:$A$73,0))) | J34: =IF(INDEX(Catálogo!J$5:J$73,MATCH($A34,Catálogo!$A$5:$A$73,0))="","",INDEX(Catálogo!J$5:J$73,MATCH($A34,Catálogo!$A$5:$A$73,0))) | K34: Pendiente | M34: =IF($F34<>"Numérico","",IF($L34="","Sin dato",IF(AND(OR(NOT(ISNUMBER($I34)),$L34>=$I34),OR(NOT(ISNUMBER($J34)),$L34<=$J34)),"Dentro de rango","Fuera de rango"))) | P34: =IF(INDEX(Catálogo!M$5:M$73,MATCH($A34,Catálogo!$A$5:$A$73,0))="","",INDEX(Catálogo!M$5:M$73,MATCH($A34,Catálogo!$A$5:$A$73,0)))
A35: 3.2.1 | B35: =IF(INDEX(Catálogo!B$5:B$73,MATCH($A35,Catálogo!$A$5:$A$73,0))="","",INDEX(Catálogo!B$5:B$73,MATCH($A35,Catálogo!$A$5:$A$73,0))) -> 3. Sistema neumático y etapa de secado | C35: =IF(INDEX(Catálogo!C$5:C$73,MATCH($A35,Catálogo!$A$5:$A$73,0))="","",INDEX(Catálogo!C$5:C$73,MATCH($A35,Catálogo!$A$5:$A$73,0))) -> 3.2 Instrumentación de presión | D35: =IF(INDEX(Catálogo!D$5:D$73,MATCH($A35,Catálogo!$A$5:$A$73,0))="","",INDEX(Catálogo!D$5:D$73,MATCH($A35,Catálogo!$A$5:$A$73,0))) -> Manómetro de vacío | E35: =IF(INDEX(Catálogo!E$5:E$73,MATCH($A35,Catálogo!$A$5:$A$73,0))="","",INDEX(Catálogo!E$5:E$73,MATCH($A35,Catálogo!$A$5:$A$73,0))) -> El manómetro entrega lectura y no presenta falla mecánica | F35: =IF(INDEX(Catálogo!F$5:F$73,MATCH($A35,Catálogo!$A$5:$A$73,0))="","",INDEX(Catálogo!F$5:F$73,MATCH($A35,Catálogo!$A$5:$A$73,0))) -> OK / No OK | G35: =IF(INDEX(Catálogo!G$5:G$73,MATCH($A35,Catálogo!$A$5:$A$73,0))="","",INDEX(Catálogo!G$5:G$73,MATCH($A35,Catálogo!$A$5:$A$73,0))) | H35: =IF(INDEX(Catálogo!H$5:H$73,MATCH($A35,Catálogo!$A$5:$A$73,0))="","",INDEX(Catálogo!H$5:H$73,MATCH($A35,Catálogo!$A$5:$A$73,0))) -> Debe entregar lectura | I35: =IF(INDEX(Catálogo!I$5:I$73,MATCH($A35,Catálogo!$A$5:$A$73,0))="","",INDEX(Catálogo!I$5:I$73,MATCH($A35,Catálogo!$A$5:$A$73,0))) | J35: =IF(INDEX(Catálogo!J$5:J$73,MATCH($A35,Catálogo!$A$5:$A$73,0))="","",INDEX(Catálogo!J$5:J$73,MATCH($A35,Catálogo!$A$5:$A$73,0))) | K35: Pendiente | M35: =IF($F35<>"Numérico","",IF($L35="","Sin dato",IF(AND(OR(NOT(ISNUMBER($I35)),$L35>=$I35),OR(NOT(ISNUMBER($J35)),$L35<=$J35)),"Dentro de rango","Fuera de rango"))) | P35: =IF(INDEX(Catálogo!M$5:M$73,MATCH($A35,Catálogo!$A$5:$A$73,0))="","",INDEX(Catálogo!M$5:M$73,MATCH($A35,Catálogo!$A$5:$A$73,0))) -> 1201007
A36: 3.2.2 | B36: =IF(INDEX(Catálogo!B$5:B$73,MATCH($A36,Catálogo!$A$5:$A$73,0))="","",INDEX(Catálogo!B$5:B$73,MATCH($A36,Catálogo!$A$5:$A$73,0))) -> 3. Sistema neumático y etapa de secado | C36: =IF(INDEX(Catálogo!C$5:C$73,MATCH($A36,Catálogo!$A$5:$A$73,0))="","",INDEX(Catálogo!C$5:C$73,MATCH($A36,Catálogo!$A$5:$A$73,0))) -> 3.2 Instrumentación de presión | D36: =IF(INDEX(Catálogo!D$5:D$73,MATCH($A36,Catálogo!$A$5:$A$73,0))="","",INDEX(Catálogo!D$5:D$73,MATCH($A36,Catálogo!$A$5:$A$73,0))) -> Presión negativa de succión | E36: =IF(INDEX(Catálogo!E$5:E$73,MATCH($A36,Catálogo!$A$5:$A$73,0))="","",INDEX(Catálogo!E$5:E$73,MATCH($A36,Catálogo!$A$5:$A$73,0))) -> Presión negativa generada por la etapa de secado | F36: =IF(INDEX(Catálogo!F$5:F$73,MATCH($A36,Catálogo!$A$5:$A$73,0))="","",INDEX(Catálogo!F$5:F$73,MATCH($A36,Catálogo!$A$5:$A$73,0))) -> Numérico | G36: =IF(INDEX(Catálogo!G$5:G$73,MATCH($A36,Catálogo!$A$5:$A$73,0))="","",INDEX(Catálogo!G$5:G$73,MATCH($A36,Catálogo!$A$5:$A$73,0))) -> bar | H36: =IF(INDEX(Catálogo!H$5:H$73,MATCH($A36,Catálogo!$A$5:$A$73,0))="","",INDEX(Catálogo!H$5:H$73,MATCH($A36,Catálogo!$A$5:$A$73,0))) -> Dentro del rango del fabricante | I36: =IF(INDEX(Catálogo!I$5:I$73,MATCH($A36,Catálogo!$A$5:$A$73,0))="","",INDEX(Catálogo!I$5:I$73,MATCH($A36,Catálogo!$A$5:$A$73,0))) -> PENDIENTE DE VALIDAR | J36: =IF(INDEX(Catálogo!J$5:J$73,MATCH($A36,Catálogo!$A$5:$A$73,0))="","",INDEX(Catálogo!J$5:J$73,MATCH($A36,Catálogo!$A$5:$A$73,0))) -> PENDIENTE DE VALIDAR | K36: Pendiente | M36: =IF($F36<>"Numérico","",IF($L36="","Sin dato",IF(AND(OR(NOT(ISNUMBER($I36)),$L36>=$I36),OR(NOT(ISNUMBER($J36)),$L36<=$J36)),"Dentro de rango","Fuera de rango"))) -> Sin dato | P36: =IF(INDEX(Catálogo!M$5:M$73,MATCH($A36,Catálogo!$A$5:$A$73,0))="","",INDEX(Catálogo!M$5:M$73,MATCH($A36,Catálogo!$A$5:$A$73,0)))
A37: 3.3.1 | B37: =IF(INDEX(Catálogo!B$5:B$73,MATCH($A37,Catálogo!$A$5:$A$73,0))="","",INDEX(Catálogo!B$5:B$73,MATCH($A37,Catálogo!$A$5:$A$73,0))) -> 3. Sistema neumático y etapa de secado | C37: =IF(INDEX(Catálogo!C$5:C$73,MATCH($A37,Catálogo!$A$5:$A$73,0))="","",INDEX(Catálogo!C$5:C$73,MATCH($A37,Catálogo!$A$5:$A$73,0))) -> 3.3 Estanqueidad | D37: =IF(INDEX(Catálogo!D$5:D$73,MATCH($A37,Catálogo!$A$5:$A$73,0))="","",INDEX(Catálogo!D$5:D$73,MATCH($A37,Catálogo!$A$5:$A$73,0))) -> Prueba de fugas del circuito | E37: =IF(INDEX(Catálogo!E$5:E$73,MATCH($A37,Catálogo!$A$5:$A$73,0))="","",INDEX(Catálogo!E$5:E$73,MATCH($A37,Catálogo!$A$5:$A$73,0))) -> Prueba de fugas del circuito neumático completo | F37: =IF(INDEX(Catálogo!F$5:F$73,MATCH($A37,Catálogo!$A$5:$A$73,0))="","",INDEX(Catálogo!F$5:F$73,MATCH($A37,Catálogo!$A$5:$A$73,0))) -> OK / No OK | G37: =IF(INDEX(Catálogo!G$5:G$73,MATCH($A37,Catálogo!$A$5:$A$73,0))="","",INDEX(Catálogo!G$5:G$73,MATCH($A37,Catálogo!$A$5:$A$73,0))) | H37: =IF(INDEX(Catálogo!H$5:H$73,MATCH($A37,Catálogo!$A$5:$A$73,0))="","",INDEX(Catálogo!H$5:H$73,MATCH($A37,Catálogo!$A$5:$A$73,0))) -> Sin fugas | I37: =IF(INDEX(Catálogo!I$5:I$73,MATCH($A37,Catálogo!$A$5:$A$73,0))="","",INDEX(Catálogo!I$5:I$73,MATCH($A37,Catálogo!$A$5:$A$73,0))) | J37: =IF(INDEX(Catálogo!J$5:J$73,MATCH($A37,Catálogo!$A$5:$A$73,0))="","",INDEX(Catálogo!J$5:J$73,MATCH($A37,Catálogo!$A$5:$A$73,0))) | K37: Pendiente | M37: =IF($F37<>"Numérico","",IF($L37="","Sin dato",IF(AND(OR(NOT(ISNUMBER($I37)),$L37>=$I37),OR(NOT(ISNUMBER($J37)),$L37<=$J37)),"Dentro de rango","Fuera de rango"))) | P37: =IF(INDEX(Catálogo!M$5:M$73,MATCH($A37,Catálogo!$A$5:$A$73,0))="","",INDEX(Catálogo!M$5:M$73,MATCH($A37,Catálogo!$A$5:$A$73,0)))
A38: 3.3.2 | B38: =IF(INDEX(Catálogo!B$5:B$73,MATCH($A38,Catálogo!$A$5:$A$73,0))="","",INDEX(Catálogo!B$5:B$73,MATCH($A38,Catálogo!$A$5:$A$73,0))) -> 3. Sistema neumático y etapa de secado | C38: =IF(INDEX(Catálogo!C$5:C$73,MATCH($A38,Catálogo!$A$5:$A$73,0))="","",INDEX(Catálogo!C$5:C$73,MATCH($A38,Catálogo!$A$5:$A$73,0))) -> 3.3 Estanqueidad | D38: =IF(INDEX(Catálogo!D$5:D$73,MATCH($A38,Catálogo!$A$5:$A$73,0))="","",INDEX(Catálogo!D$5:D$73,MATCH($A38,Catálogo!$A$5:$A$73,0))) -> O-Rings y conectores del holder | E38: =IF(INDEX(Catálogo!E$5:E$73,MATCH($A38,Catálogo!$A$5:$A$73,0))="","",INDEX(Catálogo!E$5:E$73,MATCH($A38,Catálogo!$A$5:$A$73,0))) -> Estado de los O-Rings y conectores del cabezal de muestra (holder) | F38: =IF(INDEX(Catálogo!F$5:F$73,MATCH($A38,Catálogo!$A$5:$A$73,0))="","",INDEX(Catálogo!F$5:F$73,MATCH($A38,Catálogo!$A$5:$A$73,0))) -> OK / No OK | G38: =IF(INDEX(Catálogo!G$5:G$73,MATCH($A38,Catálogo!$A$5:$A$73,0))="","",INDEX(Catálogo!G$5:G$73,MATCH($A38,Catálogo!$A$5:$A$73,0))) | H38: =IF(INDEX(Catálogo!H$5:H$73,MATCH($A38,Catálogo!$A$5:$A$73,0))="","",INDEX(Catálogo!H$5:H$73,MATCH($A38,Catálogo!$A$5:$A$73,0))) -> Sin desgaste | I38: =IF(INDEX(Catálogo!I$5:I$73,MATCH($A38,Catálogo!$A$5:$A$73,0))="","",INDEX(Catálogo!I$5:I$73,MATCH($A38,Catálogo!$A$5:$A$73,0))) | J38: =IF(INDEX(Catálogo!J$5:J$73,MATCH($A38,Catálogo!$A$5:$A$73,0))="","",INDEX(Catálogo!J$5:J$73,MATCH($A38,Catálogo!$A$5:$A$73,0))) | K38: Pendiente | M38: =IF($F38<>"Numérico","",IF($L38="","Sin dato",IF(AND(OR(NOT(ISNUMBER($I38)),$L38>=$I38),OR(NOT(ISNUMBER($J38)),$L38<=$J38)),"Dentro de rango","Fuera de rango"))) | P38: =IF(INDEX(Catálogo!M$5:M$73,MATCH($A38,Catálogo!$A$5:$A$73,0))="","",INDEX(Catálogo!M$5:M$73,MATCH($A38,Catálogo!$A$5:$A$73,0))) -> C0004x1.2N70 / 1201011
A39: 3.3.3 | B39: =IF(INDEX(Catálogo!B$5:B$73,MATCH($A39,Catálogo!$A$5:$A$73,0))="","",INDEX(Catálogo!B$5:B$73,MATCH($A39,Catálogo!$A$5:$A$73,0))) -> 3. Sistema neumático y etapa de secado | C39: =IF(INDEX(Catálogo!C$5:C$73,MATCH($A39,Catálogo!$A$5:$A$73,0))="","",INDEX(Catálogo!C$5:C$73,MATCH($A39,Catálogo!$A$5:$A$73,0))) -> 3.3 Estanqueidad | D39: =IF(INDEX(Catálogo!D$5:D$73,MATCH($A39,Catálogo!$A$5:$A$73,0))="","",INDEX(Catálogo!D$5:D$73,MATCH($A39,Catálogo!$A$5:$A$73,0))) -> Alerta "Dryer" | E39: =IF(INDEX(Catálogo!E$5:E$73,MATCH($A39,Catálogo!$A$5:$A$73,0))="","",INDEX(Catálogo!E$5:E$73,MATCH($A39,Catálogo!$A$5:$A$73,0))) -> Alerta activa de la etapa de secado en el equipo | F39: =IF(INDEX(Catálogo!F$5:F$73,MATCH($A39,Catálogo!$A$5:$A$73,0))="","",INDEX(Catálogo!F$5:F$73,MATCH($A39,Catálogo!$A$5:$A$73,0))) -> Sí/No | G39: =IF(INDEX(Catálogo!G$5:G$73,MATCH($A39,Catálogo!$A$5:$A$73,0))="","",INDEX(Catálogo!G$5:G$73,MATCH($A39,Catálogo!$A$5:$A$73,0))) | H39: =IF(INDEX(Catálogo!H$5:H$73,MATCH($A39,Catálogo!$A$5:$A$73,0))="","",INDEX(Catálogo!H$5:H$73,MATCH($A39,Catálogo!$A$5:$A$73,0))) -> No debe estar activa | I39: =IF(INDEX(Catálogo!I$5:I$73,MATCH($A39,Catálogo!$A$5:$A$73,0))="","",INDEX(Catálogo!I$5:I$73,MATCH($A39,Catálogo!$A$5:$A$73,0))) | J39: =IF(INDEX(Catálogo!J$5:J$73,MATCH($A39,Catálogo!$A$5:$A$73,0))="","",INDEX(Catálogo!J$5:J$73,MATCH($A39,Catálogo!$A$5:$A$73,0))) | K39: Pendiente | M39: =IF($F39<>"Numérico","",IF($L39="","Sin dato",IF(AND(OR(NOT(ISNUMBER($I39)),$L39>=$I39),OR(NOT(ISNUMBER($J39)),$L39<=$J39)),"Dentro de rango","Fuera de rango"))) | P39: =IF(INDEX(Catálogo!M$5:M$73,MATCH($A39,Catálogo!$A$5:$A$73,0))="","",INDEX(Catálogo!M$5:M$73,MATCH($A39,Catálogo!$A$5:$A$73,0)))
A40: 4.1.1 | B40: =IF(INDEX(Catálogo!B$5:B$73,MATCH($A40,Catálogo!$A$5:$A$73,0))="","",INDEX(Catálogo!B$5:B$73,MATCH($A40,Catálogo!$A$5:$A$73,0))) -> 4. Espectrómetro: cámara de medida y óptica | C40: =IF(INDEX(Catálogo!C$5:C$73,MATCH($A40,Catálogo!$A$5:$A$73,0))="","",INDEX(Catálogo!C$5:C$73,MATCH($A40,Catálogo!$A$5:$A$73,0))) -> 4.1 Estado del recinto | D40: =IF(INDEX(Catálogo!D$5:D$73,MATCH($A40,Catálogo!$A$5:$A$73,0))="","",INDEX(Catálogo!D$5:D$73,MATCH($A40,Catálogo!$A$5:$A$73,0))) -> Humedad / condensación | E40: =IF(INDEX(Catálogo!E$5:E$73,MATCH($A40,Catálogo!$A$5:$A$73,0))="","",INDEX(Catálogo!E$5:E$73,MATCH($A40,Catálogo!$A$5:$A$73,0))) -> Presencia de humedad o condensación en el gabinete del espectrómetro | F40: =IF(INDEX(Catálogo!F$5:F$73,MATCH($A40,Catálogo!$A$5:$A$73,0))="","",INDEX(Catálogo!F$5:F$73,MATCH($A40,Catálogo!$A$5:$A$73,0))) -> Sí/No | G40: =IF(INDEX(Catálogo!G$5:G$73,MATCH($A40,Catálogo!$A$5:$A$73,0))="","",INDEX(Catálogo!G$5:G$73,MATCH($A40,Catálogo!$A$5:$A$73,0))) | H40: =IF(INDEX(Catálogo!H$5:H$73,MATCH($A40,Catálogo!$A$5:$A$73,0))="","",INDEX(Catálogo!H$5:H$73,MATCH($A40,Catálogo!$A$5:$A$73,0))) -> Ausencia de humedad | I40: =IF(INDEX(Catálogo!I$5:I$73,MATCH($A40,Catálogo!$A$5:$A$73,0))="","",INDEX(Catálogo!I$5:I$73,MATCH($A40,Catálogo!$A$5:$A$73,0))) | J40: =IF(INDEX(Catálogo!J$5:J$73,MATCH($A40,Catálogo!$A$5:$A$73,0))="","",INDEX(Catálogo!J$5:J$73,MATCH($A40,Catálogo!$A$5:$A$73,0))) | K40: Pendiente | M40: =IF($F40<>"Numérico","",IF($L40="","Sin dato",IF(AND(OR(NOT(ISNUMBER($I40)),$L40>=$I40),OR(NOT(ISNUMBER($J40)),$L40<=$J40)),"Dentro de rango","Fuera de rango"))) | P40: =IF(INDEX(Catálogo!M$5:M$73,MATCH($A40,Catálogo!$A$5:$A$73,0))="","",INDEX(Catálogo!M$5:M$73,MATCH($A40,Catálogo!$A$5:$A$73,0)))
A41: 4.1.2 | B41: =IF(INDEX(Catálogo!B$5:B$73,MATCH($A41,Catálogo!$A$5:$A$73,0))="","",INDEX(Catálogo!B$5:B$73,MATCH($A41,Catálogo!$A$5:$A$73,0))) -> 4. Espectrómetro: cámara de medida y óptica | C41: =IF(INDEX(Catálogo!C$5:C$73,MATCH($A41,Catálogo!$A$5:$A$73,0))="","",INDEX(Catálogo!C$5:C$73,MATCH($A41,Catálogo!$A$5:$A$73,0))) -> 4.1 Estado del recinto | D41: =IF(INDEX(Catálogo!D$5:D$73,MATCH($A41,Catálogo!$A$5:$A$73,0))="","",INDEX(Catálogo!D$5:D$73,MATCH($A41,Catálogo!$A$5:$A$73,0))) -> Óxido y corrosión | E41: =IF(INDEX(Catálogo!E$5:E$73,MATCH($A41,Catálogo!$A$5:$A$73,0))="","",INDEX(Catálogo!E$5:E$73,MATCH($A41,Catálogo!$A$5:$A$73,0))) -> Óxido o corrosión en componentes internos por ingreso de humedad | F41: =IF(INDEX(Catálogo!F$5:F$73,MATCH($A41,Catálogo!$A$5:$A$73,0))="","",INDEX(Catálogo!F$5:F$73,MATCH($A41,Catálogo!$A$5:$A$73,0))) -> Sí/No | G41: =IF(INDEX(Catálogo!G$5:G$73,MATCH($A41,Catálogo!$A$5:$A$73,0))="","",INDEX(Catálogo!G$5:G$73,MATCH($A41,Catálogo!$A$5:$A$73,0))) | H41: =IF(INDEX(Catálogo!H$5:H$73,MATCH($A41,Catálogo!$A$5:$A$73,0))="","",INDEX(Catálogo!H$5:H$73,MATCH($A41,Catálogo!$A$5:$A$73,0))) -> Sin óxido ni corrosión | I41: =IF(INDEX(Catálogo!I$5:I$73,MATCH($A41,Catálogo!$A$5:$A$73,0))="","",INDEX(Catálogo!I$5:I$73,MATCH($A41,Catálogo!$A$5:$A$73,0))) | J41: =IF(INDEX(Catálogo!J$5:J$73,MATCH($A41,Catálogo!$A$5:$A$73,0))="","",INDEX(Catálogo!J$5:J$73,MATCH($A41,Catálogo!$A$5:$A$73,0))) | K41: Pendiente | M41: =IF($F41<>"Numérico","",IF($L41="","Sin dato",IF(AND(OR(NOT(ISNUMBER($I41)),$L41>=$I41),OR(NOT(ISNUMBER($J41)),$L41<=$J41)),"Dentro de rango","Fuera de rango"))) | P41: =IF(INDEX(Catálogo!M$5:M$73,MATCH($A41,Catálogo!$A$5:$A$73,0))="","",INDEX(Catálogo!M$5:M$73,MATCH($A41,Catálogo!$A$5:$A$73,0)))
A42: 4.1.3 | B42: =IF(INDEX(Catálogo!B$5:B$73,MATCH($A42,Catálogo!$A$5:$A$73,0))="","",INDEX(Catálogo!B$5:B$73,MATCH($A42,Catálogo!$A$5:$A$73,0))) -> 4. Espectrómetro: cámara de medida y óptica | C42: =IF(INDEX(Catálogo!C$5:C$73,MATCH($A42,Catálogo!$A$5:$A$73,0))="","",INDEX(Catálogo!C$5:C$73,MATCH($A42,Catálogo!$A$5:$A$73,0))) -> 4.1 Estado del recinto | D42: =IF(INDEX(Catálogo!D$5:D$73,MATCH($A42,Catálogo!$A$5:$A$73,0))="","",INDEX(Catálogo!D$5:D$73,MATCH($A42,Catálogo!$A$5:$A$73,0))) -> Limpieza de la cámara de medida | E42: =IF(INDEX(Catálogo!E$5:E$73,MATCH($A42,Catálogo!$A$5:$A$73,0))="","",INDEX(Catálogo!E$5:E$73,MATCH($A42,Catálogo!$A$5:$A$73,0))) -> Necesidad de limpieza integral de la cámara de medición | F42: =IF(INDEX(Catálogo!F$5:F$73,MATCH($A42,Catálogo!$A$5:$A$73,0))="","",INDEX(Catálogo!F$5:F$73,MATCH($A42,Catálogo!$A$5:$A$73,0))) -> OK / No OK | G42: =IF(INDEX(Catálogo!G$5:G$73,MATCH($A42,Catálogo!$A$5:$A$73,0))="","",INDEX(Catálogo!G$5:G$73,MATCH($A42,Catálogo!$A$5:$A$73,0))) | H42: =IF(INDEX(Catálogo!H$5:H$73,MATCH($A42,Catálogo!$A$5:$A$73,0))="","",INDEX(Catálogo!H$5:H$73,MATCH($A42,Catálogo!$A$5:$A$73,0))) -> Cámara limpia | I42: =IF(INDEX(Catálogo!I$5:I$73,MATCH($A42,Catálogo!$A$5:$A$73,0))="","",INDEX(Catálogo!I$5:I$73,MATCH($A42,Catálogo!$A$5:$A$73,0))) | J42: =IF(INDEX(Catálogo!J$5:J$73,MATCH($A42,Catálogo!$A$5:$A$73,0))="","",INDEX(Catálogo!J$5:J$73,MATCH($A42,Catálogo!$A$5:$A$73,0))) | K42: Pendiente | M42: =IF($F42<>"Numérico","",IF($L42="","Sin dato",IF(AND(OR(NOT(ISNUMBER($I42)),$L42>=$I42),OR(NOT(ISNUMBER($J42)),$L42<=$J42)),"Dentro de rango","Fuera de rango"))) | P42: =IF(INDEX(Catálogo!M$5:M$73,MATCH($A42,Catálogo!$A$5:$A$73,0))="","",INDEX(Catálogo!M$5:M$73,MATCH($A42,Catálogo!$A$5:$A$73,0)))
A43: 4.2.1 | B43: =IF(INDEX(Catálogo!B$5:B$73,MATCH($A43,Catálogo!$A$5:$A$73,0))="","",INDEX(Catálogo!B$5:B$73,MATCH($A43,Catálogo!$A$5:$A$73,0))) -> 4. Espectrómetro: cámara de medida y óptica | C43: =IF(INDEX(Catálogo!C$5:C$73,MATCH($A43,Catálogo!$A$5:$A$73,0))="","",INDEX(Catálogo!C$5:C$73,MATCH($A43,Catálogo!$A$5:$A$73,0))) -> 4.2 Componentes ópticos | D43: =IF(INDEX(Catálogo!D$5:D$73,MATCH($A43,Catálogo!$A$5:$A$73,0))="","",INDEX(Catálogo!D$5:D$73,MATCH($A43,Catálogo!$A$5:$A$73,0))) -> Espejo y tornillo del espejo | E43: =IF(INDEX(Catálogo!E$5:E$73,MATCH($A43,Catálogo!$A$5:$A$73,0))="","",INDEX(Catálogo!E$5:E$73,MATCH($A43,Catálogo!$A$5:$A$73,0))) -> Estado del espejo y de su O-Ring de montaje | F43: =IF(INDEX(Catálogo!F$5:F$73,MATCH($A43,Catálogo!$A$5:$A$73,0))="","",INDEX(Catálogo!F$5:F$73,MATCH($A43,Catálogo!$A$5:$A$73,0))) -> OK / No OK | G43: =IF(INDEX(Catálogo!G$5:G$73,MATCH($A43,Catálogo!$A$5:$A$73,0))="","",INDEX(Catálogo!G$5:G$73,MATCH($A43,Catálogo!$A$5:$A$73,0))) | H43: =IF(INDEX(Catálogo!H$5:H$73,MATCH($A43,Catálogo!$A$5:$A$73,0))="","",INDEX(Catálogo!H$5:H$73,MATCH($A43,Catálogo!$A$5:$A$73,0))) -> Sin daño ni fuga | I43: =IF(INDEX(Catálogo!I$5:I$73,MATCH($A43,Catálogo!$A$5:$A$73,0))="","",INDEX(Catálogo!I$5:I$73,MATCH($A43,Catálogo!$A$5:$A$73,0))) | J43: =IF(INDEX(Catálogo!J$5:J$73,MATCH($A43,Catálogo!$A$5:$A$73,0))="","",INDEX(Catálogo!J$5:J$73,MATCH($A43,Catálogo!$A$5:$A$73,0))) | K43: Pendiente | M43: =IF($F43<>"Numérico","",IF($L43="","Sin dato",IF(AND(OR(NOT(ISNUMBER($I43)),$L43>=$I43),OR(NOT(ISNUMBER($J43)),$L43<=$J43)),"Dentro de rango","Fuera de rango"))) | P43: =IF(INDEX(Catálogo!M$5:M$73,MATCH($A43,Catálogo!$A$5:$A$73,0))="","",INDEX(Catálogo!M$5:M$73,MATCH($A43,Catálogo!$A$5:$A$73,0))) -> C00014x2.5NBR70
